Workbook

Sheet 使用说明
A1: 塔防模式｜4 日战役智能设计器
A2: 正式战役为第 1～3 日共 12 波；第 4 日白昼只进行铃兰 Boss。第 1 日前三波已锁定保留。
A4: 建议工作流
A5: 1 | B5: 先在“敌人目录”维护全局固定战斗数值、息壤与掉落概率。
A6: 2 | B6: 在“全局设置”调整模拟玩家数、击杀率，以及第 1～3 日独立地下探索行动力。
A7: 3 | B7: 在“第1日”至“第3日”编辑每波敌人、数量、出生点与刷怪节奏；第 4 日 Boss 面板只读。
A8: 4 | B8: 到“总览”检查 12 波统计、日汇总、地下探索行动力和 Boss 接续。
A9: 5 | B9: 完成后把工作簿交回 Codex；Codex 校验并转换为 schema v3 JSON。工作簿不会直接写入正式 .tres。
A11: 颜色与输入规则
A12: 浅蓝 | B12: 波次名称、敌人、数量、出生点及节奏：可编辑
A13: 金黄 | B13: 敌人固定息壤与工作簿关键提醒
A14: 浅绿 / 浅紫 | B14: 敌人掉落概率：可编辑，输入 0%～100%
A15: 浅灰 | B15: 公式与权威结构字段：请勿手工覆盖
A16: 浅红 | B16: 校验失败：缺少输入、重复敌人或数值越界
A18: 四日流程（结构性约束）
A19: 第1～3日 | B19: 每天 4 个普通波次；第 4、8、12 波完成后进入地下探索。
A20: 地下探索 | B20: 三日默认行动力分别为 5、5、5；配置为 0 时跳过。正式流程不再进入命运时间。
A21: 第4日 | B21: 白昼准备完成后只进行铃兰 Boss；不显示普通波次编号，击败后直接通关。
A22: 导入契约 | B22: schema v3：12 波、4 日、Boss 位于第 12 波后、Boss 日为第 4 日白昼。
A24: 请勿直接编辑“敌人导入数据（勿改）”“导入数据（勿改）”与“系统数据（勿改）”；它们是稳定 ID 和反向回读契约。

Sheet 总览
A1: 塔防模式｜4 日战役总览
A2: 第 1～3 日共 12 个普通波次；每日日终进入地下探索；第 4 日白昼只进行铃兰 Boss。
A4: 可回读波次 | D4: 基础敌人数 | G4: 实际敌人数 | J4: 预计息壤/队伍 | M4: Boss | N4: 铃兰
A5: =COUNTIF(E9:E20,"可回读")&" / 12" -> 12 / 12 | D5: =SUM(F9:F20) -> 21810 | G5: =SUM(G9:G20) -> 21810 | J5: =SUM(K9:K20) -> 57351 | M5: 第4日·白昼
A8: 波次 | B8: 日 | C8: 时段 | D8: 名称 | E8: 状态 | F8: 基础数量 | G8: 实际数量 | H8: 敌人种类 | I8: 最大息壤/玩家 | J8: 预计息壤/玩家 | K8: 预计息壤/队伍 | L8: 最短刷怪(s) | M8: 存活上限 | N8: 启用出生点
A9: 第1波 | B9: 1 | C9: 白昼 | D9: =第1日!B3 -> 第1波 | E9: =第1日!I4 -> 可回读 | F9: =SUM(第1日!C7:C24) -> 3000 | G9: =SUM(第1日!D7:D24) -> 3000 | H9: =COUNTA(第1日!B7:B24) -> 5 | I9: =SUM(第1日!F7:F24) -> 3000 | J9: =SUM(第1日!G7:G24) -> 3000 | K9: =SUM(第1日!H7:H24) -> 3000 | L9: =IF(G9=0,0,MAX(0,(ROUNDUP(G9/第1日!G3,0)-1)*第1日!E3)) -> 299.9 | M9: =第1日!I3 -> 300 | N9: =IF(第1日!B4="点1·开启",1,0)+IF(第1日!C4="点2·开启",1,0)+IF(第1日!D4="点3·开启",1,0)+IF(第1日!E4="点4·开启",1,0)+IF(第1日!F4="点5·开启",1,0)+IF(第1日!G4="点6·开启",1,0) -> 4
A10: 第2波 | B10: 1 | C10: 白昼 | D10: =第1日!B32 -> 第2波 | E10: =第1日!I33 -> 可回读 | F10: =SUM(第1日!C36:C53) -> 3850 | G10: =SUM(第1日!D36:D53) -> 3850 | H10: =COUNTA(第1日!B36:B53) -> 7 | I10: =SUM(第1日!F36:F53) -> 4050 | J10: =SUM(第1日!G36:G53) -> 4050 | K10: =SUM(第1日!H36:H53) -> 4050 | L10: =IF(G10=0,0,MAX(0,(ROUNDUP(G10/第1日!G32,0)-1)*第1日!E32)) -> 384.9 | M10: =第1日!I32 -> 300 | N10: =IF(第1日!B33="点1·开启",1,0)+IF(第1日!C33="点2·开启",1,0)+IF(第1日!D33="点3·开启",1,0)+IF(第1日!E33="点4·开启",1,0)+IF(第1日!F33="点5·开启",1,0)+IF(第1日!G33="点6·开启",1,0) -> 4
A11: 第3波 | B11: 1 | C11: 夜晚 | D11: =第1日!B61 -> 第3波 | E11: =第1日!I62 -> 可回读 | F11: =SUM(第1日!C65:C82) -> 3470 | G11: =SUM(第1日!D65:D82) -> 3470 | H11: =COUNTA(第1日!B65:B82) -> 9 | I11: =SUM(第1日!F65:F82) -> 4540 | J11: =SUM(第1日!G65:G82) -> 4540 | K11: =SUM(第1日!H65:H82) -> 4540 | L11: =IF(G11=0,0,MAX(0,(ROUNDUP(G11/第1日!G61,0)-1)*第1日!E61)) -> 173.4 | M11: =第1日!I61 -> 300 | N11: =IF(第1日!B62="点1·开启",1,0)+IF(第1日!C62="点2·开启",1,0)+IF(第1日!D62="点3·开启",1,0)+IF(第1日!E62="点4·开启",1,0)+IF(第1日!F62="点5·开启",1,0)+IF(第1日!G62="点6·开启",1,0) -> 6
A12: 第4波 | B12: 1 | C12: 夜晚 | D12: =第1日!B90 -> 第4波 | E12: =第1日!I91 -> 可回读 | F12: =SUM(第1日!C94:C111) -> 2080 | G12: =SUM(第1日!D94:D111) -> 2080 | H12: =COUNTA(第1日!B94:B111) -> 11 | I12: =SUM(第1日!F94:F111) -> 5140 | J12: =SUM(第1日!G94:G111) -> 5140 | K12: =SUM(第1日!H94:H111) -> 5140 | L12: =IF(G12=0,0,MAX(0,(ROUNDUP(G12/第1日!G90,0)-1)*第1日!E90)) -> 69.3 | M12: =第1日!I90 -> 300 | N12: =IF(第1日!B91="点1·开启",1,0)+IF(第1日!C91="点2·开启",1,0)+IF(第1日!D91="点3·开启",1,0)+IF(第1日!E91="点4·开启",1,0)+IF(第1日!F91="点5·开启",1,0)+IF(第1日!G91="点6·开启",1,0) -> 6
A13: 第5波 | B13: 2 | C13: 白昼 | D13: =第2日!B3 -> 第5波 | E13: =第2日!I4 -> 可回读 | F13: =SUM(第2日!C7:C24) -> 2100 | G13: =SUM(第2日!D7:D24) -> 2100 | H13: =COUNTA(第2日!B7:B24) -> 15 | I13: =SUM(第2日!F7:F24) -> 8000 | J13: =SUM(第2日!G7:G24) -> 8000 | K13: =SUM(第2日!H7:H24) -> 8000 | L13: =IF(G13=0,0,MAX(0,(ROUNDUP(G13/第2日!G3,0)-1)*第2日!E3)) -> 52.4 | M13: =第2日!I3 -> 300 | N13: =IF(第2日!B4="点1·开启",1,0)+IF(第2日!C4="点2·开启",1,0)+IF(第2日!D4="点3·开启",1,0)+IF(第2日!E4="点4·开启",1,0)+IF(第2日!F4="点5·开启",1,0)+IF(第2日!G4="点6·开启",1,0) -> 6
A14: 第6波 | B14: 2 | C14: 白昼 | D14: =第2日!B32 -> 第6波 | E14: =第2日!I33 -> 可回读 | F14: =SUM(第2日!C36:C53) -> 2240 | G14: =SUM(第2日!D36:D53) -> 2240 | H14: =COUNTA(第2日!B36:B53) -> 18 | I14: =SUM(第2日!F36:F53) -> 9060 | J14: =SUM(第2日!G36:G53) -> 9060 | K14: =SUM(第2日!H36:H53) -> 9060 | L14: =IF(G14=0,0,MAX(0,(ROUNDUP(G14/第2日!G32,0)-1)*第2日!E32)) -> 201.51 | M14: =第2日!I32 -> 275 | N14: =IF(第2日!B33="点1·开启",1,0)+IF(第2日!C33="点2·开启",1,0)+IF(第2日!D33="点3·开启",1,0)+IF(第2日!E33="点4·开启",1,0)+IF(第2日!F33="点5·开启",1,0)+IF(第2日!G33="点6·开启",1,0) -> 6
A15: 第7波 | B15: 2 | C15: 夜晚 | D15: =第2日!B61 -> 第7波 | E15: =第2日!I62 -> 可回读 | F15: =SUM(第2日!C65:C82) -> 2150 | G15: =SUM(第2日!D65:D82) -> 2150 | H15: =COUNTA(第2日!B65:B82) -> 18 | I15: =SUM(第2日!F65:F82) -> 10410 | J15: =SUM(第2日!G65:G82) -> 10410 | K15: =SUM(第2日!H65:H82) -> 10410 | L15: =IF(G15=0,0,MAX(0,(ROUNDUP(G15/第2日!G61,0)-1)*第2日!E61)) -> 171.92 | M15: =第2日!I61 -> 285 | N15: =IF(第2日!B62="点1·开启",1,0)+IF(第2日!C62="点2·开启",1,0)+IF(第2日!D62="点3·开启",1,0)+IF(第2日!E62="点4·开启",1,0)+IF(第2日!F62="点5·开启",1,0)+IF(第2日!G62="点6·开启",1,0) -> 6
A16: 第8波 | B16: 2 | C16: 夜晚 | D16: =第2日!B90 -> 第8波 | E16: =第2日!I91 -> 可回读 | F16: =SUM(第2日!C94:C111) -> 2240 | G16: =SUM(第2日!D94:D111) -> 2240 | H16: =COUNTA(第2日!B94:B111) -> 18 | I16: =SUM(第2日!F94:F111) -> 11750 | J16: =SUM(第2日!G94:G111) -> 11750 | K16: =SUM(第2日!H94:H111) -> 11750 | L16: =IF(G16=0,0,MAX(0,(ROUNDUP(G16/第2日!G90,0)-1)*第2日!E90)) -> 167.925 | M16: =第2日!I90 -> 300 | N16: =IF(第2日!B91="点1·开启",1,0)+IF(第2日!C91="点2·开启",1,0)+IF(第2日!D91="点3·开启",1,0)+IF(第2日!E91="点4·开启",1,0)+IF(第2日!F91="点5·开启",1,0)+IF(第2日!G91="点6·开启",1,0) -> 6
A17: 第9波 | B17: 3 | C17: 白昼 | D17: =第3日!B3 -> 第9波 | E17: =第3日!I4 -> 可回读 | F17: =SUM(第3日!C7:C24) -> 144 | G17: =SUM(第3日!D7:D24) -> 144 | H17: =COUNTA(第3日!B7:B24) -> 9 | I17: =SUM(第3日!F7:F24) -> 242 | J17: =SUM(第3日!G7:G24) -> 242 | K17: =SUM(第3日!H7:H24) -> 242 | L17: =IF(G17=0,0,MAX(0,(ROUNDUP(G17/第3日!G3,0)-1)*第3日!E3)) -> 40.04 | M17: =第3日!I3 -> 300 | N17: =IF(第3日!B4="点1·开启",1,0)+IF(第3日!C4="点2·开启",1,0)+IF(第3日!D4="点3·开启",1,0)+IF(第3日!E4="点4·开启",1,0)+IF(第3日!F4="点5·开启",1,0)+IF(第3日!G4="点6·开启",1,0) -> 6
A18: 第10波 | B18: 3 | C18: 白昼 | D18: =第3日!B32 -> 第10波 | E18: =第3日!I33 -> 可回读 | F18: =SUM(第3日!C36:C53) -> 160 | G18: =SUM(第3日!D36:D53) -> 160 | H18: =COUNTA(第3日!B36:B53) -> 10 | I18: =SUM(第3日!F36:F53) -> 308 | J18: =SUM(第3日!G36:G53) -> 308 | K18: =SUM(第3日!H36:H53) -> 308 | L18: =IF(G18=0,0,MAX(0,(ROUNDUP(G18/第3日!G32,0)-1)*第3日!E32)) -> 41.34 | M18: =第3日!I32 -> 300 | N18: =IF(第3日!B33="点1·开启",1,0)+IF(第3日!C33="点2·开启",1,0)+IF(第3日!D33="点3·开启",1,0)+IF(第3日!E33="点4·开启",1,0)+IF(第3日!F33="点5·开启",1,0)+IF(第3日!G33="点6·开启",1,0) -> 6
A19: 第11波 | B19: 3 | C19: 夜晚 | D19: =第3日!B61 -> 第11波 | E19: =第3日!I62 -> 可回读 | F19: =SUM(第3日!C65:C82) -> 176 | G19: =SUM(第3日!D65:D82) -> 176 | H19: =COUNTA(第3日!B65:B82) -> 12 | I19: =SUM(第3日!F65:F82) -> 398 | J19: =SUM(第3日!G65:G82) -> 398 | K19: =SUM(第3日!H65:H82) -> 398 | L19: =IF(G19=0,0,MAX(0,(ROUNDUP(G19/第3日!G61,0)-1)*第3日!E61)) -> 42 | M19: =第3日!I61 -> 300 | N19: =IF(第3日!B62="点1·开启",1,0)+IF(第3日!C62="点2·开启",1,0)+IF(第3日!D62="点3·开启",1,0)+IF(第3日!E62="点4·开启",1,0)+IF(第3日!F62="点5·开启",1,0)+IF(第3日!G62="点6·开启",1,0) -> 6
A20: 第12波 | B20: 3 | C20: 夜晚 | D20: =第3日!B90 -> 第12波 | E20: =第3日!I91 -> 可回读 | F20: =SUM(第3日!C94:C111) -> 200 | G20: =SUM(第3日!D94:D111) -> 200 | H20: =COUNTA(第3日!B94:B111) -> 13 | I20: =SUM(第3日!F94:F111) -> 453 | J20: =SUM(第3日!G94:G111) -> 453 | K20: =SUM(第3日!H94:H111) -> 453 | L20: =IF(G20=0,0,MAX(0,(ROUNDUP(G20/第3日!G90,0)-1)*第3日!E90)) -> 43.78 | M20: =第3日!I90 -> 300 | N20: =IF(第3日!B91="点1·开启",1,0)+IF(第3日!C91="点2·开启",1,0)+IF(第3日!D91="点3·开启",1,0)+IF(第3日!E91="点4·开启",1,0)+IF(第3日!F91="点5·开启",1,0)+IF(第3日!G91="点6·开启",1,0) -> 6
A22: 第 4 日·白昼｜60 秒准备 → 铃兰 Boss → 击败后直接通关（无普通波次编号、无日终探索）
A24: 每日汇总
A25: 日 | B25: 普通波次 | C25: 基础敌人 | D25: 实际敌人 | E25: 预计息壤/队伍 | F25: 日终地下探索 AP
A26: 第1日 | B26: 4 | C26: =SUM(F9:F12) -> 12400 | D26: =SUM(G9:G12) -> 12400 | E26: =SUM(K9:K12) -> 16730 | F26: =全局设置!B16 -> 5
A27: 第2日 | B27: 4 | C27: =SUM(F13:F16) -> 8730 | D27: =SUM(G13:G16) -> 8730 | E27: =SUM(K13:K16) -> 39220 | F27: =全局设置!D16 -> 5
A28: 第3日 | B28: 4 | C28: =SUM(F17:F20) -> 680 | D28: =SUM(G17:G20) -> 680 | E28: =SUM(K17:K20) -> 1401 | F28: =全局设置!F16 -> 5
A29: 第4日 | B29: 0 | C29: 0 | D29: 0 | E29: 0 | F29: 无（Boss 后通关）
A33: 波次 | B33: 预计息壤/玩家 | C33: 预计息壤/队伍
A34: 第1波 | B34: =J9 -> 3000 | C34: =K9 -> 3000
A35: 第2波 | B35: =J10 -> 4050 | C35: =K10 -> 4050
A36: 第3波 | B36: =J11 -> 4540 | C36: =K11 -> 4540
A37: 第4波 | B37: =J12 -> 5140 | C37: =K12 -> 5140
A38: 第5波 | B38: =J13 -> 8000 | C38: =K13 -> 8000
A39: 第6波 | B39: =J14 -> 9060 | C39: =K14 -> 9060
A40: 第7波 | B40: =J15 -> 10410 | C40: =K15 -> 10410
A41: 第8波 | B41: =J16 -> 11750 | C41: =K16 -> 11750
A42: 第9波 | B42: =J17 -> 242 | C42: =K17 -> 242
A43: 第10波 | B43: =J18 -> 308 | C43: =K18 -> 308
A44: 第11波 | B44: =J19 -> 398 | C44: =K19 -> 398
A45: 第12波 | B45: =J20 -> 453 | C45: =K20 -> 453
A51: 波次 | B51: 实际敌人数
A52: 第1波 | B52: =G9 -> 3000
A53: 第2波 | B53: =G10 -> 3850
...

Sheet 全局设置
A1: 全局设置与四日战役契约
A2: 蓝色项目影响平衡预览；地下探索行动力会进入 schema v3 并由正式成长配置读取。
A4: 模拟参数 | B4: 当前值
A5: 玩家人数 | B5: 1
A6: 每名额外玩家敌人数增幅 | B6: 0.25
A7: 预计击杀率 | B7: 1
A8: 目标普通波次数 | B8: 12
A9: 总日数 | B9: 4
A10: 每日日内波次 | B10: 4
A11: Boss 接续于 | B11: 第12波之后
A12: Boss 日期 | B12: 第4日
A13: Boss 时段 | B13: 白昼
A15: 第 1～3 日地下探索行动力（独立输入）
A16: 第1日探索 AP | B16: 5 | C16: 第2日探索 AP | D16: 5 | E16: 第3日探索 AP | F16: 5
A18: 设计完整度
A19: 可回读波次 | B19: =COUNTIF(总览!E9:E20,"可回读")&" / 12" -> 12 / 12
A20: 总体状态 | B20: =IF(B19="12 / 12","完整","仍有待设计或需修正") -> 完整
A21: 敌人目录签名 | B21: b1fe8380d773e1597266e16f821f218f409f50807d0f37e8e2cf139bc0c16be8
A22: 回读契约 | B22: tower_defense_formal / schema v3
A24: 注意：本工作簿不会直接修改正式 wave_01～12.tres；Codex 会先校验 JSON 契约并明确审计差异。

Sheet 第1日
A1: ="第1日｜4 波配置｜日终地下探索 +"&全局设置!B16&" AP" -> 第1日｜4 波配置｜日终地下探索 +5 AP
A2: 第 1 波｜第 1 日·1/4｜白昼｜当前正式配置
A3: 波次名称 | B3: 第1波 | C3: 第1波 林地试探 | D3: 出生间隔(s) | E3: 0.1 | F3: 每Tick | G3: 1 | H3: 存活上限 | I3: 300
A4: 出生点 | B4: 点1·开启 | C4: 点2·开启 | D4: 点3·开启 | E4: 点4·开启 | F4: 点5·关闭 | G4: 点6·关闭 | H4: 波次校验 | I4: =IF(COUNTA(B7:B24)=0,"待设计",IF(COUNTIF(I7:I24,"需修正")>0,"需修正","可回读")) -> 可回读
A5: 仅编辑蓝色列、敌人数值和出生点；所有公式、稳定 ID 与 schema 字段由机器区自动生成。
A6: 槽位 | B6: 敌人（下拉选择） | C6: 基础数量 | D6: 实际数量 | E6: 息壤/击杀 | F6: 最大息壤/玩家 | G6: 预计息壤/玩家 | H6: 预计息壤/队伍 | I6: 校验
A7: 1 | B7: 史莱姆 | C7: 1300 | D7: =IF(B7="",0,ROUNDUP(C7*(1+(全局设置!$B$5-1)*全局设置!$B$6),0)) -> 1300 | E7: =IF(B7="",0,IFERROR(VLOOKUP(B7,敌人目录!$A$6:$M$68,13,FALSE),0)) -> 1 | F7: =D7*E7 -> 1300 | G7: =F7*全局设置!$B$7 -> 1300 | H7: =G7*全局设置!$B$5 -> 1300 | I7: =IF(AND(B7="",C7=""),"",IF(AND(B7<>"",C7>=1,COUNTIF($B$7:$B$24,B7)=1),"可回读","需修正")) -> 可回读
A8: 2 | B8: 火焰史莱姆 | C8: 400 | D8: =IF(B8="",0,ROUNDUP(C8*(1+(全局设置!$B$5-1)*全局设置!$B$6),0)) -> 400 | E8: =IF(B8="",0,IFERROR(VLOOKUP(B8,敌人目录!$A$6:$M$68,13,FALSE),0)) -> 1 | F8: =D8*E8 -> 400 | G8: =F8*全局设置!$B$7 -> 400 | H8: =G8*全局设置!$B$5 -> 400 | I8: =IF(AND(B8="",C8=""),"",IF(AND(B8<>"",C8>=1,COUNTIF($B$7:$B$24,B8)=1),"可回读","需修正")) -> 可回读
A9: 3 | B9: 普通原石虫 | C9: 500 | D9: =IF(B9="",0,ROUNDUP(C9*(1+(全局设置!$B$5-1)*全局设置!$B$6),0)) -> 500 | E9: =IF(B9="",0,IFERROR(VLOOKUP(B9,敌人目录!$A$6:$M$68,13,FALSE),0)) -> 1 | F9: =D9*E9 -> 500 | G9: =F9*全局设置!$B$7 -> 500 | H9: =G9*全局设置!$B$5 -> 500 | I9: =IF(AND(B9="",C9=""),"",IF(AND(B9<>"",C9>=1,COUNTIF($B$7:$B$24,B9)=1),"可回读","需修正")) -> 可回读
A10: 4 | B10: 迅捷原石虫 | C10: 300 | D10: =IF(B10="",0,ROUNDUP(C10*(1+(全局设置!$B$5-1)*全局设置!$B$6),0)) -> 300 | E10: =IF(B10="",0,IFERROR(VLOOKUP(B10,敌人目录!$A$6:$M$68,13,FALSE),0)) -> 1 | F10: =D10*E10 -> 300 | G10: =F10*全局设置!$B$7 -> 300 | H10: =G10*全局设置!$B$5 -> 300 | I10: =IF(AND(B10="",C10=""),"",IF(AND(B10<>"",C10>=1,COUNTIF($B$7:$B$24,B10)=1),"可回读","需修正")) -> 可回读
A11: 5 | B11: 火焰弹原石虫 | C11: 500 | D11: =IF(B11="",0,ROUNDUP(C11*(1+(全局设置!$B$5-1)*全局设置!$B$6),0)) -> 500 | E11: =IF(B11="",0,IFERROR(VLOOKUP(B11,敌人目录!$A$6:$M$68,13,FALSE),0)) -> 1 | F11: =D11*E11 -> 500 | G11: =F11*全局设置!$B$7 -> 500 | H11: =G11*全局设置!$B$5 -> 500 | I11: =IF(AND(B11="",C11=""),"",IF(AND(B11<>"",C11>=1,COUNTIF($B$7:$B$24,B11)=1),"可回读","需修正")) -> 可回读
A12: 6 | D12: =IF(B12="",0,ROUNDUP(C12*(1+(全局设置!$B$5-1)*全局设置!$B$6),0)) -> 0 | E12: =IF(B12="",0,IFERROR(VLOOKUP(B12,敌人目录!$A$6:$M$68,13,FALSE),0)) -> 0 | F12: =D12*E12 -> 0 | G12: =F12*全局设置!$B$7 -> 0 | H12: =G12*全局设置!$B$5 -> 0 | I12: =IF(AND(B12="",C12=""),"",IF(AND(B12<>"",C12>=1,COUNTIF($B$7:$B$24,B12)=1),"可回读","需修正"))
A13: 7 | D13: =IF(B13="",0,ROUNDUP(C13*(1+(全局设置!$B$5-1)*全局设置!$B$6),0)) -> 0 | E13: =IF(B13="",0,IFERROR(VLOOKUP(B13,敌人目录!$A$6:$M$68,13,FALSE),0)) -> 0 | F13: =D13*E13 -> 0 | G13: =F13*全局设置!$B$7 -> 0 | H13: =G13*全局设置!$B$5 -> 0 | I13: =IF(AND(B13="",C13=""),"",IF(AND(B13<>"",C13>=1,COUNTIF($B$7:$B$24,B13)=1),"可回读","需修正"))
A14: 8 | D14: =IF(B14="",0,ROUNDUP(C14*(1+(全局设置!$B$5-1)*全局设置!$B$6),0)) -> 0 | E14: =IF(B14="",0,IFERROR(VLOOKUP(B14,敌人目录!$A$6:$M$68,13,FALSE),0)) -> 0 | F14: =D14*E14 -> 0 | G14: =F14*全局设置!$B$7 -> 0 | H14: =G14*全局设置!$B$5 -> 0 | I14: =IF(AND(B14="",C14=""),"",IF(AND(B14<>"",C14>=1,COUNTIF($B$7:$B$24,B14)=1),"可回读","需修正"))
A15: 9 | D15: =IF(B15="",0,ROUNDUP(C15*(1+(全局设置!$B$5-1)*全局设置!$B$6),0)) -> 0 | E15: =IF(B15="",0,IFERROR(VLOOKUP(B15,敌人目录!$A$6:$M$68,13,FALSE),0)) -> 0 | F15: =D15*E15 -> 0 | G15: =F15*全局设置!$B$7 -> 0 | H15: =G15*全局设置!$B$5 -> 0 | I15: =IF(AND(B15="",C15=""),"",IF(AND(B15<>"",C15>=1,COUNTIF($B$7:$B$24,B15)=1),"可回读","需修正"))
A16: 10 | D16: =IF(B16="",0,ROUNDUP(C16*(1+(全局设置!$B$5-1)*全局设置!$B$6),0)) -> 0 | E16: =IF(B16="",0,IFERROR(VLOOKUP(B16,敌人目录!$A$6:$M$68,13,FALSE),0)) -> 0 | F16: =D16*E16 -> 0 | G16: =F16*全局设置!$B$7 -> 0 | H16: =G16*全局设置!$B$5 -> 0 | I16: =IF(AND(B16="",C16=""),"",IF(AND(B16<>"",C16>=1,COUNTIF($B$7:$B$24,B16)=1),"可回读","需修正"))
A17: 11 | D17: =IF(B17="",0,ROUNDUP(C17*(1+(全局设置!$B$5-1)*全局设置!$B$6),0)) -> 0 | E17: =IF(B17="",0,IFERROR(VLOOKUP(B17,敌人目录!$A$6:$M$68,13,FALSE),0)) -> 0 | F17: =D17*E17 -> 0 | G17: =F17*全局设置!$B$7 -> 0 | H17: =G17*全局设置!$B$5 -> 0 | I17: =IF(AND(B17="",C17=""),"",IF(AND(B17<>"",C17>=1,COUNTIF($B$7:$B$24,B17)=1),"可回读","需修正"))
A18: 12 | D18: =IF(B18="",0,ROUNDUP(C18*(1+(全局设置!$B$5-1)*全局设置!$B$6),0)) -> 0 | E18: =IF(B18="",0,IFERROR(VLOOKUP(B18,敌人目录!$A$6:$M$68,13,FALSE),0)) -> 0 | F18: =D18*E18 -> 0 | G18: =F18*全局设置!$B$7 -> 0 | H18: =G18*全局设置!$B$5 -> 0 | I18: =IF(AND(B18="",C18=""),"",IF(AND(B18<>"",C18>=1,COUNTIF($B$7:$B$24,B18)=1),"可回读","需修正"))
A19: 13 | D19: =IF(B19="",0,ROUNDUP(C19*(1+(全局设置!$B$5-1)*全局设置!$B$6),0)) -> 0 | E19: =IF(B19="",0,IFERROR(VLOOKUP(B19,敌人目录!$A$6:$M$68,13,FALSE),0)) -> 0 | F19: =D19*E19 -> 0 | G19: =F19*全局设置!$B$7 -> 0 | H19: =G19*全局设置!$B$5 -> 0 | I19: =IF(AND(B19="",C19=""),"",IF(AND(B19<>"",C19>=1,COUNTIF($B$7:$B$24,B19)=1),"可回读","需修正"))
A20: 14 | D20: =IF(B20="",0,ROUNDUP(C20*(1+(全局设置!$B$5-1)*全局设置!$B$6),0)) -> 0 | E20: =IF(B20="",0,IFERROR(VLOOKUP(B20,敌人目录!$A$6:$M$68,13,FALSE),0)) -> 0 | F20: =D20*E20 -> 0 | G20: =F20*全局设置!$B$7 -> 0 | H20: =G20*全局设置!$B$5 -> 0 | I20: =IF(AND(B20="",C20=""),"",IF(AND(B20<>"",C20>=1,COUNTIF($B$7:$B$24,B20)=1),"可回读","需修正"))
A21: 15 | D21: =IF(B21="",0,ROUNDUP(C21*(1+(全局设置!$B$5-1)*全局设置!$B$6),0)) -> 0 | E21: =IF(B21="",0,IFERROR(VLOOKUP(B21,敌人目录!$A$6:$M$68,13,FALSE),0)) -> 0 | F21: =D21*E21 -> 0 | G21: =F21*全局设置!$B$7 -> 0 | H21: =G21*全局设置!$B$5 -> 0 | I21: =IF(AND(B21="",C21=""),"",IF(AND(B21<>"",C21>=1,COUNTIF($B$7:$B$24,B21)=1),"可回读","需修正"))
A22: 16 | D22: =IF(B22="",0,ROUNDUP(C22*(1+(全局设置!$B$5-1)*全局设置!$B$6),0)) -> 0 | E22: =IF(B22="",0,IFERROR(VLOOKUP(B22,敌人目录!$A$6:$M$68,13,FALSE),0)) -> 0 | F22: =D22*E22 -> 0 | G22: =F22*全局设置!$B$7 -> 0 | H22: =G22*全局设置!$B$5 -> 0 | I22: =IF(AND(B22="",C22=""),"",IF(AND(B22<>"",C22>=1,COUNTIF($B$7:$B$24,B22)=1),"可回读","需修正"))
A23: 17 | D23: =IF(B23="",0,ROUNDUP(C23*(1+(全局设置!$B$5-1)*全局设置!$B$6),0)) -> 0 | E23: =IF(B23="",0,IFERROR(VLOOKUP(B23,敌人目录!$A$6:$M$68,13,FALSE),0)) -> 0 | F23: =D23*E23 -> 0 | G23: =F23*全局设置!$B$7 -> 0 | H23: =G23*全局设置!$B$5 -> 0 | I23: =IF(AND(B23="",C23=""),"",IF(AND(B23<>"",C23>=1,COUNTIF($B$7:$B$24,B23)=1),"可回读","需修正"))
A24: 18 | D24: =IF(B24="",0,ROUNDUP(C24*(1+(全局设置!$B$5-1)*全局设置!$B$6),0)) -> 0 | E24: =IF(B24="",0,IFERROR(VLOOKUP(B24,敌人目录!$A$6:$M$68,13,FALSE),0)) -> 0 | F24: =D24*E24 -> 0 | G24: =F24*全局设置!$B$7 -> 0 | H24: =G24*全局设置!$B$5 -> 0 | I24: =IF(AND(B24="",C24=""),"",IF(AND(B24<>"",C24>=1,COUNTIF($B$7:$B$24,B24)=1),"可回读","需修正"))
A26: 基础总数 | B26: =SUM(C7:C24) -> 3000 | C26: 实际总数 | D26: =SUM(D7:D24) -> 3000 | E26: 最大息壤/玩家 | F26: =SUM(F7:F24) -> 3000 | G26: 预计息壤/玩家 | H26: =SUM(G7:G24) -> 3000
A27: 预计息壤/队伍 | B27: =SUM(H7:H24) -> 3000 | C27: 说明 | D27: 预计息壤 = 实际数量 × 固定息壤 × 击杀率；已移除每日命运倍率。
A31: 第 2 波｜第 1 日·2/4｜白昼｜当前正式配置
A32: 波次名称 | B32: 第2波 | C32: 第2波 迅影与硬壳 | D32: 出生间隔(s) | E32: 0.1 | F32: 每Tick | G32: 1 | H32: 存活上限 | I32: 300
A33: 出生点 | B33: 点1·开启 | C33: 点2·开启 | D33: 点3·开启 | E33: 点4·开启 | F33: 点5·关闭 | G33: 点6·关闭 | H33: 波次校验 | I33: =IF(COUNTA(B36:B53)=0,"待设计",IF(COUNTIF(I36:I53,"需修正")>0,"需修正","可回读")) -> 可回读
A34: 仅编辑蓝色列、敌人数值和出生点；所有公式、稳定 ID 与 schema 字段由机器区自动生成。
A35: 槽位 | B35: 敌人（下拉选择） | C35: 基础数量 | D35: 实际数量 | E35: 息壤/击杀 | F35: 最大息壤/玩家 | G35: 预计息壤/玩家 | H35: 预计息壤/队伍 | I35: 校验
A36: 1 | B36: 史莱姆 | C36: 2000 | D36: =IF(B36="",0,ROUNDUP(C36*(1+(全局设置!$B$5-1)*全局设置!$B$6),0)) -> 2000 | E36: =IF(B36="",0,IFERROR(VLOOKUP(B36,敌人目录!$A$6:$M$68,13,FALSE),0)) -> 1 | F36: =D36*E36 -> 2000 | G36: =F36*全局设置!$B$7 -> 2000 | H36: =G36*全局设置!$B$5 -> 2000 | I36: =IF(AND(B36="",C36=""),"",IF(AND(B36<>"",C36>=1,COUNTIF($B$36:$B$53,B36)=1),"可回读","需修正")) -> 可回读
A37: 2 | B37: 火焰史莱姆 | C37: 400 | D37: =IF(B37="",0,ROUNDUP(C37*(1+(全局设置!$B$5-1)*全局设置!$B$6),0)) -> 400 | E37: =IF(B37="",0,IFERROR(VLOOKUP(B37,敌人目录!$A$6:$M$68,13,FALSE),0)) -> 1 | F37: =D37*E37 -> 400 | G37: =F37*全局设置!$B$7 -> 400 | H37: =G37*全局设置!$B$5 -> 400 | I37: =IF(AND(B37="",C37=""),"",IF(AND(B37<>"",C37>=1,COUNTIF($B$36:$B$53,B37)=1),"可回读","需修正")) -> 可回读
A38: 3 | B38: 普通原石虫 | C38: 500 | D38: =IF(B38="",0,ROUNDUP(C38*(1+(全局设置!$B$5-1)*全局设置!$B$6),0)) -> 500 | E38: =IF(B38="",0,IFERROR(VLOOKUP(B38,敌人目录!$A$6:$M$68,13,FALSE),0)) -> 1 | F38: =D38*E38 -> 500 | G38: =F38*全局设置!$B$7 -> 500 | H38: =G38*全局设置!$B$5 -> 500 | I38: =IF(AND(B38="",C38=""),"",IF(AND(B38<>"",C38>=1,COUNTIF($B$36:$B$53,B38)=1),"可回读","需修正")) -> 可回读
A39: 4 | B39: 迅捷原石虫 | C39: 300 | D39: =IF(B39="",0,ROUNDUP(C39*(1+(全局设置!$B$5-1)*全局设置!$B$6),0)) -> 300 | E39: =IF(B39="",0,IFERROR(VLOOKUP(B39,敌人目录!$A$6:$M$68,13,FALSE),0)) -> 1 | F39: =D39*E39 -> 300 | G39: =F39*全局设置!$B$7 -> 300 | H39: =G39*全局设置!$B$5 -> 300 | I39: =IF(AND(B39="",C39=""),"",IF(AND(B39<>"",C39>=1,COUNTIF($B$36:$B$53,B39)=1),"可回读","需修正")) -> 可回读
A40: 5 | B40: 硬壳原石虫 | C40: 200 | D40: =IF(B40="",0,ROUNDUP(C40*(1+(全局设置!$B$5-1)*全局设置!$B$6),0)) -> 200 | E40: =IF(B40="",0,IFERROR(VLOOKUP(B40,敌人目录!$A$6:$M$68,13,FALSE),0)) -> 2 | F40: =D40*E40 -> 400 | G40: =F40*全局设置!$B$7 -> 400 | H40: =G40*全局设置!$B$5 -> 400 | I40: =IF(AND(B40="",C40=""),"",IF(AND(B40<>"",C40>=1,COUNTIF($B$36:$B$53,B40)=1),"可回读","需修正")) -> 可回读
A41: 6 | B41: 火焰弹原石虫 | C41: 50 | D41: =IF(B41="",0,ROUNDUP(C41*(1+(全局设置!$B$5-1)*全局设置!$B$6),0)) -> 50 | E41: =IF(B41="",0,IFERROR(VLOOKUP(B41,敌人目录!$A$6:$M$68,13,FALSE),0)) -> 1 | F41: =D41*E41 -> 50 | G41: =F41*全局设置!$B$7 -> 50 | H41: =G41*全局设置!$B$5 -> 50 | I41: =IF(AND(B41="",C41=""),"",IF(AND(B41<>"",C41>=1,COUNTIF($B$36:$B$53,B41)=1),"可回读","需修正")) -> 可回读
A42: 7 | B42: 寒冰史莱姆 | C42: 400 | D42: =IF(B42="",0,ROUNDUP(C42*(1+(全局设置!$B$5-1)*全局设置!$B$6),0)) -> 400 | E42: =IF(B42="",0,IFERROR(VLOOKUP(B42,敌人目录!$A$6:$M$68,13,FALSE),0)) -> 1 | F42: =D42*E42 -> 400 | G42: =F42*全局设置!$B$7 -> 400 | H42: =G42*全局设置!$B$5 -> 400 | I42: =IF(AND(B42="",C42=""),"",IF(AND(B42<>"",C42>=1,COUNTIF($B$36:$B$53,B42)=1),"可回读","需修正")) -> 可回读
A43: 8 | D43: =IF(B43="",0,ROUNDUP(C43*(1+(全局设置!$B$5-1)*全局设置!$B$6),0)) -> 0 | E43: =IF(B43="",0,IFERROR(VLOOKUP(B43,敌人目录!$A$6:$M$68,13,FALSE),0)) -> 0 | F43: =D43*E43 -> 0 | G43: =F43*全局设置!$B$7 -> 0 | H43: =G43*全局设置!$B$5 -> 0 | I43: =IF(AND(B43="",C43=""),"",IF(AND(B43<>"",C43>=1,COUNTIF($B$36:$B$53,B43)=1),"可回读","需修正"))
A44: 9 | D44: =IF(B44="",0,ROUNDUP(C44*(1+(全局设置!$B$5-1)*全局设置!$B$6),0)) -> 0 | E44: =IF(B44="",0,IFERROR(VLOOKUP(B44,敌人目录!$A$6:$M$68,13,FALSE),0)) -> 0 | F44: =D44*E44 -> 0 | G44: =F44*全局设置!$B$7 -> 0 | H44: =G44*全局设置!$B$5 -> 0 | I44: =IF(AND(B44="",C44=""),"",IF(AND(B44<>"",C44>=1,COUNTIF($B$36:$B$53,B44)=1),"可回读","需修正"))
...

Sheet 第2日
A1: ="第2日｜4 波配置｜日终地下探索 +"&全局设置!D16&" AP" -> 第2日｜4 波配置｜日终地下探索 +5 AP
A2: 第 5 波｜第 2 日·1/4｜白昼｜当前正式配置
A3: 波次名称 | B3: 第5波 | C3: 第5波 沼泽先遣 | D3: 出生间隔(s) | E3: 0.1 | F3: 每Tick | G3: 4 | H3: 存活上限 | I3: 300
A4: 出生点 | B4: 点1·开启 | C4: 点2·开启 | D4: 点3·开启 | E4: 点4·开启 | F4: 点5·开启 | G4: 点6·开启 | H4: 波次校验 | I4: =IF(COUNTA(B7:B24)=0,"待设计",IF(COUNTIF(I7:I24,"需修正")>0,"需修正","可回读")) -> 可回读
A5: 仅编辑蓝色列、敌人数值和出生点；所有公式、稳定 ID 与 schema 字段由机器区自动生成。
A6: 槽位 | B6: 敌人（下拉选择） | C6: 基础数量 | D6: 实际数量 | E6: 息壤/击杀 | F6: 最大息壤/玩家 | G6: 预计息壤/玩家 | H6: 预计息壤/队伍 | I6: 校验
A7: 1 | B7: 史莱姆 | C7: 350 | D7: =IF(B7="",0,ROUNDUP(C7*(1+(全局设置!$B$5-1)*全局设置!$B$6),0)) -> 350 | E7: =IF(B7="",0,IFERROR(VLOOKUP(B7,敌人目录!$A$6:$M$68,13,FALSE),0)) -> 1 | F7: =D7*E7 -> 350 | G7: =F7*全局设置!$B$7 -> 350 | H7: =G7*全局设置!$B$5 -> 350 | I7: =IF(AND(B7="",C7=""),"",IF(AND(B7<>"",C7>=1,COUNTIF($B$7:$B$24,B7)=1),"可回读","需修正")) -> 可回读
A8: 2 | B8: 普通原石虫 | C8: 300 | D8: =IF(B8="",0,ROUNDUP(C8*(1+(全局设置!$B$5-1)*全局设置!$B$6),0)) -> 300 | E8: =IF(B8="",0,IFERROR(VLOOKUP(B8,敌人目录!$A$6:$M$68,13,FALSE),0)) -> 1 | F8: =D8*E8 -> 300 | G8: =F8*全局设置!$B$7 -> 300 | H8: =G8*全局设置!$B$5 -> 300 | I8: =IF(AND(B8="",C8=""),"",IF(AND(B8<>"",C8>=1,COUNTIF($B$7:$B$24,B8)=1),"可回读","需修正")) -> 可回读
A9: 3 | B9: 迅捷原石虫 | C9: 250 | D9: =IF(B9="",0,ROUNDUP(C9*(1+(全局设置!$B$5-1)*全局设置!$B$6),0)) -> 250 | E9: =IF(B9="",0,IFERROR(VLOOKUP(B9,敌人目录!$A$6:$M$68,13,FALSE),0)) -> 1 | F9: =D9*E9 -> 250 | G9: =F9*全局设置!$B$7 -> 250 | H9: =G9*全局设置!$B$5 -> 250 | I9: =IF(AND(B9="",C9=""),"",IF(AND(B9<>"",C9>=1,COUNTIF($B$7:$B$24,B9)=1),"可回读","需修正")) -> 可回读
A10: 4 | B10: 自爆原石虫 | C10: 200 | D10: =IF(B10="",0,ROUNDUP(C10*(1+(全局设置!$B$5-1)*全局设置!$B$6),0)) -> 200 | E10: =IF(B10="",0,IFERROR(VLOOKUP(B10,敌人目录!$A$6:$M$68,13,FALSE),0)) -> 1 | F10: =D10*E10 -> 200 | G10: =F10*全局设置!$B$7 -> 200 | H10: =G10*全局设置!$B$5 -> 200 | I10: =IF(AND(B10="",C10=""),"",IF(AND(B10<>"",C10>=1,COUNTIF($B$7:$B$24,B10)=1),"可回读","需修正")) -> 可回读
A11: 5 | B11: 火焰弹原石虫 | C11: 200 | D11: =IF(B11="",0,ROUNDUP(C11*(1+(全局设置!$B$5-1)*全局设置!$B$6),0)) -> 200 | E11: =IF(B11="",0,IFERROR(VLOOKUP(B11,敌人目录!$A$6:$M$68,13,FALSE),0)) -> 1 | F11: =D11*E11 -> 200 | G11: =F11*全局设置!$B$7 -> 200 | H11: =G11*全局设置!$B$5 -> 200 | I11: =IF(AND(B11="",C11=""),"",IF(AND(B11<>"",C11>=1,COUNTIF($B$7:$B$24,B11)=1),"可回读","需修正")) -> 可回读
A12: 6 | B12: 硬壳原石虫 | C12: 250 | D12: =IF(B12="",0,ROUNDUP(C12*(1+(全局设置!$B$5-1)*全局设置!$B$6),0)) -> 250 | E12: =IF(B12="",0,IFERROR(VLOOKUP(B12,敌人目录!$A$6:$M$68,13,FALSE),0)) -> 2 | F12: =D12*E12 -> 500 | G12: =F12*全局设置!$B$7 -> 500 | H12: =G12*全局设置!$B$5 -> 500 | I12: =IF(AND(B12="",C12=""),"",IF(AND(B12<>"",C12>=1,COUNTIF($B$7:$B$24,B12)=1),"可回读","需修正")) -> 可回读
A13: 7 | B13: 守护者原石虫 | C13: 150 | D13: =IF(B13="",0,ROUNDUP(C13*(1+(全局设置!$B$5-1)*全局设置!$B$6),0)) -> 150 | E13: =IF(B13="",0,IFERROR(VLOOKUP(B13,敌人目录!$A$6:$M$68,13,FALSE),0)) -> 2 | F13: =D13*E13 -> 300 | G13: =F13*全局设置!$B$7 -> 300 | H13: =G13*全局设置!$B$5 -> 300 | I13: =IF(AND(B13="",C13=""),"",IF(AND(B13<>"",C13>=1,COUNTIF($B$7:$B$24,B13)=1),"可回读","需修正")) -> 可回读
A14: 8 | B14: 翠壳原石虫 | C14: 100 | D14: =IF(B14="",0,ROUNDUP(C14*(1+(全局设置!$B$5-1)*全局设置!$B$6),0)) -> 100 | E14: =IF(B14="",0,IFERROR(VLOOKUP(B14,敌人目录!$A$6:$M$68,13,FALSE),0)) -> 2 | F14: =D14*E14 -> 200 | G14: =F14*全局设置!$B$7 -> 200 | H14: =G14*全局设置!$B$5 -> 200 | I14: =IF(AND(B14="",C14=""),"",IF(AND(B14<>"",C14>=1,COUNTIF($B$7:$B$24,B14)=1),"可回读","需修正")) -> 可回读
A15: 9 | B15: 战斗机器人 | C15: 80 | D15: =IF(B15="",0,ROUNDUP(C15*(1+(全局设置!$B$5-1)*全局设置!$B$6),0)) -> 80 | E15: =IF(B15="",0,IFERROR(VLOOKUP(B15,敌人目录!$A$6:$M$68,13,FALSE),0)) -> 10 | F15: =D15*E15 -> 800 | G15: =F15*全局设置!$B$7 -> 800 | H15: =G15*全局设置!$B$5 -> 800 | I15: =IF(AND(B15="",C15=""),"",IF(AND(B15<>"",C15>=1,COUNTIF($B$7:$B$24,B15)=1),"可回读","需修正")) -> 可回读
A16: 10 | B16: 持枪战斗机器人 | C16: 60 | D16: =IF(B16="",0,ROUNDUP(C16*(1+(全局设置!$B$5-1)*全局设置!$B$6),0)) -> 60 | E16: =IF(B16="",0,IFERROR(VLOOKUP(B16,敌人目录!$A$6:$M$68,13,FALSE),0)) -> 10 | F16: =D16*E16 -> 600 | G16: =F16*全局设置!$B$7 -> 600 | H16: =G16*全局设置!$B$5 -> 600 | I16: =IF(AND(B16="",C16=""),"",IF(AND(B16<>"",C16>=1,COUNTIF($B$7:$B$24,B16)=1),"可回读","需修正")) -> 可回读
A17: 11 | B17: AK猫猫虫 | C17: 60 | D17: =IF(B17="",0,ROUNDUP(C17*(1+(全局设置!$B$5-1)*全局设置!$B$6),0)) -> 60 | E17: =IF(B17="",0,IFERROR(VLOOKUP(B17,敌人目录!$A$6:$M$68,13,FALSE),0)) -> 20 | F17: =D17*E17 -> 1200 | G17: =F17*全局设置!$B$7 -> 1200 | H17: =G17*全局设置!$B$5 -> 1200 | I17: =IF(AND(B17="",C17=""),"",IF(AND(B17<>"",C17>=1,COUNTIF($B$7:$B$24,B17)=1),"可回读","需修正")) -> 可回读
A18: 12 | B18: 冲锋枪 Capoo | C18: 40 | D18: =IF(B18="",0,ROUNDUP(C18*(1+(全局设置!$B$5-1)*全局设置!$B$6),0)) -> 40 | E18: =IF(B18="",0,IFERROR(VLOOKUP(B18,敌人目录!$A$6:$M$68,13,FALSE),0)) -> 25 | F18: =D18*E18 -> 1000 | G18: =F18*全局设置!$B$7 -> 1000 | H18: =G18*全局设置!$B$5 -> 1000 | I18: =IF(AND(B18="",C18=""),"",IF(AND(B18<>"",C18>=1,COUNTIF($B$7:$B$24,B18)=1),"可回读","需修正")) -> 可回读
... A21: 15 | B21: 石头人 | C21: 10 | D21: =IF(B21="",0,ROUNDUP(C21*(1+(全局设置!$B$5-1)*全局设置!$B$6),0)) -> 10 | E21: =IF(B21="",0,IFERROR(VLOOKUP(B21,敌人目录!$A$6:$M$68,13,FALSE),0)) -> 50 | F21: =D21*E21 -> 500 | G21: =F21*全局设置!$B$7 -> 500 | H21: =G21*全局设置!$B$5 -> 500 | I21: =IF(AND(B21="",C21=""),"",IF(AND(B21<>"",C21>=1,COUNTIF($B$7:$B$24,B21)=1),"可回读","需修正")) -> 可回读
A22: 16 | D22: =IF(B22="",0,ROUNDUP(C22*(1+(全局设置!$B$5-1)*全局设置!$B$6),0)) -> 0 | E22: =IF(B22="",0,IFERROR(VLOOKUP(B22,敌人目录!$A$6:$M$68,13,FALSE),0)) -> 0 | F22: =D22*E22 -> 0 | G22: =F22*全局设置!$B$7 -> 0 | H22: =G22*全局设置!$B$5 -> 0 | I22: =IF(AND(B22="",C22=""),"",IF(AND(B22<>"",C22>=1,COUNTIF($B$7:$B$24,B22)=1),"可回读","需修正"))
A23: 17 | D23: =IF(B23="",0,ROUNDUP(C23*(1+(全局设置!$B$5-1)*全局设置!$B$6),0)) -> 0 | E23: =IF(B23="",0,IFERROR(VLOOKUP(B23,敌人目录!$A$6:$M$68,13,FALSE),0)) -> 0 | F23: =D23*E23 -> 0 | G23: =F23*全局设置!$B$7 -> 0 | H23: =G23*全局设置!$B$5 -> 0 | I23: =IF(AND(B23="",C23=""),"",IF(AND(B23<>"",C23>=1,COUNTIF($B$7:$B$24,B23)=1),"可回读","需修正"))
A24: 18 | D24: =IF(B24="",0,ROUNDUP(C24*(1+(全局设置!$B$5-1)*全局设置!$B$6),0)) -> 0 | E24: =IF(B24="",0,IFERROR(VLOOKUP(B24,敌人目录!$A$6:$M$68,13,FALSE),0)) -> 0 | F24: =D24*E24 -> 0 | G24: =F24*全局设置!$B$7 -> 0 | H24: =G24*全局设置!$B$5 -> 0 | I24: =IF(AND(B24="",C24=""),"",IF(AND(B24<>"",C24>=1,COUNTIF($B$7:$B$24,B24)=1),"可回读","需修正"))
A26: 基础总数 | B26: =SUM(C7:C24) -> 2100 | C26: 实际总数 | D26: =SUM(D7:D24) -> 2100 | E26: 最大息壤/玩家 | F26: =SUM(F7:F24) -> 8000 | G26: 预计息壤/玩家 | H26: =SUM(G7:G24) -> 8000
A27: 预计息壤/队伍 | B27: =SUM(H7:H24) -> 8000 | C27: 说明 | D27: 预计息壤 = 实际数量 × 固定息壤 × 击杀率；已移除每日命运倍率。
A31: 第 6 波｜第 2 日·2/4｜白昼｜当前正式配置
A32: 波次名称 | B32: 第6波 | C32: 第6波 守护阵列 | D32: 出生间隔(s) | E32: 0.09 | F32: 每Tick | G32: 1 | H32: 存活上限 | I32: 275
A33: 出生点 | B33: 点1·开启 | C33: 点2·开启 | D33: 点3·开启 | E33: 点4·开启 | F33: 点5·开启 | G33: 点6·开启 | H33: 波次校验 | I33: =IF(COUNTA(B36:B53)=0,"待设计",IF(COUNTIF(I36:I53,"需修正")>0,"需修正","可回读")) -> 可回读
A34: 仅编辑蓝色列、敌人数值和出生点；所有公式、稳定 ID 与 schema 字段由机器区自动生成。
A35: 槽位 | B35: 敌人（下拉选择） | C35: 基础数量 | D35: 实际数量 | E35: 息壤/击杀 | F35: 最大息壤/玩家 | G35: 预计息壤/玩家 | H35: 预计息壤/队伍 | I35: 校验
A36: 1 | B36: 史莱姆 | C36: 300 | D36: =IF(B36="",0,ROUNDUP(C36*(1+(全局设置!$B$5-1)*全局设置!$B$6),0)) -> 300 | E36: =IF(B36="",0,IFERROR(VLOOKUP(B36,敌人目录!$A$6:$M$68,13,FALSE),0)) -> 1 | F36: =D36*E36 -> 300 | G36: =F36*全局设置!$B$7 -> 300 | H36: =G36*全局设置!$B$5 -> 300 | I36: =IF(AND(B36="",C36=""),"",IF(AND(B36<>"",C36>=1,COUNTIF($B$36:$B$53,B36)=1),"可回读","需修正")) -> 可回读
A37: 2 | B37: 火焰史莱姆 | C37: 200 | D37: =IF(B37="",0,ROUNDUP(C37*(1+(全局设置!$B$5-1)*全局设置!$B$6),0)) -> 200 | E37: =IF(B37="",0,IFERROR(VLOOKUP(B37,敌人目录!$A$6:$M$68,13,FALSE),0)) -> 1 | F37: =D37*E37 -> 200 | G37: =F37*全局设置!$B$7 -> 200 | H37: =G37*全局设置!$B$5 -> 200 | I37: =IF(AND(B37="",C37=""),"",IF(AND(B37<>"",C37>=1,COUNTIF($B$36:$B$53,B37)=1),"可回读","需修正")) -> 可回读
A38: 3 | B38: 寒冰史莱姆 | C38: 200 | D38: =IF(B38="",0,ROUNDUP(C38*(1+(全局设置!$B$5-1)*全局设置!$B$6),0)) -> 200 | E38: =IF(B38="",0,IFERROR(VLOOKUP(B38,敌人目录!$A$6:$M$68,13,FALSE),0)) -> 1 | F38: =D38*E38 -> 200 | G38: =F38*全局设置!$B$7 -> 200 | H38: =G38*全局设置!$B$5 -> 200 | I38: =IF(AND(B38="",C38=""),"",IF(AND(B38<>"",C38>=1,COUNTIF($B$36:$B$53,B38)=1),"可回读","需修正")) -> 可回读
A39: 4 | B39: 普通原石虫 | C39: 260 | D39: =IF(B39="",0,ROUNDUP(C39*(1+(全局设置!$B$5-1)*全局设置!$B$6),0)) -> 260 | E39: =IF(B39="",0,IFERROR(VLOOKUP(B39,敌人目录!$A$6:$M$68,13,FALSE),0)) -> 1 | F39: =D39*E39 -> 260 | G39: =F39*全局设置!$B$7 -> 260 | H39: =G39*全局设置!$B$5 -> 260 | I39: =IF(AND(B39="",C39=""),"",IF(AND(B39<>"",C39>=1,COUNTIF($B$36:$B$53,B39)=1),"可回读","需修正")) -> 可回读
A40: 5 | B40: 迅捷原石虫 | C40: 200 | D40: =IF(B40="",0,ROUNDUP(C40*(1+(全局设置!$B$5-1)*全局设置!$B$6),0)) -> 200 | E40: =IF(B40="",0,IFERROR(VLOOKUP(B40,敌人目录!$A$6:$M$68,13,FALSE),0)) -> 1 | F40: =D40*E40 -> 200 | G40: =F40*全局设置!$B$7 -> 200 | H40: =G40*全局设置!$B$5 -> 200 | I40: =IF(AND(B40="",C40=""),"",IF(AND(B40<>"",C40>=1,COUNTIF($B$36:$B$53,B40)=1),"可回读","需修正")) -> 可回读
A41: 6 | B41: 自爆原石虫 | C41: 150 | D41: =IF(B41="",0,ROUNDUP(C41*(1+(全局设置!$B$5-1)*全局设置!$B$6),0)) -> 150 | E41: =IF(B41="",0,IFERROR(VLOOKUP(B41,敌人目录!$A$6:$M$68,13,FALSE),0)) -> 1 | F41: =D41*E41 -> 150 | G41: =F41*全局设置!$B$7 -> 150 | H41: =G41*全局设置!$B$5 -> 150 | I41: =IF(AND(B41="",C41=""),"",IF(AND(B41<>"",C41>=1,COUNTIF($B$36:$B$53,B41)=1),"可回读","需修正")) -> 可回读
A42: 7 | B42: 紫晶自爆原石虫 | C42: 100 | D42: =IF(B42="",0,ROUNDUP(C42*(1+(全局设置!$B$5-1)*全局设置!$B$6),0)) -> 100 | E42: =IF(B42="",0,IFERROR(VLOOKUP(B42,敌人目录!$A$6:$M$68,13,FALSE),0)) -> 2 | F42: =D42*E42 -> 200 | G42: =F42*全局设置!$B$7 -> 200 | H42: =G42*全局设置!$B$5 -> 200 | I42: =IF(AND(B42="",C42=""),"",IF(AND(B42<>"",C42>=1,COUNTIF($B$36:$B$53,B42)=1),"可回读","需修正")) -> 可回读
A43: 8 | B43: 火焰弹原石虫 | C43: 150 | D43: =IF(B43="",0,ROUNDUP(C43*(1+(全局设置!$B$5-1)*全局设置!$B$6),0)) -> 150 | E43: =IF(B43="",0,IFERROR(VLOOKUP(B43,敌人目录!$A$6:$M$68,13,FALSE),0)) -> 1 | F43: =D43*E43 -> 150 | G43: =F43*全局设置!$B$7 -> 150 | H43: =G43*全局设置!$B$5 -> 150 | I43: =IF(AND(B43="",C43=""),"",IF(AND(B43<>"",C43>=1,COUNTIF($B$36:$B$53,B43)=1),"可回读","需修正")) -> 可回读
A44: 9 | B44: 硬壳原石虫 | C44: 300 | D44: =IF(B44="",0,ROUNDUP(C44*(1+(全局设置!$B$5-1)*全局设置!$B$6),0)) -> 300 | E44: =IF(B44="",0,IFERROR(VLOOKUP(B44,敌人目录!$A$6:$M$68,13,FALSE),0)) -> 2 | F44: =D44*E44 -> 600 | G44: =F44*全局设置!$B$7 -> 600 | H44: =G44*全局设置!$B$5 -> 600 | I44: =IF(AND(B44="",C44=""),"",IF(AND(B44<>"",C44>=1,COUNTIF($B$36:$B$53,B44)=1),"可回读","需修正")) -> 可回读
A45: 10 | B45: 翠壳原石虫 | C45: 100 | D45: =IF(B45="",0,ROUNDUP(C45*(1+(全局设置!$B$5-1)*全局设置!$B$6),0)) -> 100 | E45: =IF(B45="",0,IFERROR(VLOOKUP(B45,敌人目录!$A$6:$M$68,13,FALSE),0)) -> 2 | F45: =D45*E45 -> 200 | G45: =F45*全局设置!$B$7 -> 200 | H45: =G45*全局设置!$B$5 -> 200 | I45: =IF(AND(B45="",C45=""),"",IF(AND(B45<>"",C45>=1,COUNTIF($B$36:$B$53,B45)=1),"可回读","需修正")) -> 可回读
A46: 11 | B46: 守护者原石虫 | C46: 50 | D46: =IF(B46="",0,ROUNDUP(C46*(1+(全局设置!$B$5-1)*全局设置!$B$6),0)) -> 50 | E46: =IF(B46="",0,IFERROR(VLOOKUP(B46,敌人目录!$A$6:$M$68,13,FALSE),0)) -> 2 | F46: =D46*E46 -> 100 | G46: =F46*全局设置!$B$7 -> 100 | H46: =G46*全局设置!$B$5 -> 100 | I46: =IF(AND(B46="",C46=""),"",IF(AND(B46<>"",C46>=1,COUNTIF($B$36:$B$53,B46)=1),"可回读","需修正")) -> 可回读
...

Sheet 第3日
A1: ="第3日｜4 波配置｜日终地下探索 +"&全局设置!F16&" AP" -> 第3日｜4 波配置｜日终地下探索 +5 AP
A2: 第 9 波｜第 3 日·1/4｜白昼｜当前正式配置
A3: 波次名称 | B3: 第9波 | C3: 第9波 城镇前锋 | D3: 出生间隔(s) | E3: 0.28 | F3: 每Tick | G3: 1 | H3: 存活上限 | I3: 300
A4: 出生点 | B4: 点1·开启 | C4: 点2·开启 | D4: 点3·开启 | E4: 点4·开启 | F4: 点5·开启 | G4: 点6·开启 | H4: 波次校验 | I4: =IF(COUNTA(B7:B24)=0,"待设计",IF(COUNTIF(I7:I24,"需修正")>0,"需修正","可回读")) -> 可回读
A5: 仅编辑蓝色列、敌人数值和出生点；所有公式、稳定 ID 与 schema 字段由机器区自动生成。
A6: 槽位 | B6: 敌人（下拉选择） | C6: 基础数量 | D6: 实际数量 | E6: 息壤/击杀 | F6: 最大息壤/玩家 | G6: 预计息壤/玩家 | H6: 预计息壤/队伍 | I6: 校验
A7: 1 | B7: 普通原石虫 | C7: 26 | D7: =IF(B7="",0,ROUNDUP(C7*(1+(全局设置!$B$5-1)*全局设置!$B$6),0)) -> 26 | E7: =IF(B7="",0,IFERROR(VLOOKUP(B7,敌人目录!$A$6:$M$68,13,FALSE),0)) -> 1 | F7: =D7*E7 -> 26 | G7: =F7*全局设置!$B$7 -> 26 | H7: =G7*全局设置!$B$5 -> 26 | I7: =IF(AND(B7="",C7=""),"",IF(AND(B7<>"",C7>=1,COUNTIF($B$7:$B$24,B7)=1),"可回读","需修正")) -> 可回读
A8: 2 | B8: 迅捷原石虫 | C8: 20 | D8: =IF(B8="",0,ROUNDUP(C8*(1+(全局设置!$B$5-1)*全局设置!$B$6),0)) -> 20 | E8: =IF(B8="",0,IFERROR(VLOOKUP(B8,敌人目录!$A$6:$M$68,13,FALSE),0)) -> 1 | F8: =D8*E8 -> 20 | G8: =F8*全局设置!$B$7 -> 20 | H8: =G8*全局设置!$B$5 -> 20 | I8: =IF(AND(B8="",C8=""),"",IF(AND(B8<>"",C8>=1,COUNTIF($B$7:$B$24,B8)=1),"可回读","需修正")) -> 可回读
A9: 3 | B9: 硬壳原石虫 | C9: 20 | D9: =IF(B9="",0,ROUNDUP(C9*(1+(全局设置!$B$5-1)*全局设置!$B$6),0)) -> 20 | E9: =IF(B9="",0,IFERROR(VLOOKUP(B9,敌人目录!$A$6:$M$68,13,FALSE),0)) -> 2 | F9: =D9*E9 -> 40 | G9: =F9*全局设置!$B$7 -> 40 | H9: =G9*全局设置!$B$5 -> 40 | I9: =IF(AND(B9="",C9=""),"",IF(AND(B9<>"",C9>=1,COUNTIF($B$7:$B$24,B9)=1),"可回读","需修正")) -> 可回读
A10: 4 | B10: 自爆原石虫 | C10: 16 | D10: =IF(B10="",0,ROUNDUP(C10*(1+(全局设置!$B$5-1)*全局设置!$B$6),0)) -> 16 | E10: =IF(B10="",0,IFERROR(VLOOKUP(B10,敌人目录!$A$6:$M$68,13,FALSE),0)) -> 1 | F10: =D10*E10 -> 16 | G10: =F10*全局设置!$B$7 -> 16 | H10: =G10*全局设置!$B$5 -> 16 | I10: =IF(AND(B10="",C10=""),"",IF(AND(B10<>"",C10>=1,COUNTIF($B$7:$B$24,B10)=1),"可回读","需修正")) -> 可回读
A11: 5 | B11: 紫晶自爆原石虫 | C11: 12 | D11: =IF(B11="",0,ROUNDUP(C11*(1+(全局设置!$B$5-1)*全局设置!$B$6),0)) -> 12 | E11: =IF(B11="",0,IFERROR(VLOOKUP(B11,敌人目录!$A$6:$M$68,13,FALSE),0)) -> 2 | F11: =D11*E11 -> 24 | G11: =F11*全局设置!$B$7 -> 24 | H11: =G11*全局设置!$B$5 -> 24 | I11: =IF(AND(B11="",C11=""),"",IF(AND(B11<>"",C11>=1,COUNTIF($B$7:$B$24,B11)=1),"可回读","需修正")) -> 可回读
A12: 6 | B12: 火焰弹原石虫 | C12: 20 | D12: =IF(B12="",0,ROUNDUP(C12*(1+(全局设置!$B$5-1)*全局设置!$B$6),0)) -> 20 | E12: =IF(B12="",0,IFERROR(VLOOKUP(B12,敌人目录!$A$6:$M$68,13,FALSE),0)) -> 1 | F12: =D12*E12 -> 20 | G12: =F12*全局设置!$B$7 -> 20 | H12: =G12*全局设置!$B$5 -> 20 | I12: =IF(AND(B12="",C12=""),"",IF(AND(B12<>"",C12>=1,COUNTIF($B$7:$B$24,B12)=1),"可回读","需修正")) -> 可回读
A13: 7 | B13: 翠壳原石虫 | C13: 16 | D13: =IF(B13="",0,ROUNDUP(C13*(1+(全局设置!$B$5-1)*全局设置!$B$6),0)) -> 16 | E13: =IF(B13="",0,IFERROR(VLOOKUP(B13,敌人目录!$A$6:$M$68,13,FALSE),0)) -> 2 | F13: =D13*E13 -> 32 | G13: =F13*全局设置!$B$7 -> 32 | H13: =G13*全局设置!$B$5 -> 32 | I13: =IF(AND(B13="",C13=""),"",IF(AND(B13<>"",C13>=1,COUNTIF($B$7:$B$24,B13)=1),"可回读","需修正")) -> 可回读
A14: 8 | B14: 守护者原石虫 | C14: 12 | D14: =IF(B14="",0,ROUNDUP(C14*(1+(全局设置!$B$5-1)*全局设置!$B$6),0)) -> 12 | E14: =IF(B14="",0,IFERROR(VLOOKUP(B14,敌人目录!$A$6:$M$68,13,FALSE),0)) -> 2 | F14: =D14*E14 -> 24 | G14: =F14*全局设置!$B$7 -> 24 | H14: =G14*全局设置!$B$5 -> 24 | I14: =IF(AND(B14="",C14=""),"",IF(AND(B14<>"",C14>=1,COUNTIF($B$7:$B$24,B14)=1),"可回读","需修正")) -> 可回读
A15: 9 | B15: 骑士猫猫虫 | C15: 2 | D15: =IF(B15="",0,ROUNDUP(C15*(1+(全局设置!$B$5-1)*全局设置!$B$6),0)) -> 2 | E15: =IF(B15="",0,IFERROR(VLOOKUP(B15,敌人目录!$A$6:$M$68,13,FALSE),0)) -> 20 | F15: =D15*E15 -> 40 | G15: =F15*全局设置!$B$7 -> 40 | H15: =G15*全局设置!$B$5 -> 40 | I15: =IF(AND(B15="",C15=""),"",IF(AND(B15<>"",C15>=1,COUNTIF($B$7:$B$24,B15)=1),"可回读","需修正")) -> 可回读
A16: 10 | D16: =IF(B16="",0,ROUNDUP(C16*(1+(全局设置!$B$5-1)*全局设置!$B$6),0)) -> 0 | E16: =IF(B16="",0,IFERROR(VLOOKUP(B16,敌人目录!$A$6:$M$68,13,FALSE),0)) -> 0 | F16: =D16*E16 -> 0 | G16: =F16*全局设置!$B$7 -> 0 | H16: =G16*全局设置!$B$5 -> 0 | I16: =IF(AND(B16="",C16=""),"",IF(AND(B16<>"",C16>=1,COUNTIF($B$7:$B$24,B16)=1),"可回读","需修正"))
A17: 11 | D17: =IF(B17="",0,ROUNDUP(C17*(1+(全局设置!$B$5-1)*全局设置!$B$6),0)) -> 0 | E17: =IF(B17="",0,IFERROR(VLOOKUP(B17,敌人目录!$A$6:$M$68,13,FALSE),0)) -> 0 | F17: =D17*E17 -> 0 | G17: =F17*全局设置!$B$7 -> 0 | H17: =G17*全局设置!$B$5 -> 0 | I17: =IF(AND(B17="",C17=""),"",IF(AND(B17<>"",C17>=1,COUNTIF($B$7:$B$24,B17)=1),"可回读","需修正"))
A18: 12 | D18: =IF(B18="",0,ROUNDUP(C18*(1+(全局设置!$B$5-1)*全局设置!$B$6),0)) -> 0 | E18: =IF(B18="",0,IFERROR(VLOOKUP(B18,敌人目录!$A$6:$M$68,13,FALSE),0)) -> 0 | F18: =D18*E18 -> 0 | G18: =F18*全局设置!$B$7 -> 0 | H18: =G18*全局设置!$B$5 -> 0 | I18: =IF(AND(B18="",C18=""),"",IF(AND(B18<>"",C18>=1,COUNTIF($B$7:$B$24,B18)=1),"可回读","需修正"))
A19: 13 | D19: =IF(B19="",0,ROUNDUP(C19*(1+(全局设置!$B$5-1)*全局设置!$B$6),0)) -> 0 | E19: =IF(B19="",0,IFERROR(VLOOKUP(B19,敌人目录!$A$6:$M$68,13,FALSE),0)) -> 0 | F19: =D19*E19 -> 0 | G19: =F19*全局设置!$B$7 -> 0 | H19: =G19*全局设置!$B$5 -> 0 | I19: =IF(AND(B19="",C19=""),"",IF(AND(B19<>"",C19>=1,COUNTIF($B$7:$B$24,B19)=1),"可回读","需修正"))
A20: 14 | D20: =IF(B20="",0,ROUNDUP(C20*(1+(全局设置!$B$5-1)*全局设置!$B$6),0)) -> 0 | E20: =IF(B20="",0,IFERROR(VLOOKUP(B20,敌人目录!$A$6:$M$68,13,FALSE),0)) -> 0 | F20: =D20*E20 -> 0 | G20: =F20*全局设置!$B$7 -> 0 | H20: =G20*全局设置!$B$5 -> 0 | I20: =IF(AND(B20="",C20=""),"",IF(AND(B20<>"",C20>=1,COUNTIF($B$7:$B$24,B20)=1),"可回读","需修正"))
A21: 15 | D21: =IF(B21="",0,ROUNDUP(C21*(1+(全局设置!$B$5-1)*全局设置!$B$6),0)) -> 0 | E21: =IF(B21="",0,IFERROR(VLOOKUP(B21,敌人目录!$A$6:$M$68,13,FALSE),0)) -> 0 | F21: =D21*E21 -> 0 | G21: =F21*全局设置!$B$7 -> 0 | H21: =G21*全局设置!$B$5 -> 0 | I21: =IF(AND(B21="",C21=""),"",IF(AND(B21<>"",C21>=1,COUNTIF($B$7:$B$24,B21)=1),"可回读","需修正"))
A22: 16 | D22: =IF(B22="",0,ROUNDUP(C22*(1+(全局设置!$B$5-1)*全局设置!$B$6),0)) -> 0 | E22: =IF(B22="",0,IFERROR(VLOOKUP(B22,敌人目录!$A$6:$M$68,13,FALSE),0)) -> 0 | F22: =D22*E22 -> 0 | G22: =F22*全局设置!$B$7 -> 0 | H22: =G22*全局设置!$B$5 -> 0 | I22: =IF(AND(B22="",C22=""),"",IF(AND(B22<>"",C22>=1,COUNTIF($B$7:$B$24,B22)=1),"可回读","需修正"))
A23: 17 | D23: =IF(B23="",0,ROUNDUP(C23*(1+(全局设置!$B$5-1)*全局设置!$B$6),0)) -> 0 | E23: =IF(B23="",0,IFERROR(VLOOKUP(B23,敌人目录!$A$6:$M$68,13,FALSE),0)) -> 0 | F23: =D23*E23 -> 0 | G23: =F23*全局设置!$B$7 -> 0 | H23: =G23*全局设置!$B$5 -> 0 | I23: =IF(AND(B23="",C23=""),"",IF(AND(B23<>"",C23>=1,COUNTIF($B$7:$B$24,B23)=1),"可回读","需修正"))
A24: 18 | D24: =IF(B24="",0,ROUNDUP(C24*(1+(全局设置!$B$5-1)*全局设置!$B$6),0)) -> 0 | E24: =IF(B24="",0,IFERROR(VLOOKUP(B24,敌人目录!$A$6:$M$68,13,FALSE),0)) -> 0 | F24: =D24*E24 -> 0 | G24: =F24*全局设置!$B$7 -> 0 | H24: =G24*全局设置!$B$5 -> 0 | I24: =IF(AND(B24="",C24=""),"",IF(AND(B24<>"",C24>=1,COUNTIF($B$7:$B$24,B24)=1),"可回读","需修正"))
A26: 基础总数 | B26: =SUM(C7:C24) -> 144 | C26: 实际总数 | D26: =SUM(D7:D24) -> 144 | E26: 最大息壤/玩家 | F26: =SUM(F7:F24) -> 242 | G26: 预计息壤/玩家 | H26: =SUM(G7:G24) -> 242
A27: 预计息壤/队伍 | B27: =SUM(H7:H24) -> 242 | C27: 说明 | D27: 预计息壤 = 实际数量 × 固定息壤 × 击杀率；已移除每日命运倍率。
A31: 第 10 波｜第 3 日·2/4｜白昼｜当前正式配置
A32: 波次名称 | B32: 第10波 | C32: 第10波 火力交叉 | D32: 出生间隔(s) | E32: 0.26 | F32: 每Tick | G32: 1 | H32: 存活上限 | I32: 300
A33: 出生点 | B33: 点1·开启 | C33: 点2·开启 | D33: 点3·开启 | E33: 点4·开启 | F33: 点5·开启 | G33: 点6·开启 | H33: 波次校验 | I33: =IF(COUNTA(B36:B53)=0,"待设计",IF(COUNTIF(I36:I53,"需修正")>0,"需修正","可回读")) -> 可回读
A34: 仅编辑蓝色列、敌人数值和出生点；所有公式、稳定 ID 与 schema 字段由机器区自动生成。
A35: 槽位 | B35: 敌人（下拉选择） | C35: 基础数量 | D35: 实际数量 | E35: 息壤/击杀 | F35: 最大息壤/玩家 | G35: 预计息壤/玩家 | H35: 预计息壤/队伍 | I35: 校验
A36: 1 | B36: 普通原石虫 | C36: 20 | D36: =IF(B36="",0,ROUNDUP(C36*(1+(全局设置!$B$5-1)*全局设置!$B$6),0)) -> 20 | E36: =IF(B36="",0,IFERROR(VLOOKUP(B36,敌人目录!$A$6:$M$68,13,FALSE),0)) -> 1 | F36: =D36*E36 -> 20 | G36: =F36*全局设置!$B$7 -> 20 | H36: =G36*全局设置!$B$5 -> 20 | I36: =IF(AND(B36="",C36=""),"",IF(AND(B36<>"",C36>=1,COUNTIF($B$36:$B$53,B36)=1),"可回读","需修正")) -> 可回读
A37: 2 | B37: 迅捷原石虫 | C37: 24 | D37: =IF(B37="",0,ROUNDUP(C37*(1+(全局设置!$B$5-1)*全局设置!$B$6),0)) -> 24 | E37: =IF(B37="",0,IFERROR(VLOOKUP(B37,敌人目录!$A$6:$M$68,13,FALSE),0)) -> 1 | F37: =D37*E37 -> 24 | G37: =F37*全局设置!$B$7 -> 24 | H37: =G37*全局设置!$B$5 -> 24 | I37: =IF(AND(B37="",C37=""),"",IF(AND(B37<>"",C37>=1,COUNTIF($B$36:$B$53,B37)=1),"可回读","需修正")) -> 可回读
A38: 3 | B38: 硬壳原石虫 | C38: 24 | D38: =IF(B38="",0,ROUNDUP(C38*(1+(全局设置!$B$5-1)*全局设置!$B$6),0)) -> 24 | E38: =IF(B38="",0,IFERROR(VLOOKUP(B38,敌人目录!$A$6:$M$68,13,FALSE),0)) -> 2 | F38: =D38*E38 -> 48 | G38: =F38*全局设置!$B$7 -> 48 | H38: =G38*全局设置!$B$5 -> 48 | I38: =IF(AND(B38="",C38=""),"",IF(AND(B38<>"",C38>=1,COUNTIF($B$36:$B$53,B38)=1),"可回读","需修正")) -> 可回读
A39: 4 | B39: 自爆原石虫 | C39: 20 | D39: =IF(B39="",0,ROUNDUP(C39*(1+(全局设置!$B$5-1)*全局设置!$B$6),0)) -> 20 | E39: =IF(B39="",0,IFERROR(VLOOKUP(B39,敌人目录!$A$6:$M$68,13,FALSE),0)) -> 1 | F39: =D39*E39 -> 20 | G39: =F39*全局设置!$B$7 -> 20 | H39: =G39*全局设置!$B$5 -> 20 | I39: =IF(AND(B39="",C39=""),"",IF(AND(B39<>"",C39>=1,COUNTIF($B$36:$B$53,B39)=1),"可回读","需修正")) -> 可回读
A40: 5 | B40: 紫晶自爆原石虫 | C40: 16 | D40: =IF(B40="",0,ROUNDUP(C40*(1+(全局设置!$B$5-1)*全局设置!$B$6),0)) -> 16 | E40: =IF(B40="",0,IFERROR(VLOOKUP(B40,敌人目录!$A$6:$M$68,13,FALSE),0)) -> 2 | F40: =D40*E40 -> 32 | G40: =F40*全局设置!$B$7 -> 32 | H40: =G40*全局设置!$B$5 -> 32 | I40: =IF(AND(B40="",C40=""),"",IF(AND(B40<>"",C40>=1,COUNTIF($B$36:$B$53,B40)=1),"可回读","需修正")) -> 可回读
A41: 6 | B41: 火焰弹原石虫 | C41: 20 | D41: =IF(B41="",0,ROUNDUP(C41*(1+(全局设置!$B$5-1)*全局设置!$B$6),0)) -> 20 | E41: =IF(B41="",0,IFERROR(VLOOKUP(B41,敌人目录!$A$6:$M$68,13,FALSE),0)) -> 1 | F41: =D41*E41 -> 20 | G41: =F41*全局设置!$B$7 -> 20 | H41: =G41*全局设置!$B$5 -> 20 | I41: =IF(AND(B41="",C41=""),"",IF(AND(B41<>"",C41>=1,COUNTIF($B$36:$B$53,B41)=1),"可回读","需修正")) -> 可回读
A42: 7 | B42: 翠壳原石虫 | C42: 16 | D42: =IF(B42="",0,ROUNDUP(C42*(1+(全局设置!$B$5-1)*全局设置!$B$6),0)) -> 16 | E42: =IF(B42="",0,IFERROR(VLOOKUP(B42,敌人目录!$A$6:$M$68,13,FALSE),0)) -> 2 | F42: =D42*E42 -> 32 | G42: =F42*全局设置!$B$7 -> 32 | H42: =G42*全局设置!$B$5 -> 32 | I42: =IF(AND(B42="",C42=""),"",IF(AND(B42<>"",C42>=1,COUNTIF($B$36:$B$53,B42)=1),"可回读","需修正")) -> 可回读
A43: 8 | B43: 守护者原石虫 | C43: 16 | D43: =IF(B43="",0,ROUNDUP(C43*(1+(全局设置!$B$5-1)*全局设置!$B$6),0)) -> 16 | E43: =IF(B43="",0,IFERROR(VLOOKUP(B43,敌人目录!$A$6:$M$68,13,FALSE),0)) -> 2 | F43: =D43*E43 -> 32 | G43: =F43*全局设置!$B$7 -> 32 | H43: =G43*全局设置!$B$5 -> 32 | I43: =IF(AND(B43="",C43=""),"",IF(AND(B43<>"",C43>=1,COUNTIF($B$36:$B$53,B43)=1),"可回读","需修正")) -> 可回读
A44: 9 | B44: AK猫猫虫 | C44: 2 | D44: =IF(B44="",0,ROUNDUP(C44*(1+(全局设置!$B$5-1)*全局设置!$B$6),0)) -> 2 | E44: =IF(B44="",0,IFERROR(VLOOKUP(B44,敌人目录!$A$6:$M$68,13,FALSE),0)) -> 20 | F44: =D44*E44 -> 40 | G44: =F44*全局设置!$B$7 -> 40 | H44: =G44*全局设置!$B$5 -> 40 | I44: =IF(AND(B44="",C44=""),"",IF(AND(B44<>"",C44>=1,COUNTIF($B$36:$B$53,B44)=1),"可回读","需修正")) -> 可回读
...

Sheet 第4日
A1: 第 4 日｜白昼｜铃兰 Boss
A2: 只读 Boss 面板：第 4 日没有第 13～16 波；60 秒白昼准备后进入铃兰战，击败后直接通关。
A4: 流程身份
A5: 日期 | B5: 第4日 | C5: 时段 | D5: 白昼 | E5: 前置 | F5: 第12波 + 第3日地下探索 | G5: 准备 | H5: 60 秒（正式默认）
A6: 流程节点 | B6: boss_01_linglan | E6: Boss ID | F6: linglan_boss
A7: 显示名称 | B7: 铃兰 | E7: 普通波次编号 | F7: 不显示
A8: Boss 配置 | B8: res://resources/config/bosses/boss_01_linglan.tres
A9: 敌人配置 | B9: res://resources/config/enemies/linglan_boss.tres
A10: Boss 音乐 | B10: res://resources/audio/BGM_The_Truth_Never_Spoken.mp3
A12: 通关条件
A13: 铃兰死亡 → 沿用现有胜利流程 → 显示通关 不会再次进入地下探索，也不会进入小葱命运时间。
A17: 此页无可编辑波次区域；Boss 数值继续由现有 Boss / Enemy 资源维护。

Sheet 敌人目录
A1: 敌人目录｜63 个普通波次敌人的全局固定配置 | B1: 敌人目录｜49 个普通波次敌人的全局固定配置 | C1: 敌人目录｜49 个普通波次敌人的全局固定配置 | D1: 敌人目录｜49 个普通波次敌人的全局固定配置 | E1: 敌人目录｜49 个普通波次敌人的全局固定配置 | F1: 敌人目录｜49 个普通波次敌人的全局固定配置 | G1: 敌人目录｜49 个普通波次敌人的全局固定配置 | H1: 敌人目录｜49 个普通波次敌人的全局固定配置 | I1: 敌人目录｜49 个普通波次敌人的全局固定配置 | J1: 敌人目录｜49 个普通波次敌人的全局固定配置 | K1: 敌人目录｜49 个普通波次敌人的全局固定配置 | L1: 敌人目录｜49 个普通波次敌人的全局固定配置 | M1: 敌人目录｜49 个普通波次敌人的全局固定配置 | N1: 敌人目录｜49 个普通波次敌人的全局固定配置 | O1: 敌人目录｜49 个普通波次敌人的全局固定配置 | P1: 敌人目录｜49 个普通波次敌人的全局固定配置 | Q1: 敌人目录｜49 个普通波次敌人的全局固定配置 | R1: 敌人目录｜49 个普通波次敌人的全局固定配置 | S1: 敌人目录｜49 个普通波次敌人的全局固定配置 | T1: 敌人目录｜49 个普通波次敌人的全局固定配置 | U1: 敌人目录｜49 个普通波次敌人的全局固定配置 | V1: 敌人目录｜49 个普通波次敌人的全局固定配置 | W1: 敌人目录｜49 个普通波次敌人的全局固定配置 | X1: 敌人目录｜49 个普通波次敌人的全局固定配置 | Y1: 敌人目录｜49 个普通波次敌人的全局固定配置 | Z1: 敌人目录｜49 个普通波次敌人的全局固定配置 | AA1: 敌人目录｜49 个普通波次敌人的全局固定配置 | AB1: 敌人目录｜49 个普通波次敌人的全局固定配置 | AC1: 敌人目录｜49 个普通波次敌人的全局固定配置 | AD1: 敌人目录｜49 个普通波次敌人的全局固定配置
A2: 蓝色、金色、绿色与紫色区域可编辑；所有 12 波共同引用本目录，Boss 不在普通波次下拉列表中。 | B2: 蓝色、金色、绿色与紫色区域均可编辑。每种敌人的数值、息壤和掉落只在此处定义一次，并由所有波次共同引用；波次页不再提供覆盖值。 | C2: 蓝色、金色、绿色与紫色区域均可编辑。每种敌人的数值、息壤和掉落只在此处定义一次，并由所有波次共同引用；波次页不再提供覆盖值。 | D2: 蓝色、金色、绿色与紫色区域均可编辑。每种敌人的数值、息壤和掉落只在此处定义一次，并由所有波次共同引用；波次页不再提供覆盖值。 | E2: 蓝色、金色、绿色与紫色区域均可编辑。每种敌人的数值、息壤和掉落只在此处定义一次，并由所有波次共同引用；波次页不再提供覆盖值。 | F2: 蓝色、金色、绿色与紫色区域均可编辑。每种敌人的数值、息壤和掉落只在此处定义一次，并由所有波次共同引用；波次页不再提供覆盖值。 | G2: 蓝色、金色、绿色与紫色区域均可编辑。每种敌人的数值、息壤和掉落只在此处定义一次，并由所有波次共同引用；波次页不再提供覆盖值。 | H2: 蓝色、金色、绿色与紫色区域均可编辑。每种敌人的数值、息壤和掉落只在此处定义一次，并由所有波次共同引用；波次页不再提供覆盖值。 | I2: 蓝色、金色、绿色与紫色区域均可编辑。每种敌人的数值、息壤和掉落只在此处定义一次，并由所有波次共同引用；波次页不再提供覆盖值。 | J2: 蓝色、金色、绿色与紫色区域均可编辑。每种敌人的数值、息壤和掉落只在此处定义一次，并由所有波次共同引用；波次页不再提供覆盖值。 | K2: 蓝色、金色、绿色与紫色区域均可编辑。每种敌人的数值、息壤和掉落只在此处定义一次，并由所有波次共同引用；波次页不再提供覆盖值。 | L2: 蓝色、金色、绿色与紫色区域均可编辑。每种敌人的数值、息壤和掉落只在此处定义一次，并由所有波次共同引用；波次页不再提供覆盖值。 | M2: 蓝色、金色、绿色与紫色区域均可编辑。每种敌人的数值、息壤和掉落只在此处定义一次，并由所有波次共同引用；波次页不再提供覆盖值。 | N2: 蓝色、金色、绿色与紫色区域均可编辑。每种敌人的数值、息壤和掉落只在此处定义一次，并由所有波次共同引用；波次页不再提供覆盖值。 | O2: 蓝色、金色、绿色与紫色区域均可编辑。每种敌人的数值、息壤和掉落只在此处定义一次，并由所有波次共同引用；波次页不再提供覆盖值。 | P2: 蓝色、金色、绿色与紫色区域均可编辑。每种敌人的数值、息壤和掉落只在此处定义一次，并由所有波次共同引用；波次页不再提供覆盖值。 | Q2: 蓝色、金色、绿色与紫色区域均可编辑。每种敌人的数值、息壤和掉落只在此处定义一次，并由所有波次共同引用；波次页不再提供覆盖值。 | R2: 蓝色、金色、绿色与紫色区域均可编辑。每种敌人的数值、息壤和掉落只在此处定义一次，并由所有波次共同引用；波次页不再提供覆盖值。 | S2: 蓝色、金色、绿色与紫色区域均可编辑。每种敌人的数值、息壤和掉落只在此处定义一次，并由所有波次共同引用；波次页不再提供覆盖值。 | T2: 蓝色、金色、绿色与紫色区域均可编辑。每种敌人的数值、息壤和掉落只在此处定义一次，并由所有波次共同引用；波次页不再提供覆盖值。 | U2: 蓝色、金色、绿色与紫色区域均可编辑。每种敌人的数值、息壤和掉落只在此处定义一次，并由所有波次共同引用；波次页不再提供覆盖值。 | V2: 蓝色、金色、绿色与紫色区域均可编辑。每种敌人的数值、息壤和掉落只在此处定义一次，并由所有波次共同引用；波次页不再提供覆盖值。 | W2: 蓝色、金色、绿色与紫色区域均可编辑。每种敌人的数值、息壤和掉落只在此处定义一次，并由所有波次共同引用；波次页不再提供覆盖值。 | X2: 蓝色、金色、绿色与紫色区域均可编辑。每种敌人的数值、息壤和掉落只在此处定义一次，并由所有波次共同引用；波次页不再提供覆盖值。 | Y2: 蓝色、金色、绿色与紫色区域均可编辑。每种敌人的数值、息壤和掉落只在此处定义一次，并由所有波次共同引用；波次页不再提供覆盖值。 | Z2: 蓝色、金色、绿色与紫色区域均可编辑。每种敌人的数值、息壤和掉落只在此处定义一次，并由所有波次共同引用；波次页不再提供覆盖值。 | AA2: 蓝色、金色、绿色与紫色区域均可编辑。每种敌人的数值、息壤和掉落只在此处定义一次，并由所有波次共同引用；波次页不再提供覆盖值。 | AB2: 蓝色、金色、绿色与紫色区域均可编辑。每种敌人的数值、息壤和掉落只在此处定义一次，并由所有波次共同引用；波次页不再提供覆盖值。 | AC2: 蓝色、金色、绿色与紫色区域均可编辑。每种敌人的数值、息壤和掉落只在此处定义一次，并由所有波次共同引用；波次页不再提供覆盖值。 | AD2: 蓝色、金色、绿色与紫色区域均可编辑。每种敌人的数值、息壤和掉落只在此处定义一次，并由所有波次共同引用；波次页不再提供覆盖值。
A4: 身份与引用｜只读 | B4: 身份与引用｜只读 | C4: 身份与引用｜只读 | D4: 身份与引用｜只读 | E4: 身份与引用｜只读 | F4: 身份与引用｜只读 | G4: 战斗数值｜可编辑 | H4: 战斗数值｜可编辑 | I4: 战斗数值｜可编辑 | J4: 战斗数值｜可编辑 | K4: 战斗数值｜可编辑 | L4: 战斗数值｜可编辑 | M4: 击杀奖励｜可编辑 | N4: 自动计算 | O4: 材料掉落概率｜每次击杀独立判定 | P4: 材料掉落概率｜每次击杀独立判定 | Q4: 材料掉落概率｜每次击杀独立判定 | R4: 材料掉落概率｜每次击杀独立判定 | S4: 材料掉落概率｜每次击杀独立判定 | T4: 材料掉落概率｜每次击杀独立判定 | U4: 材料掉落概率｜每次击杀独立判定 | V4: 功能道具掉落概率｜每次击杀独立判定 | W4: 功能道具掉落概率｜每次击杀独立判定 | X4: 功能道具掉落概率｜每次击杀独立判定 | Y4: 功能道具掉落概率｜每次击杀独立判定 | Z4: 功能道具掉落概率｜每次击杀独立判定 | AA4: 校验与来源｜只读 | AB4: 校验与来源｜只读 | AC4: 校验与来源｜只读 | AD4: 校验与来源｜只读
A5: 下拉名称 | B5: 稳定ID | C5: 名称 | D5: 家族 | E5: 等级 | F5: 正式波次已使用 | G5: 生命 | H5: 攻击 | I5: 物理防御 | J5: 法术防御 | K5: 移速 | L5: Home伤害 | M5: 息壤/击杀 | N5: 掉落期望/击杀 | O5: 木头 | P5: 白色水晶 | Q5: 树苗 | R5: 卡普蓝晶 | S5: 术士紫晶粉 | T5: 凝胶 | U5: 小石块 | V5: 移速道具 | W5: 射速道具 | X5: 天妇罗道具 | Y5: 生命药瓶 | Z5: 雪狼破军 | AA5: 行校验 | AB5: 类别标签 | AC5: 配置路径 | AD5: 场景路径
A6: 普通原石虫 | B6: yuanshi_insect_basic | C6: 普通原石虫 | D6: 原石虫 | E6: 普通 | F6: 是 | G6: 40 | H6: 10 | I6: 0 | J6: 0 | K6: 20 | L6: 1 | M6: 1 | N6: =SUM(O6:Z6) -> 0.046 | O6: 0.02 | P6: 0.002 | Q6: 0.01 | R6: 0 | S6: 0 | T6: 0 | U6: 0 | V6: 0.004 | W6: 0.004 | X6: 0.004 | Y6: 0 | Z6: 0.002 | AA6: =IF(AND(A6<>"",B6<>"",G6>0,M6>=0,M6<=999),"可回读","需修正") -> 可回读 | AB6: yuanshi_insect | AC6: res://resources/config/enemies/yuanshi_insect_basic.tres | AD6: res://scene/enemy/yuanshi_insect/yuanshi_insect_basic.tscn
A7: 硬壳原石虫 | B7: yuanshi_insect_shell | C7: 硬壳原石虫 | D7: 原石虫 | E7: 普通 | F7: 是 | G7: 140 | H7: 14 | I7: 3 | J7: 0 | K7: 20 | L7: 2 | M7: 2 | N7: =SUM(O7:Z7) -> 0.046 | O7: 0.02 | P7: 0.002 | Q7: 0.01 | R7: 0 | S7: 0 | T7: 0 | U7: 0 | V7: 0.004 | W7: 0.004 | X7: 0.004 | Y7: 0 | Z7: 0.002 | AA7: =IF(AND(A7<>"",B7<>"",G7>0,M7>=0,M7<=999),"可回读","需修正") -> 可回读 | AB7: yuanshi_insect | AC7: res://resources/config/enemies/yuanshi_insect_shell.tres | AD7: res://scene/enemy/yuanshi_insect/yuanshi_insect_shell.tscn
A8: 迅捷原石虫 | B8: yuanshi_insect_fast | C8: 迅捷原石虫 | D8: 原石虫 | E8: 普通 | F8: 是 | G8: 35 | H8: 10 | I8: 0 | J8: 0 | K8: 40 | L8: 1 | M8: 1 | N8: =SUM(O8:Z8) -> 0.046 | O8: 0.02 | P8: 0.002 | Q8: 0.01 | R8: 0 | S8: 0 | T8: 0 | U8: 0 | V8: 0.004 | W8: 0.004 | X8: 0.004 | Y8: 0 | Z8: 0.002 | AA8: =IF(AND(A8<>"",B8<>"",G8>0,M8>=0,M8<=999),"可回读","需修正") -> 可回读 | AB8: yuanshi_insect | AC8: res://resources/config/enemies/yuanshi_insect_fast.tres | AD8: res://scene/enemy/yuanshi_insect/yuanshi_insect_fast.tscn
A9: 自爆原石虫 | B9: yuanshi_insect_bomber | C9: 自爆原石虫 | D9: 原石虫 | E9: 普通 | F9: 是 | G9: 30 | H9: 10 | I9: 0 | J9: 0 | K9: 18 | L9: 1 | M9: 1 | N9: =SUM(O9:Z9) -> 0.046 | O9: 0.02 | P9: 0.002 | Q9: 0.01 | R9: 0 | S9: 0 | T9: 0 | U9: 0 | V9: 0.004 | W9: 0.004 | X9: 0.004 | Y9: 0 | Z9: 0.002 | AA9: =IF(AND(A9<>"",B9<>"",G9>0,M9>=0,M9<=999),"可回读","需修正") -> 可回读 | AB9: yuanshi_insect | AC9: res://resources/config/enemies/yuanshi_insect_bomber.tres | AD9: res://scene/enemy/yuanshi_insect/yuanshi_insect_bomber.tscn
A10: 紫晶自爆原石虫 | B10: yuanshi_insect_purple_bomber | C10: 紫晶自爆原石虫 | D10: 原石虫 | E10: 普通 | F10: 是 | G10: 40 | H10: 10 | I10: 0 | J10: 0 | K10: 32 | L10: 1 | M10: 2 | N10: =SUM(O10:Z10) -> 0.046 | O10: 0.02 | P10: 0.002 | Q10: 0.01 | R10: 0 | S10: 0 | T10: 0 | U10: 0 | V10: 0.004 | W10: 0.004 | X10: 0.004 | Y10: 0 | Z10: 0.002 | AA10: =IF(AND(A10<>"",B10<>"",G10>0,M10>=0,M10<=999),"可回读","需修正") -> 可回读 | AB10: yuanshi_insect | AC10: res://resources/config/enemies/yuanshi_insect_purple_bomber.tres | AD10: res://scene/enemy/yuanshi_insect/yuanshi_insect_purple_bomber.tscn
A11: 翠壳原石虫 | B11: yuanshi_insect_green_shell | C11: 翠壳原石虫 | D11: 原石虫 | E11: 普通 | F11: 是 | G11: 200 | H11: 20 | I11: 5 | J11: 0 | K11: 15 | L11: 5 | M11: 2 | N11: =SUM(O11:Z11) -> 0.046 | O11: 0.02 | P11: 0.002 | Q11: 0.01 | R11: 0 | S11: 0 | T11: 0 | U11: 0 | V11: 0.004 | W11: 0.004 | X11: 0.004 | Y11: 0 | Z11: 0.002 | AA11: =IF(AND(A11<>"",B11<>"",G11>0,M11>=0,M11<=999),"可回读","需修正") -> 可回读 | AB11: yuanshi_insect | AC11: res://resources/config/enemies/yuanshi_insect_green_shell.tres | AD11: res://scene/enemy/yuanshi_insect/yuanshi_insect_green_shell.tscn
A12: 火焰弹原石虫 | B12: yuanshi_insect_fire_ranged | C12: 火焰弹原石虫 | D12: 原石虫 | E12: 普通 | F12: 是 | G12: 40 | H12: 25 | I12: 0 | J12: 0 | K12: 22 | L12: 2 | M12: 1 | N12: =SUM(O12:Z12) -> 0.046 | O12: 0.02 | P12: 0.002 | Q12: 0.01 | R12: 0 | S12: 0 | T12: 0 | U12: 0 | V12: 0.004 | W12: 0.004 | X12: 0.004 | Y12: 0 | Z12: 0.002 | AA12: =IF(AND(A12<>"",B12<>"",G12>0,M12>=0,M12<=999),"可回读","需修正") -> 可回读 | AB12: yuanshi_insect | AC12: res://resources/config/enemies/yuanshi_insect_fire_ranged.tres | AD12: res://scene/enemy/yuanshi_insect/yuanshi_insect_fire_ranged.tscn
A13: 守护者原石虫 | B13: yuanshi_insect_guardian | C13: 守护者原石虫 | D13: 原石虫 | E13: 普通 | F13: 是 | G13: 150 | H13: 10 | I13: 5 | J13: 0 | K13: 20 | L13: 5 | M13: 2 | N13: =SUM(O13:Z13) -> 0.046 | O13: 0.02 | P13: 0.002 | Q13: 0.01 | R13: 0 | S13: 0 | T13: 0 | U13: 0 | V13: 0.004 | W13: 0.004 | X13: 0.004 | Y13: 0 | Z13: 0.002 | AA13: =IF(AND(A13<>"",B13<>"",G13>0,M13>=0,M13<=999),"可回读","需修正") -> 可回读 | AB13: yuanshi_insect | AC13: res://resources/config/enemies/yuanshi_insect_guardian.tres | AD13: res://scene/enemy/yuanshi_insect/yuanshi_insect_guardian.tscn
A14: 被石头侵蚀的普通原石虫 | B14: stone_eroded_yuanshi_insect_basic | C14: 被石头侵蚀的普通原石虫 | D14: 原石虫 | E14: 普通 | F14: 否 | G14: 80 | H14: 10 | I14: 150 | J14: 0 | K14: 20 | L14: 1 | M14: 1 | N14: =SUM(O14:Z14) -> 0.046 | O14: 0.02 | P14: 0.002 | Q14: 0.01 | R14: 0 | S14: 0 | T14: 0 | U14: 0 | V14: 0.004 | W14: 0.004 | X14: 0.004 | Y14: 0 | Z14: 0.002 | AA14: =IF(AND(A14<>"",B14<>"",G14>0,M14>=0,M14<=999),"可回读","需修正") -> 可回读 | AB14: yuanshi_insect, stone_eroded | AC14: res://resources/config/enemies/stone_eroded_yuanshi_insect_basic.tres | AD14: res://scene/enemy/stone_eroded/stone_eroded_yuanshi_insect_basic.tscn
A15: 被石头侵蚀的硬壳原石虫 | B15: stone_eroded_yuanshi_insect_shell | C15: 被石头侵蚀的硬壳原石虫 | D15: 原石虫 | E15: 普通 | F15: 否 | G15: 280 | H15: 14 | I15: 150 | J15: 0 | K15: 20 | L15: 2 | M15: 2 | N15: =SUM(O15:Z15) -> 0.046 | O15: 0.02 | P15: 0.002 | Q15: 0.01 | R15: 0 | S15: 0 | T15: 0 | U15: 0 | V15: 0.004 | W15: 0.004 | X15: 0.004 | Y15: 0 | Z15: 0.002 | AA15: =IF(AND(A15<>"",B15<>"",G15>0,M15>=0,M15<=999),"可回读","需修正") -> 可回读 | AB15: yuanshi_insect, stone_eroded | AC15: res://resources/config/enemies/stone_eroded_yuanshi_insect_shell.tres | AD15: res://scene/enemy/stone_eroded/stone_eroded_yuanshi_insect_shell.tscn
A16: 被石头侵蚀的迅捷原石虫 | B16: stone_eroded_yuanshi_insect_fast | C16: 被石头侵蚀的迅捷原石虫 | D16: 原石虫 | E16: 普通 | F16: 否 | G16: 70 | H16: 10 | I16: 150 | J16: 0 | K16: 40 | L16: 1 | M16: 1 | N16: =SUM(O16:Z16) -> 0.046 | O16: 0.02 | P16: 0.002 | Q16: 0.01 | R16: 0 | S16: 0 | T16: 0 | U16: 0 | V16: 0.004 | W16: 0.004 | X16: 0.004 | Y16: 0 | Z16: 0.002 | AA16: =IF(AND(A16<>"",B16<>"",G16>0,M16>=0,M16<=999),"可回读","需修正") -> 可回读 | AB16: yuanshi_insect, stone_eroded | AC16: res://resources/config/enemies/stone_eroded_yuanshi_insect_fast.tres | AD16: res://scene/enemy/stone_eroded/stone_eroded_yuanshi_insect_fast.tscn
A17: 被石头侵蚀的自爆原石虫 | B17: stone_eroded_yuanshi_insect_bomber | C17: 被石头侵蚀的自爆原石虫 | D17: 原石虫 | E17: 普通 | F17: 否 | G17: 60 | H17: 10 | I17: 150 | J17: 0 | K17: 18 | L17: 1 | M17: 1 | N17: =SUM(O17:Z17) -> 0.046 | O17: 0.02 | P17: 0.002 | Q17: 0.01 | R17: 0 | S17: 0 | T17: 0 | U17: 0 | V17: 0.004 | W17: 0.004 | X17: 0.004 | Y17: 0 | Z17: 0.002 | AA17: =IF(AND(A17<>"",B17<>"",G17>0,M17>=0,M17<=999),"可回读","需修正") -> 可回读 | AB17: yuanshi_insect, stone_eroded | AC17: res://resources/config/enemies/stone_eroded_yuanshi_insect_bomber.tres | AD17: res://scene/enemy/stone_eroded/stone_eroded_yuanshi_insect_bomber.tscn
... A68: 主战机器人 | B68: combat_robot_main_battle_elite | C68: 主战机器人 | D68: 机械生命 | E68: 精英 | F68: 否 | G68: 800 | H68: 80 | I68: 40 | J68: 35 | K68: 28 | L68: 2 | M68: 10 | N68: =SUM(O68:Z68) -> 0.046 | O68: 0.02 | P68: 0.002 | Q68: 0.01 | R68: 0 | S68: 0 | T68: 0 | U68: 0 | V68: 0.004 | W68: 0.004 | X68: 0.004 | Y68: 0 | Z68: 0.002 | AA68: =IF(AND(A68<>"",B68<>"",G68>0,M68>=0,M68<=999),"可回读","需修正") -> 可回读 | AB68: mechanical_life | AC68: res://resources/config/enemies/combat_robot_main_battle_elite.tres | AD68: res://scene/enemy/mechanical_life/combat_robot_main_battle_elite.tscn

Sheet 敌人导入数据（勿改）
A1: 敌人导入数据｜schema v3｜机器读取区域，请勿编辑
A2: schema_version | B2: 3 | C2: workbook_id | D2: tower_defense_4_day_campaign_designer_v3 | E2: enemy_count | F2: 63 | G2: source | H2: 敌人目录
A4: schema_version | B4: enemy_id | C4: max_health | D4: attack_damage | E4: physical_defense | F4: magic_defense | G4: move_speed | H4: home_damage | I4: xirang_kill_reward | J4: material_wood | K4: material_white_crystal | L4: material_sapling | M4: material_capoo_blue_crystal | N4: material_sorcerer_violet_powder | O4: material_gel | P4: material_small_stone | Q4: pickup_speed | R4: pickup_rapid | S4: pickup_tenpura | T4: pickup_health | U4: pickup_spiral | V4: expected_drop_count_per_kill | W4: row_validation | X4: config_path
A5: 3 | B5: =敌人目录!B6 -> yuanshi_insect_basic | C5: =敌人目录!G6 -> 40 | D5: =敌人目录!H6 -> 10 | E5: =敌人目录!I6 -> 0 | F5: =敌人目录!J6 -> 0 | G5: =敌人目录!K6 -> 20 | H5: =敌人目录!L6 -> 1 | I5: =敌人目录!M6 -> 1 | J5: =敌人目录!O6 -> 0.02 | K5: =敌人目录!P6 -> 0.002 | L5: =敌人目录!Q6 -> 0.01 | M5: =敌人目录!R6 -> 0 | N5: =敌人目录!S6 -> 0 | O5: =敌人目录!T6 -> 0 | P5: =敌人目录!U6 -> 0 | Q5: =敌人目录!V6 -> 0.004 | ... U5: =敌人目录!Z6 -> 0.002 | V5: =敌人目录!N6 -> 0.046 | W5: =敌人目录!AA6 -> 可回读 | X5: =敌人目录!AC6 -> res://resources/config/enemies/yuanshi_insect_basic.tres
A6: 3 | B6: =敌人目录!B7 -> yuanshi_insect_shell | C6: =敌人目录!G7 -> 140 | D6: =敌人目录!H7 -> 14 | E6: =敌人目录!I7 -> 3 | F6: =敌人目录!J7 -> 0 | G6: =敌人目录!K7 -> 20 | H6: =敌人目录!L7 -> 2 | I6: =敌人目录!M7 -> 2 | J6: =敌人目录!O7 -> 0.02 | K6: =敌人目录!P7 -> 0.002 | L6: =敌人目录!Q7 -> 0.01 | M6: =敌人目录!R7 -> 0 | N6: =敌人目录!S7 -> 0 | O6: =敌人目录!T7 -> 0 | P6: =敌人目录!U7 -> 0 | Q6: =敌人目录!V7 -> 0.004 | ... U6: =敌人目录!Z7 -> 0.002 | V6: =敌人目录!N7 -> 0.046 | W6: =敌人目录!AA7 -> 可回读 | X6: =敌人目录!AC7 -> res://resources/config/enemies/yuanshi_insect_shell.tres
A7: 3 | B7: =敌人目录!B8 -> yuanshi_insect_fast | C7: =敌人目录!G8 -> 35 | D7: =敌人目录!H8 -> 10 | E7: =敌人目录!I8 -> 0 | F7: =敌人目录!J8 -> 0 | G7: =敌人目录!K8 -> 40 | H7: =敌人目录!L8 -> 1 | I7: =敌人目录!M8 -> 1 | J7: =敌人目录!O8 -> 0.02 | K7: =敌人目录!P8 -> 0.002 | L7: =敌人目录!Q8 -> 0.01 | M7: =敌人目录!R8 -> 0 | N7: =敌人目录!S8 -> 0 | O7: =敌人目录!T8 -> 0 | P7: =敌人目录!U8 -> 0 | Q7: =敌人目录!V8 -> 0.004 | ... U7: =敌人目录!Z8 -> 0.002 | V7: =敌人目录!N8 -> 0.046 | W7: =敌人目录!AA8 -> 可回读 | X7: =敌人目录!AC8 -> res://resources/config/enemies/yuanshi_insect_fast.tres
A8: 3 | B8: =敌人目录!B9 -> yuanshi_insect_bomber | C8: =敌人目录!G9 -> 30 | D8: =敌人目录!H9 -> 10 | E8: =敌人目录!I9 -> 0 | F8: =敌人目录!J9 -> 0 | G8: =敌人目录!K9 -> 18 | H8: =敌人目录!L9 -> 1 | I8: =敌人目录!M9 -> 1 | J8: =敌人目录!O9 -> 0.02 | K8: =敌人目录!P9 -> 0.002 | L8: =敌人目录!Q9 -> 0.01 | M8: =敌人目录!R9 -> 0 | N8: =敌人目录!S9 -> 0 | O8: =敌人目录!T9 -> 0 | P8: =敌人目录!U9 -> 0 | Q8: =敌人目录!V9 -> 0.004 | ... U8: =敌人目录!Z9 -> 0.002 | V8: =敌人目录!N9 -> 0.046 | W8: =敌人目录!AA9 -> 可回读 | X8: =敌人目录!AC9 -> res://resources/config/enemies/yuanshi_insect_bomber.tres
A9: 3 | B9: =敌人目录!B10 -> yuanshi_insect_purple_bomber | C9: =敌人目录!G10 -> 40 | D9: =敌人目录!H10 -> 10 | E9: =敌人目录!I10 -> 0 | F9: =敌人目录!J10 -> 0 | G9: =敌人目录!K10 -> 32 | H9: =敌人目录!L10 -> 1 | I9: =敌人目录!M10 -> 2 | J9: =敌人目录!O10 -> 0.02 | K9: =敌人目录!P10 -> 0.002 | L9: =敌人目录!Q10 -> 0.01 | M9: =敌人目录!R10 -> 0 | N9: =敌人目录!S10 -> 0 | O9: =敌人目录!T10 -> 0 | P9: =敌人目录!U10 -> 0 | Q9: =敌人目录!V10 -> 0.004 | ... U9: =敌人目录!Z10 -> 0.002 | V9: =敌人目录!N10 -> 0.046 | W9: =敌人目录!AA10 -> 可回读 | X9: =敌人目录!AC10 -> res://resources/config/enemies/yuanshi_insect_purple_bomber.tres
A10: 3 | B10: =敌人目录!B11 -> yuanshi_insect_green_shell | C10: =敌人目录!G11 -> 200 | D10: =敌人目录!H11 -> 20 | E10: =敌人目录!I11 -> 5 | F10: =敌人目录!J11 -> 0 | G10: =敌人目录!K11 -> 15 | H10: =敌人目录!L11 -> 5 | I10: =敌人目录!M11 -> 2 | J10: =敌人目录!O11 -> 0.02 | K10: =敌人目录!P11 -> 0.002 | L10: =敌人目录!Q11 -> 0.01 | M10: =敌人目录!R11 -> 0 | N10: =敌人目录!S11 -> 0 | O10: =敌人目录!T11 -> 0 | P10: =敌人目录!U11 -> 0 | Q10: =敌人目录!V11 -> 0.004 | ... U10: =敌人目录!Z11 -> 0.002 | V10: =敌人目录!N11 -> 0.046 | W10: =敌人目录!AA11 -> 可回读 | X10: =敌人目录!AC11 -> res://resources/config/enemies/yuanshi_insect_green_shell.tres
A11: 3 | B11: =敌人目录!B12 -> yuanshi_insect_fire_ranged | C11: =敌人目录!G12 -> 40 | D11: =敌人目录!H12 -> 25 | E11: =敌人目录!I12 -> 0 | F11: =敌人目录!J12 -> 0 | G11: =敌人目录!K12 -> 22 | H11: =敌人目录!L12 -> 2 | I11: =敌人目录!M12 -> 1 | J11: =敌人目录!O12 -> 0.02 | K11: =敌人目录!P12 -> 0.002 | L11: =敌人目录!Q12 -> 0.01 | M11: =敌人目录!R12 -> 0 | N11: =敌人目录!S12 -> 0 | O11: =敌人目录!T12 -> 0 | P11: =敌人目录!U12 -> 0 | Q11: =敌人目录!V12 -> 0.004 | ... U11: =敌人目录!Z12 -> 0.002 | V11: =敌人目录!N12 -> 0.046 | W11: =敌人目录!AA12 -> 可回读 | X11: =敌人目录!AC12 -> res://resources/config/enemies/yuanshi_insect_fire_ranged.tres
A12: 3 | B12: =敌人目录!B13 -> yuanshi_insect_guardian | C12: =敌人目录!G13 -> 150 | D12: =敌人目录!H13 -> 10 | E12: =敌人目录!I13 -> 5 | F12: =敌人目录!J13 -> 0 | G12: =敌人目录!K13 -> 20 | H12: =敌人目录!L13 -> 5 | I12: =敌人目录!M13 -> 2 | J12: =敌人目录!O13 -> 0.02 | K12: =敌人目录!P13 -> 0.002 | L12: =敌人目录!Q13 -> 0.01 | M12: =敌人目录!R13 -> 0 | N12: =敌人目录!S13 -> 0 | O12: =敌人目录!T13 -> 0 | P12: =敌人目录!U13 -> 0 | Q12: =敌人目录!V13 -> 0.004 | ... U12: =敌人目录!Z13 -> 0.002 | V12: =敌人目录!N13 -> 0.046 | W12: =敌人目录!AA13 -> 可回读 | X12: =敌人目录!AC13 -> res://resources/config/enemies/yuanshi_insect_guardian.tres
A13: 3 | B13: =敌人目录!B14 -> stone_eroded_yuanshi_insect_basic | C13: =敌人目录!G14 -> 80 | D13: =敌人目录!H14 -> 10 | E13: =敌人目录!I14 -> 150 | F13: =敌人目录!J14 -> 0 | G13: =敌人目录!K14 -> 20 | H13: =敌人目录!L14 -> 1 | I13: =敌人目录!M14 -> 1 | J13: =敌人目录!O14 -> 0.02 | K13: =敌人目录!P14 -> 0.002 | L13: =敌人目录!Q14 -> 0.01 | M13: =敌人目录!R14 -> 0 | N13: =敌人目录!S14 -> 0 | O13: =敌人目录!T14 -> 0 | P13: =敌人目录!U14 -> 0 | Q13: =敌人目录!V14 -> 0.004 | ... U13: =敌人目录!Z14 -> 0.002 | V13: =敌人目录!N14 -> 0.046 | W13: =敌人目录!AA14 -> 可回读 | X13: =敌人目录!AC14 -> res://resources/config/enemies/stone_eroded_yuanshi_insect_basic.tres
A14: 3 | B14: =敌人目录!B15 -> stone_eroded_yuanshi_insect_shell | C14: =敌人目录!G15 -> 280 | D14: =敌人目录!H15 -> 14 | E14: =敌人目录!I15 -> 150 | F14: =敌人目录!J15 -> 0 | G14: =敌人目录!K15 -> 20 | H14: =敌人目录!L15 -> 2 | I14: =敌人目录!M15 -> 2 | J14: =敌人目录!O15 -> 0.02 | K14: =敌人目录!P15 -> 0.002 | L14: =敌人目录!Q15 -> 0.01 | M14: =敌人目录!R15 -> 0 | N14: =敌人目录!S15 -> 0 | O14: =敌人目录!T15 -> 0 | P14: =敌人目录!U15 -> 0 | Q14: =敌人目录!V15 -> 0.004 | ... U14: =敌人目录!Z15 -> 0.002 | V14: =敌人目录!N15 -> 0.046 | W14: =敌人目录!AA15 -> 可回读 | X14: =敌人目录!AC15 -> res://resources/config/enemies/stone_eroded_yuanshi_insect_shell.tres
A15: 3 | B15: =敌人目录!B16 -> stone_eroded_yuanshi_insect_fast | C15: =敌人目录!G16 -> 70 | D15: =敌人目录!H16 -> 10 | E15: =敌人目录!I16 -> 150 | F15: =敌人目录!J16 -> 0 | G15: =敌人目录!K16 -> 40 | H15: =敌人目录!L16 -> 1 | I15: =敌人目录!M16 -> 1 | J15: =敌人目录!O16 -> 0.02 | K15: =敌人目录!P16 -> 0.002 | L15: =敌人目录!Q16 -> 0.01 | M15: =敌人目录!R16 -> 0 | N15: =敌人目录!S16 -> 0 | O15: =敌人目录!T16 -> 0 | P15: =敌人目录!U16 -> 0 | Q15: =敌人目录!V16 -> 0.004 | ... U15: =敌人目录!Z16 -> 0.002 | V15: =敌人目录!N16 -> 0.046 | W15: =敌人目录!AA16 -> 可回读 | X15: =敌人目录!AC16 -> res://resources/config/enemies/stone_eroded_yuanshi_insect_fast.tres
