Workbook

Sheet 使用说明
A1: 塔防模式｜16 波智能设计器 | B1: 塔防模式｜16 波智能设计器 | C1: 塔防模式｜16 波智能设计器 | D1: 塔防模式｜16 波智能设计器 | E1: 塔防模式｜16 波智能设计器 | F1: 塔防模式｜16 波智能设计器 | G1: 塔防模式｜16 波智能设计器 | H1: 塔防模式｜16 波智能设计器
A2: 敌人数值与掉落已改为全局固定配置；波次页只负责敌人组成、数量与息壤收益结算。第 13～16 波仍保留为空白。 | B2: 敌人数值与掉落已改为全局固定配置；波次页只负责敌人组成、数量与息壤收益结算。第 13～16 波仍保留为空白。 | C2: 敌人数值与掉落已改为全局固定配置；波次页只负责敌人组成、数量与息壤收益结算。第 13～16 波仍保留为空白。 | D2: 敌人数值与掉落已改为全局固定配置；波次页只负责敌人组成、数量与息壤收益结算。第 13～16 波仍保留为空白。 | E2: 敌人数值与掉落已改为全局固定配置；波次页只负责敌人组成、数量与息壤收益结算。第 13～16 波仍保留为空白。 | F2: 敌人数值与掉落已改为全局固定配置；波次页只负责敌人组成、数量与息壤收益结算。第 13～16 波仍保留为空白。 | G2: 敌人数值与掉落已改为全局固定配置；波次页只负责敌人组成、数量与息壤收益结算。第 13～16 波仍保留为空白。 | H2: 敌人数值与掉落已改为全局固定配置；波次页只负责敌人组成、数量与息壤收益结算。第 13～16 波仍保留为空白。
A4: 建议工作流 | B4: 建议工作流 | C4: 建议工作流 | D4: 建议工作流 | E4: 建议工作流 | F4: 建议工作流 | G4: 建议工作流 | H4: 建议工作流
A5: 1 | B5: 先到“敌人目录”编辑每种敌人的生命、攻击、防御、移速、Home 伤害、击杀息壤与 12 类独立掉落概率。
A6: 2 | B6: 再到“全局设置”选择模拟玩家数、预计击杀率和每日息壤情景倍率。
A7: 3 | B7: 在“第1日”至“第4日”逐波从下拉列表选择敌人并填写基础数量；同一种敌人同一波只填一行。
A8: 4 | B8: 波次页会逐项显示息壤/击杀、最大收益与情景收益；到“总览”复核 16 波曲线和可回读状态。
A9: 5 | B9: 设计完成后把工作簿交回 Codex；机器区会同时提供敌人固定配置与 16 波组成，再生成正式 Godot 资源。
A11: 颜色与输入规则 | B11: 颜色与输入规则 | C11: 颜色与输入规则 | D11: 颜色与输入规则 | E11: 颜色与输入规则 | F11: 颜色与输入规则 | G11: 颜色与输入规则 | H11: 颜色与输入规则
A12: 浅蓝 | B12: 波次选择、数量与敌人战斗数值：可编辑
A13: 金黄 | B13: 每只敌人的固定息壤奖励：可编辑
A14: 浅绿 | B14: 材料类掉落概率：可编辑，输入 0%～100%
A15: 浅紫 | B15: 功能道具掉落概率：可编辑，输入 0%～100%
A16: 浅灰 | B16: 自动公式与稳定标识：请勿手工覆盖
A17: 浅红 | B17: 无法回读：缺少输入、重复敌人或数值越界
A19: 计算口径（与当前游戏一致） | B19: 计算口径（与当前游戏一致） | C19: 计算口径（与当前游戏一致） | D19: 计算口径（与当前游戏一致） | E19: 计算口径（与当前游戏一致） | F19: 计算口径（与当前游戏一致） | G19: 计算口径（与当前游戏一致） | H19: 计算口径（与当前游戏一致）
A20: 多人数量 | B20: 每条敌人分别 ROUNDUP(基础数量 × [1 + (玩家数-1) × 25%], 0)。
A21: 击杀息壤 | B21: 每位玩家各得整份，不在队伍内分摊；漏进 Home 的敌人不发击杀息壤。
A22: 命运倍率 | B22: 作为每日情景倍率单独计算，不改写基础收益；默认均为 1，可选择 2。
A23: 固定配置 | B23: 敌人的数值、息壤与掉落不随波次变化；修改一行会影响所有引用该敌人的波次与最终游戏配置。
A24: 掉落 | B24: 12 类掉落均为逐敌人独立概率；同一次击杀可同时掉出多件，概率之和仅表示期望件数。
A25: 刷怪时间 | B25: 按首批立即生成计算理论最短时间；存活上限或战斗堵塞会令实战更久。
A26: 出场顺序 | B26: 游戏会将整波生成队列随机打乱；本表精确设计组成与节奏，但不承诺固定先后顺序。
A27: Boss | B27: 铃兰保留为独立 Boss 流程，不会出现在普通波次敌人下拉列表。
A29: 请勿直接编辑两个“导入数据（勿改）”工作表与“系统数据（勿改）”；它们是稳定 ID 和反向回读契约。 | B29: 请勿直接编辑两个“导入数据（勿改）”工作表与“系统数据（勿改）”；它们是稳定 ID 和反向回读契约。 | C29: 请勿直接编辑两个“导入数据（勿改）”工作表与“系统数据（勿改）”；它们是稳定 ID 和反向回读契约。 | D29: 请勿直接编辑两个“导入数据（勿改）”工作表与“系统数据（勿改）”；它们是稳定 ID 和反向回读契约。 | E29: 请勿直接编辑两个“导入数据（勿改）”工作表与“系统数据（勿改）”；它们是稳定 ID 和反向回读契约。 | F29: 请勿直接编辑两个“导入数据（勿改）”工作表与“系统数据（勿改）”；它们是稳定 ID 和反向回读契约。 | G29: 请勿直接编辑两个“导入数据（勿改）”工作表与“系统数据（勿改）”；它们是稳定 ID 和反向回读契约。 | H29: 请勿直接编辑两个“导入数据（勿改）”工作表与“系统数据（勿改）”；它们是稳定 ID 和反向回读契约。

Sheet 总览
A1: 塔防模式｜16 波息壤收益总览 | B1: 塔防模式｜16 波息壤收益总览 | C1: 塔防模式｜16 波息壤收益总览 | D1: 塔防模式｜16 波息壤收益总览 | E1: 塔防模式｜16 波息壤收益总览 | F1: 塔防模式｜16 波息壤收益总览 | G1: 塔防模式｜16 波息壤收益总览 | H1: 塔防模式｜16 波息壤收益总览 | I1: 塔防模式｜16 波息壤收益总览 | J1: 塔防模式｜16 波息壤收益总览 | K1: 塔防模式｜16 波息壤收益总览 | L1: 塔防模式｜16 波息壤收益总览 | M1: 塔防模式｜16 波息壤收益总览 | N1: 塔防模式｜16 波息壤收益总览
A2: 每波收益由“实际数量 × 敌人目录中的固定息壤”逐项汇总；第 13～16 波未填写时明确显示“待设计”。 | B2: 每波收益由“实际数量 × 敌人目录中的固定息壤”逐项汇总；第 13～16 波未填写时明确显示“待设计”。 | C2: 每波收益由“实际数量 × 敌人目录中的固定息壤”逐项汇总；第 13～16 波未填写时明确显示“待设计”。 | D2: 每波收益由“实际数量 × 敌人目录中的固定息壤”逐项汇总；第 13～16 波未填写时明确显示“待设计”。 | E2: 每波收益由“实际数量 × 敌人目录中的固定息壤”逐项汇总；第 13～16 波未填写时明确显示“待设计”。 | F2: 每波收益由“实际数量 × 敌人目录中的固定息壤”逐项汇总；第 13～16 波未填写时明确显示“待设计”。 | G2: 每波收益由“实际数量 × 敌人目录中的固定息壤”逐项汇总；第 13～16 波未填写时明确显示“待设计”。 | H2: 每波收益由“实际数量 × 敌人目录中的固定息壤”逐项汇总；第 13～16 波未填写时明确显示“待设计”。 | I2: 每波收益由“实际数量 × 敌人目录中的固定息壤”逐项汇总；第 13～16 波未填写时明确显示“待设计”。 | J2: 每波收益由“实际数量 × 敌人目录中的固定息壤”逐项汇总；第 13～16 波未填写时明确显示“待设计”。 | K2: 每波收益由“实际数量 × 敌人目录中的固定息壤”逐项汇总；第 13～16 波未填写时明确显示“待设计”。 | L2: 每波收益由“实际数量 × 敌人目录中的固定息壤”逐项汇总；第 13～16 波未填写时明确显示“待设计”。 | M2: 每波收益由“实际数量 × 敌人目录中的固定息壤”逐项汇总；第 13～16 波未填写时明确显示“待设计”。 | N2: 每波收益由“实际数量 × 敌人目录中的固定息壤”逐项汇总；第 13～16 波未填写时明确显示“待设计”。
A4: 可回读波次 | B4: =COUNTIF(E9:E24,"可回读")&" / 16" -> 11 / 16 | D4: 基础敌人数 | E4: =SUM(F9:F24) -> 11396 | G4: 情景息壤/玩家 | H4: =SUM(J9:J24) -> 13182 | J4: 情景息壤/队伍 | K4: =SUM(K9:K24) -> 13182 | M4: 敌人配置可回读 | N4: =COUNTIF(敌人目录!AA6:AA54,"可回读")&" / 49" -> 49 / 49
A8: 波次 | B8: 日 | C8: 时段 | D8: 名称 | E8: 状态 | F8: 基础数量 | G8: 实际数量 | H8: 敌人种类 | I8: 最大息壤/玩家 | J8: 情景息壤/玩家 | K8: 情景息壤/队伍 | L8: 最短刷完(s) | M8: 存活上限 | N8: 启用出生点
A9: 第1波 | B9: 1 | C9: 白昼 | D9: =第1日!$B$3 -> 第1波 林地试探 | E9: =第1日!$I$4 -> 可回读 | F9: =第1日!$B$26 -> 2500 | G9: =第1日!$D$26 -> 2500 | H9: =COUNTA(第1日!$B$7:$B$24) -> 4 | I9: =第1日!$F$26 -> 2500 | J9: =第1日!$H$26 -> 2500 | K9: =第1日!$B$27 -> 2500 | L9: =IF(G9=0,0,MAX(0,(ROUNDUP(G9/第1日!$G$3,0)-1)*第1日!$E$3)) -> 499.8 | M9: =第1日!$I$3 -> 300 | N9: =IF(第1日!$B$4="点1·开启",1,0)+IF(第1日!$C$4="点2·开启",1,0)+IF(第1日!$D$4="点3·开启",1,0)+IF(第1日!$E$4="点4·开启",1,0)+IF(第1日!$F$4="点5·开启",1,0)+IF(第1日!$G$4="点6·开启",1,0) -> 4
A10: 第2波 | B10: 1 | C10: 白昼 | D10: =第1日!$B$32 -> 第2波 迅影与硬壳 | E10: =第1日!$I$33 -> 可回读 | F10: =第1日!$B$55 -> 3850 | G10: =第1日!$D$55 -> 3850 | H10: =COUNTA(第1日!$B$36:$B$53) -> 7 | I10: =第1日!$F$55 -> 4050 | J10: =第1日!$H$55 -> 4050 | K10: =第1日!$B$56 -> 4050 | L10: =IF(G10=0,0,MAX(0,(ROUNDUP(G10/第1日!$G$32,0)-1)*第1日!$E$32)) -> 384.9 | M10: =第1日!$I$32 -> 300 | N10: =IF(第1日!$B$33="点1·开启",1,0)+IF(第1日!$C$33="点2·开启",1,0)+IF(第1日!$D$33="点3·开启",1,0)+IF(第1日!$E$33="点4·开启",1,0)+IF(第1日!$F$33="点5·开启",1,0)+IF(第1日!$G$33="点6·开启",1,0) -> 4
A11: 第3波 | B11: 1 | C11: 夜晚 | D11: =第1日!$B$61 -> 第3波 火线初现 | E11: =第1日!$I$62 -> 可回读 | F11: =第1日!$B$84 -> 3950 | G11: =第1日!$D$84 -> 3950 | H11: =COUNTA(第1日!$B$65:$B$82) -> 8 | I11: =第1日!$F$84 -> 5000 | J11: =第1日!$H$84 -> 5000 | K11: =第1日!$B$85 -> 5000 | L11: =IF(G11=0,0,MAX(0,(ROUNDUP(G11/第1日!$G$61,0)-1)*第1日!$E$61)) -> 394.9 | M11: =第1日!$I$61 -> 300 | N11: =IF(第1日!$B$62="点1·开启",1,0)+IF(第1日!$C$62="点2·开启",1,0)+IF(第1日!$D$62="点3·开启",1,0)+IF(第1日!$E$62="点4·开启",1,0)+IF(第1日!$F$62="点5·开启",1,0)+IF(第1日!$G$62="点6·开启",1,0) -> 6
A12: 第4波 | B12: 1 | C12: 夜晚 | D12: =第1日!$B$90 -> 第4波 林地合围 | E12: =第1日!$I$91 -> 待设计 | F12: =第1日!$B$113 -> 0 | G12: =第1日!$D$113 -> 0 | H12: =COUNTA(第1日!$B$94:$B$111) -> 0 | I12: =第1日!$F$113 -> 0 | J12: =第1日!$H$113 -> 0 | K12: =第1日!$B$114 -> 0 | L12: =IF(G12=0,0,MAX(0,(ROUNDUP(G12/第1日!$G$90,0)-1)*第1日!$E$90)) -> 0 | M12: =第1日!$I$90 -> 300 | N12: =IF(第1日!$B$91="点1·开启",1,0)+IF(第1日!$C$91="点2·开启",1,0)+IF(第1日!$D$91="点3·开启",1,0)+IF(第1日!$E$91="点4·开启",1,0)+IF(第1日!$F$91="点5·开启",1,0)+IF(第1日!$G$91="点6·开启",1,0) -> 6
A13: 第5波 | B13: 2 | C13: 白昼 | D13: =第2日!$B$3 -> 第5波 沼泽先遣 | E13: =第2日!$I$4 -> 可回读 | F13: =第2日!$B$26 -> 80 | G13: =第2日!$D$26 -> 80 | H13: =COUNTA(第2日!$B$7:$B$24) -> 6 | I13: =第2日!$F$26 -> 96 | J13: =第2日!$H$26 -> 96 | K13: =第2日!$B$27 -> 96 | L13: =IF(G13=0,0,MAX(0,(ROUNDUP(G13/第2日!$G$3,0)-1)*第2日!$E$3)) -> 35.55 | M13: =第2日!$I$3 -> 300 | N13: =IF(第2日!$B$4="点1·开启",1,0)+IF(第2日!$C$4="点2·开启",1,0)+IF(第2日!$D$4="点3·开启",1,0)+IF(第2日!$E$4="点4·开启",1,0)+IF(第2日!$F$4="点5·开启",1,0)+IF(第2日!$G$4="点6·开启",1,0) -> 6
A14: 第6波 | B14: 2 | C14: 白昼 | D14: =第2日!$B$32 -> 第6波 守护阵列 | E14: =第2日!$I$33 -> 可回读 | F14: =第2日!$B$55 -> 96 | G14: =第2日!$D$55 -> 96 | H14: =COUNTA(第2日!$B$36:$B$53) -> 6 | I14: =第2日!$F$55 -> 116 | J14: =第2日!$H$55 -> 116 | K14: =第2日!$B$56 -> 116 | L14: =IF(G14=0,0,MAX(0,(ROUNDUP(G14/第2日!$G$32,0)-1)*第2日!$E$32)) -> 38 | M14: =第2日!$I$32 -> 300 | N14: =IF(第2日!$B$33="点1·开启",1,0)+IF(第2日!$C$33="点2·开启",1,0)+IF(第2日!$D$33="点3·开启",1,0)+IF(第2日!$E$33="点4·开启",1,0)+IF(第2日!$F$33="点5·开启",1,0)+IF(第2日!$G$33="点6·开启",1,0) -> 6
A15: 第7波 | B15: 2 | C15: 夜晚 | D15: =第2日!$B$61 -> 第7波 紫晶突袭 | E15: =第2日!$I$62 -> 可回读 | F15: =第2日!$B$84 -> 112 | G15: =第2日!$D$84 -> 112 | H15: =COUNTA(第2日!$B$65:$B$82) -> 7 | I15: =第2日!$F$84 -> 144 | J15: =第2日!$H$84 -> 144 | K15: =第2日!$B$85 -> 144 | L15: =IF(G15=0,0,MAX(0,(ROUNDUP(G15/第2日!$G$61,0)-1)*第2日!$E$61)) -> 38.85 | M15: =第2日!$I$61 -> 300 | N15: =IF(第2日!$B$62="点1·开启",1,0)+IF(第2日!$C$62="点2·开启",1,0)+IF(第2日!$D$62="点3·开启",1,0)+IF(第2日!$E$62="点4·开启",1,0)+IF(第2日!$F$62="点5·开启",1,0)+IF(第2日!$G$62="点6·开启",1,0) -> 6
A16: 第8波 | B16: 2 | C16: 夜晚 | D16: =第2日!$B$90 -> 第8波 沼泽合围 | E16: =第2日!$I$91 -> 可回读 | F16: =第2日!$B$113 -> 128 | G16: =第2日!$D$113 -> 128 | H16: =COUNTA(第2日!$B$94:$B$111) -> 7 | I16: =第2日!$F$113 -> 172 | J16: =第2日!$H$113 -> 172 | K16: =第2日!$B$114 -> 172 | L16: =IF(G16=0,0,MAX(0,(ROUNDUP(G16/第2日!$G$90,0)-1)*第2日!$E$90)) -> 38.1 | M16: =第2日!$I$90 -> 300 | N16: =IF(第2日!$B$91="点1·开启",1,0)+IF(第2日!$C$91="点2·开启",1,0)+IF(第2日!$D$91="点3·开启",1,0)+IF(第2日!$E$91="点4·开启",1,0)+IF(第2日!$F$91="点5·开启",1,0)+IF(第2日!$G$91="点6·开启",1,0) -> 6
A17: 第9波 | B17: 3 | C17: 白昼 | D17: =第3日!$B$3 -> 第9波 城镇前锋 | E17: =第3日!$I$4 -> 可回读 | F17: =第3日!$B$26 -> 144 | G17: =第3日!$D$26 -> 144 | H17: =COUNTA(第3日!$B$7:$B$24) -> 9 | I17: =第3日!$F$26 -> 210 | J17: =第3日!$H$26 -> 210 | K17: =第3日!$B$27 -> 210 | L17: =IF(G17=0,0,MAX(0,(ROUNDUP(G17/第3日!$G$3,0)-1)*第3日!$E$3)) -> 40.04 | M17: =第3日!$I$3 -> 300 | N17: =IF(第3日!$B$4="点1·开启",1,0)+IF(第3日!$C$4="点2·开启",1,0)+IF(第3日!$D$4="点3·开启",1,0)+IF(第3日!$E$4="点4·开启",1,0)+IF(第3日!$F$4="点5·开启",1,0)+IF(第3日!$G$4="点6·开启",1,0) -> 6
A18: 第10波 | B18: 3 | C18: 白昼 | D18: =第3日!$B$32 -> 第10波 火力交叉 | E18: =第3日!$I$33 -> 可回读 | F18: =第3日!$B$55 -> 160 | G18: =第3日!$D$55 -> 160 | H18: =COUNTA(第3日!$B$36:$B$53) -> 10 | I18: =第3日!$F$55 -> 246 | J18: =第3日!$H$55 -> 246 | K18: =第3日!$B$56 -> 246 | L18: =IF(G18=0,0,MAX(0,(ROUNDUP(G18/第3日!$G$32,0)-1)*第3日!$E$32)) -> 41.34 | M18: =第3日!$I$32 -> 300 | N18: =IF(第3日!$B$33="点1·开启",1,0)+IF(第3日!$C$33="点2·开启",1,0)+IF(第3日!$D$33="点3·开启",1,0)+IF(第3日!$E$33="点4·开启",1,0)+IF(第3日!$F$33="点5·开启",1,0)+IF(第3日!$G$33="点6·开启",1,0) -> 6
A19: 第11波 | B19: 3 | C19: 夜晚 | D19: =第3日!$B$61 -> 第11波 奥术重装 | E19: =第3日!$I$62 -> 可回读 | F19: =第3日!$B$84 -> 176 | G19: =第3日!$D$84 -> 176 | H19: =COUNTA(第3日!$B$65:$B$82) -> 12 | I19: =第3日!$F$84 -> 306 | J19: =第3日!$H$84 -> 306 | K19: =第3日!$B$85 -> 306 | L19: =IF(G19=0,0,MAX(0,(ROUNDUP(G19/第3日!$G$61,0)-1)*第3日!$E$61)) -> 42 | M19: =第3日!$I$61 -> 300 | N19: =IF(第3日!$B$62="点1·开启",1,0)+IF(第3日!$C$62="点2·开启",1,0)+IF(第3日!$D$62="点3·开启",1,0)+IF(第3日!$E$62="点4·开启",1,0)+IF(第3日!$F$62="点5·开启",1,0)+IF(第3日!$G$62="点6·开启",1,0) -> 6
A20: 第12波 | B20: 3 | C20: 夜晚 | D20: =第3日!$B$90 -> 第12波 城镇决战 | E20: =第3日!$I$91 -> 可回读 | F20: =第3日!$B$113 -> 200 | G20: =第3日!$D$113 -> 200 | H20: =COUNTA(第3日!$B$94:$B$111) -> 13 | I20: =第3日!$F$113 -> 342 | J20: =第3日!$H$113 -> 342 | K20: =第3日!$B$114 -> 342 | L20: =IF(G20=0,0,MAX(0,(ROUNDUP(G20/第3日!$G$90,0)-1)*第3日!$E$90)) -> 43.78 | M20: =第3日!$I$90 -> 300 | N20: =IF(第3日!$B$91="点1·开启",1,0)+IF(第3日!$C$91="点2·开启",1,0)+IF(第3日!$D$91="点3·开启",1,0)+IF(第3日!$E$91="点4·开启",1,0)+IF(第3日!$F$91="点5·开启",1,0)+IF(第3日!$G$91="点6·开启",1,0) -> 6
A21: 第13波 | B21: 4 | C21: 白昼 | D21: =第4日!$B$3 -> 第13波（待设计） | E21: =第4日!$I$4 -> 待设计 | F21: =第4日!$B$26 -> 0 | G21: =第4日!$D$26 -> 0 | H21: =COUNTA(第4日!$B$7:$B$24) -> 0 | I21: =第4日!$F$26 -> 0 | J21: =第4日!$H$26 -> 0 | K21: =第4日!$B$27 -> 0 | L21: =IF(G21=0,0,MAX(0,(ROUNDUP(G21/第4日!$G$3,0)-1)*第4日!$E$3)) -> 0 | M21: =第4日!$I$3 -> 300 | N21: =IF(第4日!$B$4="点1·开启",1,0)+IF(第4日!$C$4="点2·开启",1,0)+IF(第4日!$D$4="点3·开启",1,0)+IF(第4日!$E$4="点4·开启",1,0)+IF(第4日!$F$4="点5·开启",1,0)+IF(第4日!$G$4="点6·开启",1,0) -> 6
A22: 第14波 | B22: 4 | C22: 白昼 | D22: =第4日!$B$32 -> 第14波（待设计） | E22: =第4日!$I$33 -> 待设计 | F22: =第4日!$B$55 -> 0 | G22: =第4日!$D$55 -> 0 | H22: =COUNTA(第4日!$B$36:$B$53) -> 0 | I22: =第4日!$F$55 -> 0 | J22: =第4日!$H$55 -> 0 | K22: =第4日!$B$56 -> 0 | L22: =IF(G22=0,0,MAX(0,(ROUNDUP(G22/第4日!$G$32,0)-1)*第4日!$E$32)) -> 0 | M22: =第4日!$I$32 -> 300 | N22: =IF(第4日!$B$33="点1·开启",1,0)+IF(第4日!$C$33="点2·开启",1,0)+IF(第4日!$D$33="点3·开启",1,0)+IF(第4日!$E$33="点4·开启",1,0)+IF(第4日!$F$33="点5·开启",1,0)+IF(第4日!$G$33="点6·开启",1,0) -> 6
A23: 第15波 | B23: 4 | C23: 夜晚 | D23: =第4日!$B$61 -> 第15波（待设计） | E23: =第4日!$I$62 -> 待设计 | F23: =第4日!$B$84 -> 0 | G23: =第4日!$D$84 -> 0 | H23: =COUNTA(第4日!$B$65:$B$82) -> 0 | I23: =第4日!$F$84 -> 0 | J23: =第4日!$H$84 -> 0 | K23: =第4日!$B$85 -> 0 | L23: =IF(G23=0,0,MAX(0,(ROUNDUP(G23/第4日!$G$61,0)-1)*第4日!$E$61)) -> 0 | M23: =第4日!$I$61 -> 300 | N23: =IF(第4日!$B$62="点1·开启",1,0)+IF(第4日!$C$62="点2·开启",1,0)+IF(第4日!$D$62="点3·开启",1,0)+IF(第4日!$E$62="点4·开启",1,0)+IF(第4日!$F$62="点5·开启",1,0)+IF(第4日!$G$62="点6·开启",1,0) -> 6
A24: 第16波 | B24: 4 | C24: 夜晚 | D24: =第4日!$B$90 -> 第16波（待设计） | E24: =第4日!$I$91 -> 待设计 | F24: =第4日!$B$113 -> 0 | G24: =第4日!$D$113 -> 0 | H24: =COUNTA(第4日!$B$94:$B$111) -> 0 | I24: =第4日!$F$113 -> 0 | J24: =第4日!$H$113 -> 0 | K24: =第4日!$B$114 -> 0 | L24: =IF(G24=0,0,MAX(0,(ROUNDUP(G24/第4日!$G$90,0)-1)*第4日!$E$90)) -> 0 | M24: =第4日!$I$90 -> 300 | N24: =IF(第4日!$B$91="点1·开启",1,0)+IF(第4日!$C$91="点2·开启",1,0)+IF(第4日!$D$91="点3·开启",1,0)+IF(第4日!$E$91="点4·开启",1,0)+IF(第4日!$F$91="点5·开启",1,0)+IF(第4日!$G$91="点6·开启",1,0) -> 6
A26: 每日汇总 | B26: 每日汇总 | C26: 每日汇总 | D26: 每日汇总 | E26: 每日汇总 | F26: 每日汇总 | G26: 每日汇总 | H26: 每日汇总 | I26: 每日汇总 | J26: 每日汇总 | K26: 每日汇总 | L26: 每日汇总 | M26: 每日汇总 | N26: 每日汇总
A27: 日 | B27: 基础敌人 | C27: 实际敌人 | D27: 最大息壤/玩家 | E27: 情景息壤/玩家 | F27: 情景息壤/队伍
A28: 第1日 | B28: =SUM(F9:F12) -> 10300 | C28: =SUM(G9:G12) -> 10300 | D28: =SUM(I9:I12) -> 11550 | E28: =SUM(J9:J12) -> 11550 | F28: =SUM(K9:K12) -> 11550
A29: 第2日 | B29: =SUM(F13:F16) -> 416 | C29: =SUM(G13:G16) -> 416 | D29: =SUM(I13:I16) -> 528 | E29: =SUM(J13:J16) -> 528 | F29: =SUM(K13:K16) -> 528
A30: 第3日 | B30: =SUM(F17:F20) -> 680 | C30: =SUM(G17:G20) -> 680 | D30: =SUM(I17:I20) -> 1104 | E30: =SUM(J17:J20) -> 1104 | F30: =SUM(K17:K20) -> 1104
A31: 第4日 | B31: =SUM(F21:F24) -> 0 | C31: =SUM(G21:G24) -> 0 | D31: =SUM(I21:I24) -> 0 | E31: =SUM(J21:J24) -> 0 | F31: =SUM(K21:K24) -> 0
A34: 波次 | B34: 最大息壤/玩家 | C34: 情景息壤/玩家
A35: =A9 -> 第1波 | B35: =I9 -> 2500 | C35: =J9 -> 2500
A36: =A10 -> 第2波 | B36: =I10 -> 4050 | C36: =J10 -> 4050
A37: =A11 -> 第3波 | B37: =I11 -> 5000 | C37: =J11 -> 5000
A38: =A12 -> 第4波 | B38: =I12 -> 0 | C38: =J12 -> 0
A39: =A13 -> 第5波 | B39: =I13 -> 96 | C39: =J13 -> 96
A40: =A14 -> 第6波 | B40: =I14 -> 116 | C40: =J14 -> 116
A41: =A15 -> 第7波 | B41: =I15 -> 144 | C41: =J15 -> 144
A42: =A16 -> 第8波 | B42: =I16 -> 172 | C42: =J16 -> 172
A43: =A17 -> 第9波 | B43: =I17 -> 210 | C43: =J17 -> 210
A44: =A18 -> 第10波 | B44: =I18 -> 246 | C44: =J18 -> 246
A45: =A19 -> 第11波 | B45: =I19 -> 306 | C45: =J19 -> 306
A46: =A20 -> 第12波 | B46: =I20 -> 342 | C46: =J20 -> 342
... A50: =A24 -> 第16波 | B50: =I24 -> 0 | C50: =J24 -> 0
...

Sheet 全局设置
A1: 全局设置与模拟情景 | B1: 全局设置与模拟情景 | C1: 全局设置与模拟情景 | D1: 全局设置与模拟情景 | E1: 全局设置与模拟情景 | F1: 全局设置与模拟情景
A2: 蓝色项目会影响整本工作簿的自动计算；灰色项目来自当前游戏权威配置。 | B2: 蓝色项目会影响整本工作簿的自动计算；灰色项目来自当前游戏权威配置。 | C2: 蓝色项目会影响整本工作簿的自动计算；灰色项目来自当前游戏权威配置。 | D2: 蓝色项目会影响整本工作簿的自动计算；灰色项目来自当前游戏权威配置。 | E2: 蓝色项目会影响整本工作簿的自动计算；灰色项目来自当前游戏权威配置。 | F2: 蓝色项目会影响整本工作簿的自动计算；灰色项目来自当前游戏权威配置。
A4: 模拟参数 | B4: 当前值
A5: 玩家人数 | B5: 1
A6: 每名额外玩家敌人数增幅 | B6: 0.25
A7: 预计击杀率 | B7: 1
A8: 总日数 | B8: 4
A9: 每日日内波次 | B9: 4
A10: 每波可用敌人槽位 | B10: 18
A11: Boss 接续于 | B11: 第16波之后
A13: 每日息壤情景倍率（命运双倍日设为 2） | B13: 每日息壤情景倍率（命运双倍日设为 2） | C13: 每日息壤情景倍率（命运双倍日设为 2） | D13: 每日息壤情景倍率（命运双倍日设为 2） | E13: 每日息壤情景倍率（命运双倍日设为 2） | F13: 每日息壤情景倍率（命运双倍日设为 2）
B14: 倍率 | C14: 1 | D14: 1 | E14: 1 | F14: 1
B15: 对应日 | C15: 第1日 | D15: 第2日 | E15: 第3日 | F15: 第4日
A17: 设计完整度 | B17: 设计完整度 | C17: 设计完整度 | D17: 设计完整度 | E17: 设计完整度 | F17: 设计完整度
A18: 可回读波次 | B18: =COUNTIF(总览!$E$9:$E$24,"可回读") -> 11
A19: 总体状态 | B19: =IF(AND(B18=16,COUNTIF(敌人目录!AA6:AA54,"可回读")=49),"全部配置已就绪","仍有待设计或错误") -> 仍有待设计或错误
A20: 敌人目录签名 | B20: b1fe8380d773e1597266e16f821f218f409f50807d0f37e8e2cf139bc0c16be8
A21: 回读契约 | B21: tower_defense_formal / schema v2
A23: 注意：玩家人数、击杀率和每日倍率只用于平衡预览；正式回读会写入敌人固定数值、固定掉落与波次组成，不再产生波次级息壤覆盖。 | B23: 注意：玩家人数、击杀率和每日倍率只用于平衡预览；正式回读会写入敌人固定数值、固定掉落与波次组成，不再产生波次级息壤覆盖。 | C23: 注意：玩家人数、击杀率和每日倍率只用于平衡预览；正式回读会写入敌人固定数值、固定掉落与波次组成，不再产生波次级息壤覆盖。 | D23: 注意：玩家人数、击杀率和每日倍率只用于平衡预览；正式回读会写入敌人固定数值、固定掉落与波次组成，不再产生波次级息壤覆盖。 | E23: 注意：玩家人数、击杀率和每日倍率只用于平衡预览；正式回读会写入敌人固定数值、固定掉落与波次组成，不再产生波次级息壤覆盖。 | F23: 注意：玩家人数、击杀率和每日倍率只用于平衡预览；正式回读会写入敌人固定数值、固定掉落与波次组成，不再产生波次级息壤覆盖。

Sheet 第1日
A2: 第 1 波｜第 1 日·1/4｜白昼｜当前正式配置 | B2: 第 1 波｜第 1 日·1/4｜白昼｜当前正式配置 | C2: 第 1 波｜第 1 日·1/4｜白昼｜当前正式配置 | D2: 第 1 波｜第 1 日·1/4｜白昼｜当前正式配置 | E2: 第 1 波｜第 1 日·1/4｜白昼｜当前正式配置 | F2: 第 1 波｜第 1 日·1/4｜白昼｜当前正式配置 | G2: 第 1 波｜第 1 日·1/4｜白昼｜当前正式配置 | H2: 第 1 波｜第 1 日·1/4｜白昼｜当前正式配置 | I2: 第 1 波｜第 1 日·1/4｜白昼｜当前正式配置
A3: 波次名称 | B3: 第1波 林地试探 | C3: 第1波 林地试探 | D3: 出生间隔(s) | E3: 0.2 | F3: 每Tick | G3: 1 | H3: 存活上限 | I3: 300
A4: 出生点 | B4: 点1·开启 | C4: 点2·开启 | D4: 点3·开启 | E4: 点4·开启 | F4: 点5·关闭 | G4: 点6·关闭 | H4: 波次校验 | I4: =IF(COUNTA(B7:B24)=0,"待设计",IF(COUNTIF(I7:I24,"可回读")=COUNTA(B7:B24),"可回读","需修正")) -> 可回读
A5: 仅编辑蓝色列。敌人数值、固定息壤与掉落统一在“敌人目录”维护；本页按实际数量逐项精确结算息壤。 | B5: 仅编辑蓝色列。敌人数值、固定息壤与掉落统一在“敌人目录”维护；本页按实际数量逐项精确结算息壤。 | C5: 仅编辑蓝色列。敌人数值、固定息壤与掉落统一在“敌人目录”维护；本页按实际数量逐项精确结算息壤。 | D5: 仅编辑蓝色列。敌人数值、固定息壤与掉落统一在“敌人目录”维护；本页按实际数量逐项精确结算息壤。 | E5: 仅编辑蓝色列。敌人数值、固定息壤与掉落统一在“敌人目录”维护；本页按实际数量逐项精确结算息壤。 | F5: 仅编辑蓝色列。敌人数值、固定息壤与掉落统一在“敌人目录”维护；本页按实际数量逐项精确结算息壤。 | G5: 仅编辑蓝色列。敌人数值、固定息壤与掉落统一在“敌人目录”维护；本页按实际数量逐项精确结算息壤。 | H5: 仅编辑蓝色列。敌人数值、固定息壤与掉落统一在“敌人目录”维护；本页按实际数量逐项精确结算息壤。 | I5: 仅编辑蓝色列。敌人数值、固定息壤与掉落统一在“敌人目录”维护；本页按实际数量逐项精确结算息壤。
A6: 槽位 | B6: 敌人（下拉选择） | C6: 基础数量 | D6: 实际数量 | E6: 息壤/击杀 | F6: 本项最大息壤/玩家 | G6: 本项情景息壤/玩家 | H6: 本项情景息壤/队伍 | I6: 校验
A7: 1 | B7: 史莱姆 | C7: 1300 | D7: =IF(OR(B7="",C7=""),"",ROUNDUP(C7*(1+(全局设置!$B$5-1)*全局设置!$B$6),0)) -> 1300 | E7: =IFERROR(VLOOKUP(B7,敌人目录!$A$6:$AD$54,13,FALSE),"") -> 1 | F7: =IF(D7="","",D7*E7) -> 1300 | G7: =IF(F7="","",F7*全局设置!$B$7*全局设置!$C$14) -> 1300 | H7: =IF(G7="","",G7*全局设置!$B$5) -> 1300 | I7: =IF(AND(B7="",C7=""),"",IF(B7="","缺少敌人",IF(C7="","缺少数量",IF(OR(C7<1,C7>9999,C7<>INT(C7)),"数量无效",IF(COUNTIF($B$7:$B$24,B7)>1,"重复敌人",IFERROR(IF(VLOOKUP(B7,敌人目录!$A$6:$AD$54,27,FALSE)="可回读","可回读","敌人参数错误"),"敌人不存在")))))) -> 可回读
A8: 2 | B8: 火焰史莱姆 | C8: 400 | D8: =IF(OR(B8="",C8=""),"",ROUNDUP(C8*(1+(全局设置!$B$5-1)*全局设置!$B$6),0)) -> 400 | E8: =IFERROR(VLOOKUP(B8,敌人目录!$A$6:$AD$54,13,FALSE),"") -> 1 | F8: =IF(D8="","",D8*E8) -> 400 | G8: =IF(F8="","",F8*全局设置!$B$7*全局设置!$C$14) -> 400 | H8: =IF(G8="","",G8*全局设置!$B$5) -> 400 | I8: =IF(AND(B8="",C8=""),"",IF(B8="","缺少敌人",IF(C8="","缺少数量",IF(OR(C8<1,C8>9999,C8<>INT(C8)),"数量无效",IF(COUNTIF($B$7:$B$24,B8)>1,"重复敌人",IFERROR(IF(VLOOKUP(B8,敌人目录!$A$6:$AD$54,27,FALSE)="可回读","可回读","敌人参数错误"),"敌人不存在")))))) -> 可回读
A9: 3 | B9: 普通原石虫 | C9: 500 | D9: =IF(OR(B9="",C9=""),"",ROUNDUP(C9*(1+(全局设置!$B$5-1)*全局设置!$B$6),0)) -> 500 | E9: =IFERROR(VLOOKUP(B9,敌人目录!$A$6:$AD$54,13,FALSE),"") -> 1 | F9: =IF(D9="","",D9*E9) -> 500 | G9: =IF(F9="","",F9*全局设置!$B$7*全局设置!$C$14) -> 500 | H9: =IF(G9="","",G9*全局设置!$B$5) -> 500 | I9: =IF(AND(B9="",C9=""),"",IF(B9="","缺少敌人",IF(C9="","缺少数量",IF(OR(C9<1,C9>9999,C9<>INT(C9)),"数量无效",IF(COUNTIF($B$7:$B$24,B9)>1,"重复敌人",IFERROR(IF(VLOOKUP(B9,敌人目录!$A$6:$AD$54,27,FALSE)="可回读","可回读","敌人参数错误"),"敌人不存在")))))) -> 可回读
A10: 4 | B10: 迅捷原石虫 | C10: 300 | D10: =IF(OR(B10="",C10=""),"",ROUNDUP(C10*(1+(全局设置!$B$5-1)*全局设置!$B$6),0)) -> 300 | E10: =IFERROR(VLOOKUP(B10,敌人目录!$A$6:$AD$54,13,FALSE),"") -> 1 | F10: =IF(D10="","",D10*E10) -> 300 | G10: =IF(F10="","",F10*全局设置!$B$7*全局设置!$C$14) -> 300 | H10: =IF(G10="","",G10*全局设置!$B$5) -> 300 | I10: =IF(AND(B10="",C10=""),"",IF(B10="","缺少敌人",IF(C10="","缺少数量",IF(OR(C10<1,C10>9999,C10<>INT(C10)),"数量无效",IF(COUNTIF($B$7:$B$24,B10)>1,"重复敌人",IFERROR(IF(VLOOKUP(B10,敌人目录!$A$6:$AD$54,27,FALSE)="可回读","可回读","敌人参数错误"),"敌人不存在")))))) -> 可回读
A11: 5 | D11: =IF(OR(B11="",C11=""),"",ROUNDUP(C11*(1+(全局设置!$B$5-1)*全局设置!$B$6),0)) | E11: =IFERROR(VLOOKUP(B11,敌人目录!$A$6:$AD$54,13,FALSE),"") | F11: =IF(D11="","",D11*E11) | G11: =IF(F11="","",F11*全局设置!$B$7*全局设置!$C$14) | H11: =IF(G11="","",G11*全局设置!$B$5) | I11: =IF(AND(B11="",C11=""),"",IF(B11="","缺少敌人",IF(C11="","缺少数量",IF(OR(C11<1,C11>9999,C11<>INT(C11)),"数量无效",IF(COUNTIF($B$7:$B$24,B11)>1,"重复敌人",IFERROR(IF(VLOOKUP(B11,敌人目录!$A$6:$AD$54,27,FALSE)="可回读","可回读","敌人参数错误"),"敌人不存在"))))))
A12: 6 | D12: =IF(OR(B12="",C12=""),"",ROUNDUP(C12*(1+(全局设置!$B$5-1)*全局设置!$B$6),0)) | E12: =IFERROR(VLOOKUP(B12,敌人目录!$A$6:$AD$54,13,FALSE),"") | F12: =IF(D12="","",D12*E12) | G12: =IF(F12="","",F12*全局设置!$B$7*全局设置!$C$14) | H12: =IF(G12="","",G12*全局设置!$B$5) | I12: =IF(AND(B12="",C12=""),"",IF(B12="","缺少敌人",IF(C12="","缺少数量",IF(OR(C12<1,C12>9999,C12<>INT(C12)),"数量无效",IF(COUNTIF($B$7:$B$24,B12)>1,"重复敌人",IFERROR(IF(VLOOKUP(B12,敌人目录!$A$6:$AD$54,27,FALSE)="可回读","可回读","敌人参数错误"),"敌人不存在"))))))
A13: 7 | D13: =IF(OR(B13="",C13=""),"",ROUNDUP(C13*(1+(全局设置!$B$5-1)*全局设置!$B$6),0)) | E13: =IFERROR(VLOOKUP(B13,敌人目录!$A$6:$AD$54,13,FALSE),"") | F13: =IF(D13="","",D13*E13) | G13: =IF(F13="","",F13*全局设置!$B$7*全局设置!$C$14) | H13: =IF(G13="","",G13*全局设置!$B$5) | I13: =IF(AND(B13="",C13=""),"",IF(B13="","缺少敌人",IF(C13="","缺少数量",IF(OR(C13<1,C13>9999,C13<>INT(C13)),"数量无效",IF(COUNTIF($B$7:$B$24,B13)>1,"重复敌人",IFERROR(IF(VLOOKUP(B13,敌人目录!$A$6:$AD$54,27,FALSE)="可回读","可回读","敌人参数错误"),"敌人不存在"))))))
A14: 8 | D14: =IF(OR(B14="",C14=""),"",ROUNDUP(C14*(1+(全局设置!$B$5-1)*全局设置!$B$6),0)) | E14: =IFERROR(VLOOKUP(B14,敌人目录!$A$6:$AD$54,13,FALSE),"") | F14: =IF(D14="","",D14*E14) | G14: =IF(F14="","",F14*全局设置!$B$7*全局设置!$C$14) | H14: =IF(G14="","",G14*全局设置!$B$5) | I14: =IF(AND(B14="",C14=""),"",IF(B14="","缺少敌人",IF(C14="","缺少数量",IF(OR(C14<1,C14>9999,C14<>INT(C14)),"数量无效",IF(COUNTIF($B$7:$B$24,B14)>1,"重复敌人",IFERROR(IF(VLOOKUP(B14,敌人目录!$A$6:$AD$54,27,FALSE)="可回读","可回读","敌人参数错误"),"敌人不存在"))))))
A15: 9 | D15: =IF(OR(B15="",C15=""),"",ROUNDUP(C15*(1+(全局设置!$B$5-1)*全局设置!$B$6),0)) | E15: =IFERROR(VLOOKUP(B15,敌人目录!$A$6:$AD$54,13,FALSE),"") | F15: =IF(D15="","",D15*E15) | G15: =IF(F15="","",F15*全局设置!$B$7*全局设置!$C$14) | H15: =IF(G15="","",G15*全局设置!$B$5) | I15: =IF(AND(B15="",C15=""),"",IF(B15="","缺少敌人",IF(C15="","缺少数量",IF(OR(C15<1,C15>9999,C15<>INT(C15)),"数量无效",IF(COUNTIF($B$7:$B$24,B15)>1,"重复敌人",IFERROR(IF(VLOOKUP(B15,敌人目录!$A$6:$AD$54,27,FALSE)="可回读","可回读","敌人参数错误"),"敌人不存在"))))))
A16: 10 | D16: =IF(OR(B16="",C16=""),"",ROUNDUP(C16*(1+(全局设置!$B$5-1)*全局设置!$B$6),0)) | E16: =IFERROR(VLOOKUP(B16,敌人目录!$A$6:$AD$54,13,FALSE),"") | F16: =IF(D16="","",D16*E16) | G16: =IF(F16="","",F16*全局设置!$B$7*全局设置!$C$14) | H16: =IF(G16="","",G16*全局设置!$B$5) | I16: =IF(AND(B16="",C16=""),"",IF(B16="","缺少敌人",IF(C16="","缺少数量",IF(OR(C16<1,C16>9999,C16<>INT(C16)),"数量无效",IF(COUNTIF($B$7:$B$24,B16)>1,"重复敌人",IFERROR(IF(VLOOKUP(B16,敌人目录!$A$6:$AD$54,27,FALSE)="可回读","可回读","敌人参数错误"),"敌人不存在"))))))
A17: 11 | D17: =IF(OR(B17="",C17=""),"",ROUNDUP(C17*(1+(全局设置!$B$5-1)*全局设置!$B$6),0)) | E17: =IFERROR(VLOOKUP(B17,敌人目录!$A$6:$AD$54,13,FALSE),"") | F17: =IF(D17="","",D17*E17) | G17: =IF(F17="","",F17*全局设置!$B$7*全局设置!$C$14) | H17: =IF(G17="","",G17*全局设置!$B$5) | I17: =IF(AND(B17="",C17=""),"",IF(B17="","缺少敌人",IF(C17="","缺少数量",IF(OR(C17<1,C17>9999,C17<>INT(C17)),"数量无效",IF(COUNTIF($B$7:$B$24,B17)>1,"重复敌人",IFERROR(IF(VLOOKUP(B17,敌人目录!$A$6:$AD$54,27,FALSE)="可回读","可回读","敌人参数错误"),"敌人不存在"))))))
A18: 12 | D18: =IF(OR(B18="",C18=""),"",ROUNDUP(C18*(1+(全局设置!$B$5-1)*全局设置!$B$6),0)) | E18: =IFERROR(VLOOKUP(B18,敌人目录!$A$6:$AD$54,13,FALSE),"") | F18: =IF(D18="","",D18*E18) | G18: =IF(F18="","",F18*全局设置!$B$7*全局设置!$C$14) | H18: =IF(G18="","",G18*全局设置!$B$5) | I18: =IF(AND(B18="",C18=""),"",IF(B18="","缺少敌人",IF(C18="","缺少数量",IF(OR(C18<1,C18>9999,C18<>INT(C18)),"数量无效",IF(COUNTIF($B$7:$B$24,B18)>1,"重复敌人",IFERROR(IF(VLOOKUP(B18,敌人目录!$A$6:$AD$54,27,FALSE)="可回读","可回读","敌人参数错误"),"敌人不存在"))))))
A19: 13 | D19: =IF(OR(B19="",C19=""),"",ROUNDUP(C19*(1+(全局设置!$B$5-1)*全局设置!$B$6),0)) | E19: =IFERROR(VLOOKUP(B19,敌人目录!$A$6:$AD$54,13,FALSE),"") | F19: =IF(D19="","",D19*E19) | G19: =IF(F19="","",F19*全局设置!$B$7*全局设置!$C$14) | H19: =IF(G19="","",G19*全局设置!$B$5) | I19: =IF(AND(B19="",C19=""),"",IF(B19="","缺少敌人",IF(C19="","缺少数量",IF(OR(C19<1,C19>9999,C19<>INT(C19)),"数量无效",IF(COUNTIF($B$7:$B$24,B19)>1,"重复敌人",IFERROR(IF(VLOOKUP(B19,敌人目录!$A$6:$AD$54,27,FALSE)="可回读","可回读","敌人参数错误"),"敌人不存在"))))))
A20: 14 | D20: =IF(OR(B20="",C20=""),"",ROUNDUP(C20*(1+(全局设置!$B$5-1)*全局设置!$B$6),0)) | E20: =IFERROR(VLOOKUP(B20,敌人目录!$A$6:$AD$54,13,FALSE),"") | F20: =IF(D20="","",D20*E20) | G20: =IF(F20="","",F20*全局设置!$B$7*全局设置!$C$14) | H20: =IF(G20="","",G20*全局设置!$B$5) | I20: =IF(AND(B20="",C20=""),"",IF(B20="","缺少敌人",IF(C20="","缺少数量",IF(OR(C20<1,C20>9999,C20<>INT(C20)),"数量无效",IF(COUNTIF($B$7:$B$24,B20)>1,"重复敌人",IFERROR(IF(VLOOKUP(B20,敌人目录!$A$6:$AD$54,27,FALSE)="可回读","可回读","敌人参数错误"),"敌人不存在"))))))
A21: 15 | D21: =IF(OR(B21="",C21=""),"",ROUNDUP(C21*(1+(全局设置!$B$5-1)*全局设置!$B$6),0)) | E21: =IFERROR(VLOOKUP(B21,敌人目录!$A$6:$AD$54,13,FALSE),"") | F21: =IF(D21="","",D21*E21) | G21: =IF(F21="","",F21*全局设置!$B$7*全局设置!$C$14) | H21: =IF(G21="","",G21*全局设置!$B$5) | I21: =IF(AND(B21="",C21=""),"",IF(B21="","缺少敌人",IF(C21="","缺少数量",IF(OR(C21<1,C21>9999,C21<>INT(C21)),"数量无效",IF(COUNTIF($B$7:$B$24,B21)>1,"重复敌人",IFERROR(IF(VLOOKUP(B21,敌人目录!$A$6:$AD$54,27,FALSE)="可回读","可回读","敌人参数错误"),"敌人不存在"))))))
A22: 16 | D22: =IF(OR(B22="",C22=""),"",ROUNDUP(C22*(1+(全局设置!$B$5-1)*全局设置!$B$6),0)) | E22: =IFERROR(VLOOKUP(B22,敌人目录!$A$6:$AD$54,13,FALSE),"") | F22: =IF(D22="","",D22*E22) | G22: =IF(F22="","",F22*全局设置!$B$7*全局设置!$C$14) | H22: =IF(G22="","",G22*全局设置!$B$5) | I22: =IF(AND(B22="",C22=""),"",IF(B22="","缺少敌人",IF(C22="","缺少数量",IF(OR(C22<1,C22>9999,C22<>INT(C22)),"数量无效",IF(COUNTIF($B$7:$B$24,B22)>1,"重复敌人",IFERROR(IF(VLOOKUP(B22,敌人目录!$A$6:$AD$54,27,FALSE)="可回读","可回读","敌人参数错误"),"敌人不存在"))))))
... A24: 18 | D24: =IF(OR(B24="",C24=""),"",ROUNDUP(C24*(1+(全局设置!$B$5-1)*全局设置!$B$6),0)) | E24: =IFERROR(VLOOKUP(B24,敌人目录!$A$6:$AD$54,13,FALSE),"") | F24: =IF(D24="","",D24*E24) | G24: =IF(F24="","",F24*全局设置!$B$7*全局设置!$C$14) | H24: =IF(G24="","",G24*全局设置!$B$5) | I24: =IF(AND(B24="",C24=""),"",IF(B24="","缺少敌人",IF(C24="","缺少数量",IF(OR(C24<1,C24>9999,C24<>INT(C24)),"数量无效",IF(COUNTIF($B$7:$B$24,B24)>1,"重复敌人",IFERROR(IF(VLOOKUP(B24,敌人目录!$A$6:$AD$54,27,FALSE)="可回读","可回读","敌人参数错误"),"敌人不存在"))))))
A26: 基础总数 | B26: =SUM(C7:C24) -> 2500 | C26: 实际总数 | D26: =SUM(D7:D24) -> 2500 | E26: 最大息壤/玩家 | F26: =SUM(F7:F24) -> 2500 | G26: 情景息壤/玩家 | H26: =SUM(G7:G24) -> 2500
A27: 情景息壤/队伍 | B27: =SUM(H7:H24) -> 2500 | C27: 情景收益 = 最大息壤 × 全局击杀率 × 第1日倍率；队伍值再乘模拟玩家数。 | D27: 情景收益 = 最大息壤 × 全局击杀率 × 第1日倍率；队伍值再乘模拟玩家数。 | E27: 情景收益 = 最大息壤 × 全局击杀率 × 第1日倍率；队伍值再乘模拟玩家数。 | F27: 情景收益 = 最大息壤 × 全局击杀率 × 第1日倍率；队伍值再乘模拟玩家数。 | G27: 情景收益 = 最大息壤 × 全局击杀率 × 第1日倍率；队伍值再乘模拟玩家数。 | H27: 情景收益 = 最大息壤 × 全局击杀率 × 第1日倍率；队伍值再乘模拟玩家数。 | I27: 情景收益 = 最大息壤 × 全局击杀率 × 第1日倍率；队伍值再乘模拟玩家数。
A31: 第 2 波｜第 1 日·2/4｜白昼｜当前正式配置 | B31: 第 2 波｜第 1 日·2/4｜白昼｜当前正式配置 | C31: 第 2 波｜第 1 日·2/4｜白昼｜当前正式配置 | D31: 第 2 波｜第 1 日·2/4｜白昼｜当前正式配置 | E31: 第 2 波｜第 1 日·2/4｜白昼｜当前正式配置 | F31: 第 2 波｜第 1 日·2/4｜白昼｜当前正式配置 | G31: 第 2 波｜第 1 日·2/4｜白昼｜当前正式配置 | H31: 第 2 波｜第 1 日·2/4｜白昼｜当前正式配置 | I31: 第 2 波｜第 1 日·2/4｜白昼｜当前正式配置
A32: 波次名称 | B32: 第2波 迅影与硬壳 | C32: 第2波 迅影与硬壳 | D32: 出生间隔(s) | E32: 0.1 | F32: 每Tick | G32: 1 | H32: 存活上限 | I32: 300
A33: 出生点 | B33: 点1·开启 | C33: 点2·开启 | D33: 点3·开启 | E33: 点4·开启 | F33: 点5·关闭 | G33: 点6·关闭 | H33: 波次校验 | I33: =IF(COUNTA(B36:B53)=0,"待设计",IF(COUNTIF(I36:I53,"可回读")=COUNTA(B36:B53),"可回读","需修正")) -> 可回读
A34: 仅编辑蓝色列。敌人数值、固定息壤与掉落统一在“敌人目录”维护；本页按实际数量逐项精确结算息壤。 | B34: 仅编辑蓝色列。敌人数值、固定息壤与掉落统一在“敌人目录”维护；本页按实际数量逐项精确结算息壤。 | C34: 仅编辑蓝色列。敌人数值、固定息壤与掉落统一在“敌人目录”维护；本页按实际数量逐项精确结算息壤。 | D34: 仅编辑蓝色列。敌人数值、固定息壤与掉落统一在“敌人目录”维护；本页按实际数量逐项精确结算息壤。 | E34: 仅编辑蓝色列。敌人数值、固定息壤与掉落统一在“敌人目录”维护；本页按实际数量逐项精确结算息壤。 | F34: 仅编辑蓝色列。敌人数值、固定息壤与掉落统一在“敌人目录”维护；本页按实际数量逐项精确结算息壤。 | G34: 仅编辑蓝色列。敌人数值、固定息壤与掉落统一在“敌人目录”维护；本页按实际数量逐项精确结算息壤。 | H34: 仅编辑蓝色列。敌人数值、固定息壤与掉落统一在“敌人目录”维护；本页按实际数量逐项精确结算息壤。 | I34: 仅编辑蓝色列。敌人数值、固定息壤与掉落统一在“敌人目录”维护；本页按实际数量逐项精确结算息壤。
A35: 槽位 | B35: 敌人（下拉选择） | C35: 基础数量 | D35: 实际数量 | E35: 息壤/击杀 | F35: 本项最大息壤/玩家 | G35: 本项情景息壤/玩家 | H35: 本项情景息壤/队伍 | I35: 校验
A36: 1 | B36: 史莱姆 | C36: 2000 | D36: =IF(OR(B36="",C36=""),"",ROUNDUP(C36*(1+(全局设置!$B$5-1)*全局设置!$B$6),0)) -> 2000 | E36: =IFERROR(VLOOKUP(B36,敌人目录!$A$6:$AD$54,13,FALSE),"") -> 1 | F36: =IF(D36="","",D36*E36) -> 2000 | G36: =IF(F36="","",F36*全局设置!$B$7*全局设置!$C$14) -> 2000 | H36: =IF(G36="","",G36*全局设置!$B$5) -> 2000 | I36: =IF(AND(B36="",C36=""),"",IF(B36="","缺少敌人",IF(C36="","缺少数量",IF(OR(C36<1,C36>9999,C36<>INT(C36)),"数量无效",IF(COUNTIF($B$36:$B$53,B36)>1,"重复敌人",IFERROR(IF(VLOOKUP(B36,敌人目录!$A$6:$AD$54,27,FALSE)="可回读","可回读","敌人参数错误"),"敌人不存在")))))) -> 可回读
A37: 2 | B37: 火焰史莱姆 | C37: 400 | D37: =IF(OR(B37="",C37=""),"",ROUNDUP(C37*(1+(全局设置!$B$5-1)*全局设置!$B$6),0)) -> 400 | E37: =IFERROR(VLOOKUP(B37,敌人目录!$A$6:$AD$54,13,FALSE),"") -> 1 | F37: =IF(D37="","",D37*E37) -> 400 | G37: =IF(F37="","",F37*全局设置!$B$7*全局设置!$C$14) -> 400 | H37: =IF(G37="","",G37*全局设置!$B$5) -> 400 | I37: =IF(AND(B37="",C37=""),"",IF(B37="","缺少敌人",IF(C37="","缺少数量",IF(OR(C37<1,C37>9999,C37<>INT(C37)),"数量无效",IF(COUNTIF($B$36:$B$53,B37)>1,"重复敌人",IFERROR(IF(VLOOKUP(B37,敌人目录!$A$6:$AD$54,27,FALSE)="可回读","可回读","敌人参数错误"),"敌人不存在")))))) -> 可回读
A38: 3 | B38: 普通原石虫 | C38: 500 | D38: =IF(OR(B38="",C38=""),"",ROUNDUP(C38*(1+(全局设置!$B$5-1)*全局设置!$B$6),0)) -> 500 | E38: =IFERROR(VLOOKUP(B38,敌人目录!$A$6:$AD$54,13,FALSE),"") -> 1 | F38: =IF(D38="","",D38*E38) -> 500 | G38: =IF(F38="","",F38*全局设置!$B$7*全局设置!$C$14) -> 500 | H38: =IF(G38="","",G38*全局设置!$B$5) -> 500 | I38: =IF(AND(B38="",C38=""),"",IF(B38="","缺少敌人",IF(C38="","缺少数量",IF(OR(C38<1,C38>9999,C38<>INT(C38)),"数量无效",IF(COUNTIF($B$36:$B$53,B38)>1,"重复敌人",IFERROR(IF(VLOOKUP(B38,敌人目录!$A$6:$AD$54,27,FALSE)="可回读","可回读","敌人参数错误"),"敌人不存在")))))) -> 可回读
A39: 4 | B39: 迅捷原石虫 | C39: 300 | D39: =IF(OR(B39="",C39=""),"",ROUNDUP(C39*(1+(全局设置!$B$5-1)*全局设置!$B$6),0)) -> 300 | E39: =IFERROR(VLOOKUP(B39,敌人目录!$A$6:$AD$54,13,FALSE),"") -> 1 | F39: =IF(D39="","",D39*E39) -> 300 | G39: =IF(F39="","",F39*全局设置!$B$7*全局设置!$C$14) -> 300 | H39: =IF(G39="","",G39*全局设置!$B$5) -> 300 | I39: =IF(AND(B39="",C39=""),"",IF(B39="","缺少敌人",IF(C39="","缺少数量",IF(OR(C39<1,C39>9999,C39<>INT(C39)),"数量无效",IF(COUNTIF($B$36:$B$53,B39)>1,"重复敌人",IFERROR(IF(VLOOKUP(B39,敌人目录!$A$6:$AD$54,27,FALSE)="可回读","可回读","敌人参数错误"),"敌人不存在")))))) -> 可回读
A40: 5 | B40: 硬壳原石虫 | C40: 200 | D40: =IF(OR(B40="",C40=""),"",ROUNDUP(C40*(1+(全局设置!$B$5-1)*全局设置!$B$6),0)) -> 200 | E40: =IFERROR(VLOOKUP(B40,敌人目录!$A$6:$AD$54,13,FALSE),"") -> 2 | F40: =IF(D40="","",D40*E40) -> 400 | G40: =IF(F40="","",F40*全局设置!$B$7*全局设置!$C$14) -> 400 | H40: =IF(G40="","",G40*全局设置!$B$5) -> 400 | I40: =IF(AND(B40="",C40=""),"",IF(B40="","缺少敌人",IF(C40="","缺少数量",IF(OR(C40<1,C40>9999,C40<>INT(C40)),"数量无效",IF(COUNTIF($B$36:$B$53,B40)>1,"重复敌人",IFERROR(IF(VLOOKUP(B40,敌人目录!$A$6:$AD$54,27,FALSE)="可回读","可回读","敌人参数错误"),"敌人不存在")))))) -> 可回读
A41: 6 | B41: 火焰弹原石虫 | C41: 50 | D41: =IF(OR(B41="",C41=""),"",ROUNDUP(C41*(1+(全局设置!$B$5-1)*全局设置!$B$6),0)) -> 50 | E41: =IFERROR(VLOOKUP(B41,敌人目录!$A$6:$AD$54,13,FALSE),"") -> 1 | F41: =IF(D41="","",D41*E41) -> 50 | G41: =IF(F41="","",F41*全局设置!$B$7*全局设置!$C$14) -> 50 | H41: =IF(G41="","",G41*全局设置!$B$5) -> 50 | I41: =IF(AND(B41="",C41=""),"",IF(B41="","缺少敌人",IF(C41="","缺少数量",IF(OR(C41<1,C41>9999,C41<>INT(C41)),"数量无效",IF(COUNTIF($B$36:$B$53,B41)>1,"重复敌人",IFERROR(IF(VLOOKUP(B41,敌人目录!$A$6:$AD$54,27,FALSE)="可回读","可回读","敌人参数错误"),"敌人不存在")))))) -> 可回读
A42: 7 | B42: 寒冰史莱姆 | C42: 400 | D42: =IF(OR(B42="",C42=""),"",ROUNDUP(C42*(1+(全局设置!$B$5-1)*全局设置!$B$6),0)) -> 400 | E42: =IFERROR(VLOOKUP(B42,敌人目录!$A$6:$AD$54,13,FALSE),"") -> 1 | F42: =IF(D42="","",D42*E42) -> 400 | G42: =IF(F42="","",F42*全局设置!$B$7*全局设置!$C$14) -> 400 | H42: =IF(G42="","",G42*全局设置!$B$5) -> 400 | I42: =IF(AND(B42="",C42=""),"",IF(B42="","缺少敌人",IF(C42="","缺少数量",IF(OR(C42<1,C42>9999,C42<>INT(C42)),"数量无效",IF(COUNTIF($B$36:$B$53,B42)>1,"重复敌人",IFERROR(IF(VLOOKUP(B42,敌人目录!$A$6:$AD$54,27,FALSE)="可回读","可回读","敌人参数错误"),"敌人不存在")))))) -> 可回读
A43: 8 | D43: =IF(OR(B43="",C43=""),"",ROUNDUP(C43*(1+(全局设置!$B$5-1)*全局设置!$B$6),0)) | E43: =IFERROR(VLOOKUP(B43,敌人目录!$A$6:$AD$54,13,FALSE),"") | F43: =IF(D43="","",D43*E43) | G43: =IF(F43="","",F43*全局设置!$B$7*全局设置!$C$14) | H43: =IF(G43="","",G43*全局设置!$B$5) | I43: =IF(AND(B43="",C43=""),"",IF(B43="","缺少敌人",IF(C43="","缺少数量",IF(OR(C43<1,C43>9999,C43<>INT(C43)),"数量无效",IF(COUNTIF($B$36:$B$53,B43)>1,"重复敌人",IFERROR(IF(VLOOKUP(B43,敌人目录!$A$6:$AD$54,27,FALSE)="可回读","可回读","敌人参数错误"),"敌人不存在"))))))
A44: 9 | D44: =IF(OR(B44="",C44=""),"",ROUNDUP(C44*(1+(全局设置!$B$5-1)*全局设置!$B$6),0)) | E44: =IFERROR(VLOOKUP(B44,敌人目录!$A$6:$AD$54,13,FALSE),"") | F44: =IF(D44="","",D44*E44) | G44: =IF(F44="","",F44*全局设置!$B$7*全局设置!$C$14) | H44: =IF(G44="","",G44*全局设置!$B$5) | I44: =IF(AND(B44="",C44=""),"",IF(B44="","缺少敌人",IF(C44="","缺少数量",IF(OR(C44<1,C44>9999,C44<>INT(C44)),"数量无效",IF(COUNTIF($B$36:$B$53,B44)>1,"重复敌人",IFERROR(IF(VLOOKUP(B44,敌人目录!$A$6:$AD$54,27,FALSE)="可回读","可回读","敌人参数错误"),"敌人不存在"))))))
A45: 10 | D45: =IF(OR(B45="",C45=""),"",ROUNDUP(C45*(1+(全局设置!$B$5-1)*全局设置!$B$6),0)) | E45: =IFERROR(VLOOKUP(B45,敌人目录!$A$6:$AD$54,13,FALSE),"") | F45: =IF(D45="","",D45*E45) | G45: =IF(F45="","",F45*全局设置!$B$7*全局设置!$C$14) | H45: =IF(G45="","",G45*全局设置!$B$5) | I45: =IF(AND(B45="",C45=""),"",IF(B45="","缺少敌人",IF(C45="","缺少数量",IF(OR(C45<1,C45>9999,C45<>INT(C45)),"数量无效",IF(COUNTIF($B$36:$B$53,B45)>1,"重复敌人",IFERROR(IF(VLOOKUP(B45,敌人目录!$A$6:$AD$54,27,FALSE)="可回读","可回读","敌人参数错误"),"敌人不存在"))))))
A46: 11 | D46: =IF(OR(B46="",C46=""),"",ROUNDUP(C46*(1+(全局设置!$B$5-1)*全局设置!$B$6),0)) | E46: =IFERROR(VLOOKUP(B46,敌人目录!$A$6:$AD$54,13,FALSE),"") | F46: =IF(D46="","",D46*E46) | G46: =IF(F46="","",F46*全局设置!$B$7*全局设置!$C$14) | H46: =IF(G46="","",G46*全局设置!$B$5) | I46: =IF(AND(B46="",C46=""),"",IF(B46="","缺少敌人",IF(C46="","缺少数量",IF(OR(C46<1,C46>9999,C46<>INT(C46)),"数量无效",IF(COUNTIF($B$36:$B$53,B46)>1,"重复敌人",IFERROR(IF(VLOOKUP(B46,敌人目录!$A$6:$AD$54,27,FALSE)="可回读","可回读","敌人参数错误"),"敌人不存在"))))))
...

Sheet 第2日
A2: 第 5 波｜第 2 日·1/4｜白昼｜当前正式配置 | B2: 第 5 波｜第 2 日·1/4｜白昼｜当前正式配置 | C2: 第 5 波｜第 2 日·1/4｜白昼｜当前正式配置 | D2: 第 5 波｜第 2 日·1/4｜白昼｜当前正式配置 | E2: 第 5 波｜第 2 日·1/4｜白昼｜当前正式配置 | F2: 第 5 波｜第 2 日·1/4｜白昼｜当前正式配置 | G2: 第 5 波｜第 2 日·1/4｜白昼｜当前正式配置 | H2: 第 5 波｜第 2 日·1/4｜白昼｜当前正式配置 | I2: 第 5 波｜第 2 日·1/4｜白昼｜当前正式配置
A3: 波次名称 | B3: 第5波 沼泽先遣 | C3: 第5波 沼泽先遣 | D3: 出生间隔(s) | E3: 0.45 | F3: 每Tick | G3: 1 | H3: 存活上限 | I3: 300
A4: 出生点 | B4: 点1·开启 | C4: 点2·开启 | D4: 点3·开启 | E4: 点4·开启 | F4: 点5·开启 | G4: 点6·开启 | H4: 波次校验 | I4: =IF(COUNTA(B7:B24)=0,"待设计",IF(COUNTIF(I7:I24,"可回读")=COUNTA(B7:B24),"可回读","需修正")) -> 可回读
A5: 仅编辑蓝色列。敌人数值、固定息壤与掉落统一在“敌人目录”维护；本页按实际数量逐项精确结算息壤。 | B5: 仅编辑蓝色列。敌人数值、固定息壤与掉落统一在“敌人目录”维护；本页按实际数量逐项精确结算息壤。 | C5: 仅编辑蓝色列。敌人数值、固定息壤与掉落统一在“敌人目录”维护；本页按实际数量逐项精确结算息壤。 | D5: 仅编辑蓝色列。敌人数值、固定息壤与掉落统一在“敌人目录”维护；本页按实际数量逐项精确结算息壤。 | E5: 仅编辑蓝色列。敌人数值、固定息壤与掉落统一在“敌人目录”维护；本页按实际数量逐项精确结算息壤。 | F5: 仅编辑蓝色列。敌人数值、固定息壤与掉落统一在“敌人目录”维护；本页按实际数量逐项精确结算息壤。 | G5: 仅编辑蓝色列。敌人数值、固定息壤与掉落统一在“敌人目录”维护；本页按实际数量逐项精确结算息壤。 | H5: 仅编辑蓝色列。敌人数值、固定息壤与掉落统一在“敌人目录”维护；本页按实际数量逐项精确结算息壤。 | I5: 仅编辑蓝色列。敌人数值、固定息壤与掉落统一在“敌人目录”维护；本页按实际数量逐项精确结算息壤。
A6: 槽位 | B6: 敌人（下拉选择） | C6: 基础数量 | D6: 实际数量 | E6: 息壤/击杀 | F6: 本项最大息壤/玩家 | G6: 本项情景息壤/玩家 | H6: 本项情景息壤/队伍 | I6: 校验
A7: 1 | B7: 普通原石虫 | C7: 28 | D7: =IF(OR(B7="",C7=""),"",ROUNDUP(C7*(1+(全局设置!$B$5-1)*全局设置!$B$6),0)) -> 28 | E7: =IFERROR(VLOOKUP(B7,敌人目录!$A$6:$AD$54,13,FALSE),"") -> 1 | F7: =IF(D7="","",D7*E7) -> 28 | G7: =IF(F7="","",F7*全局设置!$B$7*全局设置!$D$14) -> 28 | H7: =IF(G7="","",G7*全局设置!$B$5) -> 28 | I7: =IF(AND(B7="",C7=""),"",IF(B7="","缺少敌人",IF(C7="","缺少数量",IF(OR(C7<1,C7>9999,C7<>INT(C7)),"数量无效",IF(COUNTIF($B$7:$B$24,B7)>1,"重复敌人",IFERROR(IF(VLOOKUP(B7,敌人目录!$A$6:$AD$54,27,FALSE)="可回读","可回读","敌人参数错误"),"敌人不存在")))))) -> 可回读
A8: 2 | B8: 迅捷原石虫 | C8: 20 | D8: =IF(OR(B8="",C8=""),"",ROUNDUP(C8*(1+(全局设置!$B$5-1)*全局设置!$B$6),0)) -> 20 | E8: =IFERROR(VLOOKUP(B8,敌人目录!$A$6:$AD$54,13,FALSE),"") -> 1 | F8: =IF(D8="","",D8*E8) -> 20 | G8: =IF(F8="","",F8*全局设置!$B$7*全局设置!$D$14) -> 20 | H8: =IF(G8="","",G8*全局设置!$B$5) -> 20 | I8: =IF(AND(B8="",C8=""),"",IF(B8="","缺少敌人",IF(C8="","缺少数量",IF(OR(C8<1,C8>9999,C8<>INT(C8)),"数量无效",IF(COUNTIF($B$7:$B$24,B8)>1,"重复敌人",IFERROR(IF(VLOOKUP(B8,敌人目录!$A$6:$AD$54,27,FALSE)="可回读","可回读","敌人参数错误"),"敌人不存在")))))) -> 可回读
A9: 3 | B9: 硬壳原石虫 | C9: 12 | D9: =IF(OR(B9="",C9=""),"",ROUNDUP(C9*(1+(全局设置!$B$5-1)*全局设置!$B$6),0)) -> 12 | E9: =IFERROR(VLOOKUP(B9,敌人目录!$A$6:$AD$54,13,FALSE),"") -> 2 | F9: =IF(D9="","",D9*E9) -> 24 | G9: =IF(F9="","",F9*全局设置!$B$7*全局设置!$D$14) -> 24 | H9: =IF(G9="","",G9*全局设置!$B$5) -> 24 | I9: =IF(AND(B9="",C9=""),"",IF(B9="","缺少敌人",IF(C9="","缺少数量",IF(OR(C9<1,C9>9999,C9<>INT(C9)),"数量无效",IF(COUNTIF($B$7:$B$24,B9)>1,"重复敌人",IFERROR(IF(VLOOKUP(B9,敌人目录!$A$6:$AD$54,27,FALSE)="可回读","可回读","敌人参数错误"),"敌人不存在")))))) -> 可回读
A10: 4 | B10: 自爆原石虫 | C10: 8 | D10: =IF(OR(B10="",C10=""),"",ROUNDUP(C10*(1+(全局设置!$B$5-1)*全局设置!$B$6),0)) -> 8 | E10: =IFERROR(VLOOKUP(B10,敌人目录!$A$6:$AD$54,13,FALSE),"") -> 1 | F10: =IF(D10="","",D10*E10) -> 8 | G10: =IF(F10="","",F10*全局设置!$B$7*全局设置!$D$14) -> 8 | H10: =IF(G10="","",G10*全局设置!$B$5) -> 8 | I10: =IF(AND(B10="",C10=""),"",IF(B10="","缺少敌人",IF(C10="","缺少数量",IF(OR(C10<1,C10>9999,C10<>INT(C10)),"数量无效",IF(COUNTIF($B$7:$B$24,B10)>1,"重复敌人",IFERROR(IF(VLOOKUP(B10,敌人目录!$A$6:$AD$54,27,FALSE)="可回读","可回读","敌人参数错误"),"敌人不存在")))))) -> 可回读
A11: 5 | B11: 火焰弹原石虫 | C11: 8 | D11: =IF(OR(B11="",C11=""),"",ROUNDUP(C11*(1+(全局设置!$B$5-1)*全局设置!$B$6),0)) -> 8 | E11: =IFERROR(VLOOKUP(B11,敌人目录!$A$6:$AD$54,13,FALSE),"") -> 1 | F11: =IF(D11="","",D11*E11) -> 8 | G11: =IF(F11="","",F11*全局设置!$B$7*全局设置!$D$14) -> 8 | H11: =IF(G11="","",G11*全局设置!$B$5) -> 8 | I11: =IF(AND(B11="",C11=""),"",IF(B11="","缺少敌人",IF(C11="","缺少数量",IF(OR(C11<1,C11>9999,C11<>INT(C11)),"数量无效",IF(COUNTIF($B$7:$B$24,B11)>1,"重复敌人",IFERROR(IF(VLOOKUP(B11,敌人目录!$A$6:$AD$54,27,FALSE)="可回读","可回读","敌人参数错误"),"敌人不存在")))))) -> 可回读
A12: 6 | B12: 守护者原石虫 | C12: 4 | D12: =IF(OR(B12="",C12=""),"",ROUNDUP(C12*(1+(全局设置!$B$5-1)*全局设置!$B$6),0)) -> 4 | E12: =IFERROR(VLOOKUP(B12,敌人目录!$A$6:$AD$54,13,FALSE),"") -> 2 | F12: =IF(D12="","",D12*E12) -> 8 | G12: =IF(F12="","",F12*全局设置!$B$7*全局设置!$D$14) -> 8 | H12: =IF(G12="","",G12*全局设置!$B$5) -> 8 | I12: =IF(AND(B12="",C12=""),"",IF(B12="","缺少敌人",IF(C12="","缺少数量",IF(OR(C12<1,C12>9999,C12<>INT(C12)),"数量无效",IF(COUNTIF($B$7:$B$24,B12)>1,"重复敌人",IFERROR(IF(VLOOKUP(B12,敌人目录!$A$6:$AD$54,27,FALSE)="可回读","可回读","敌人参数错误"),"敌人不存在")))))) -> 可回读
A13: 7 | D13: =IF(OR(B13="",C13=""),"",ROUNDUP(C13*(1+(全局设置!$B$5-1)*全局设置!$B$6),0)) | E13: =IFERROR(VLOOKUP(B13,敌人目录!$A$6:$AD$54,13,FALSE),"") | F13: =IF(D13="","",D13*E13) | G13: =IF(F13="","",F13*全局设置!$B$7*全局设置!$D$14) | H13: =IF(G13="","",G13*全局设置!$B$5) | I13: =IF(AND(B13="",C13=""),"",IF(B13="","缺少敌人",IF(C13="","缺少数量",IF(OR(C13<1,C13>9999,C13<>INT(C13)),"数量无效",IF(COUNTIF($B$7:$B$24,B13)>1,"重复敌人",IFERROR(IF(VLOOKUP(B13,敌人目录!$A$6:$AD$54,27,FALSE)="可回读","可回读","敌人参数错误"),"敌人不存在"))))))
A14: 8 | D14: =IF(OR(B14="",C14=""),"",ROUNDUP(C14*(1+(全局设置!$B$5-1)*全局设置!$B$6),0)) | E14: =IFERROR(VLOOKUP(B14,敌人目录!$A$6:$AD$54,13,FALSE),"") | F14: =IF(D14="","",D14*E14) | G14: =IF(F14="","",F14*全局设置!$B$7*全局设置!$D$14) | H14: =IF(G14="","",G14*全局设置!$B$5) | I14: =IF(AND(B14="",C14=""),"",IF(B14="","缺少敌人",IF(C14="","缺少数量",IF(OR(C14<1,C14>9999,C14<>INT(C14)),"数量无效",IF(COUNTIF($B$7:$B$24,B14)>1,"重复敌人",IFERROR(IF(VLOOKUP(B14,敌人目录!$A$6:$AD$54,27,FALSE)="可回读","可回读","敌人参数错误"),"敌人不存在"))))))
A15: 9 | D15: =IF(OR(B15="",C15=""),"",ROUNDUP(C15*(1+(全局设置!$B$5-1)*全局设置!$B$6),0)) | E15: =IFERROR(VLOOKUP(B15,敌人目录!$A$6:$AD$54,13,FALSE),"") | F15: =IF(D15="","",D15*E15) | G15: =IF(F15="","",F15*全局设置!$B$7*全局设置!$D$14) | H15: =IF(G15="","",G15*全局设置!$B$5) | I15: =IF(AND(B15="",C15=""),"",IF(B15="","缺少敌人",IF(C15="","缺少数量",IF(OR(C15<1,C15>9999,C15<>INT(C15)),"数量无效",IF(COUNTIF($B$7:$B$24,B15)>1,"重复敌人",IFERROR(IF(VLOOKUP(B15,敌人目录!$A$6:$AD$54,27,FALSE)="可回读","可回读","敌人参数错误"),"敌人不存在"))))))
A16: 10 | D16: =IF(OR(B16="",C16=""),"",ROUNDUP(C16*(1+(全局设置!$B$5-1)*全局设置!$B$6),0)) | E16: =IFERROR(VLOOKUP(B16,敌人目录!$A$6:$AD$54,13,FALSE),"") | F16: =IF(D16="","",D16*E16) | G16: =IF(F16="","",F16*全局设置!$B$7*全局设置!$D$14) | H16: =IF(G16="","",G16*全局设置!$B$5) | I16: =IF(AND(B16="",C16=""),"",IF(B16="","缺少敌人",IF(C16="","缺少数量",IF(OR(C16<1,C16>9999,C16<>INT(C16)),"数量无效",IF(COUNTIF($B$7:$B$24,B16)>1,"重复敌人",IFERROR(IF(VLOOKUP(B16,敌人目录!$A$6:$AD$54,27,FALSE)="可回读","可回读","敌人参数错误"),"敌人不存在"))))))
A17: 11 | D17: =IF(OR(B17="",C17=""),"",ROUNDUP(C17*(1+(全局设置!$B$5-1)*全局设置!$B$6),0)) | E17: =IFERROR(VLOOKUP(B17,敌人目录!$A$6:$AD$54,13,FALSE),"") | F17: =IF(D17="","",D17*E17) | G17: =IF(F17="","",F17*全局设置!$B$7*全局设置!$D$14) | H17: =IF(G17="","",G17*全局设置!$B$5) | I17: =IF(AND(B17="",C17=""),"",IF(B17="","缺少敌人",IF(C17="","缺少数量",IF(OR(C17<1,C17>9999,C17<>INT(C17)),"数量无效",IF(COUNTIF($B$7:$B$24,B17)>1,"重复敌人",IFERROR(IF(VLOOKUP(B17,敌人目录!$A$6:$AD$54,27,FALSE)="可回读","可回读","敌人参数错误"),"敌人不存在"))))))
A18: 12 | D18: =IF(OR(B18="",C18=""),"",ROUNDUP(C18*(1+(全局设置!$B$5-1)*全局设置!$B$6),0)) | E18: =IFERROR(VLOOKUP(B18,敌人目录!$A$6:$AD$54,13,FALSE),"") | F18: =IF(D18="","",D18*E18) | G18: =IF(F18="","",F18*全局设置!$B$7*全局设置!$D$14) | H18: =IF(G18="","",G18*全局设置!$B$5) | I18: =IF(AND(B18="",C18=""),"",IF(B18="","缺少敌人",IF(C18="","缺少数量",IF(OR(C18<1,C18>9999,C18<>INT(C18)),"数量无效",IF(COUNTIF($B$7:$B$24,B18)>1,"重复敌人",IFERROR(IF(VLOOKUP(B18,敌人目录!$A$6:$AD$54,27,FALSE)="可回读","可回读","敌人参数错误"),"敌人不存在"))))))
A19: 13 | D19: =IF(OR(B19="",C19=""),"",ROUNDUP(C19*(1+(全局设置!$B$5-1)*全局设置!$B$6),0)) | E19: =IFERROR(VLOOKUP(B19,敌人目录!$A$6:$AD$54,13,FALSE),"") | F19: =IF(D19="","",D19*E19) | G19: =IF(F19="","",F19*全局设置!$B$7*全局设置!$D$14) | H19: =IF(G19="","",G19*全局设置!$B$5) | I19: =IF(AND(B19="",C19=""),"",IF(B19="","缺少敌人",IF(C19="","缺少数量",IF(OR(C19<1,C19>9999,C19<>INT(C19)),"数量无效",IF(COUNTIF($B$7:$B$24,B19)>1,"重复敌人",IFERROR(IF(VLOOKUP(B19,敌人目录!$A$6:$AD$54,27,FALSE)="可回读","可回读","敌人参数错误"),"敌人不存在"))))))
A20: 14 | D20: =IF(OR(B20="",C20=""),"",ROUNDUP(C20*(1+(全局设置!$B$5-1)*全局设置!$B$6),0)) | E20: =IFERROR(VLOOKUP(B20,敌人目录!$A$6:$AD$54,13,FALSE),"") | F20: =IF(D20="","",D20*E20) | G20: =IF(F20="","",F20*全局设置!$B$7*全局设置!$D$14) | H20: =IF(G20="","",G20*全局设置!$B$5) | I20: =IF(AND(B20="",C20=""),"",IF(B20="","缺少敌人",IF(C20="","缺少数量",IF(OR(C20<1,C20>9999,C20<>INT(C20)),"数量无效",IF(COUNTIF($B$7:$B$24,B20)>1,"重复敌人",IFERROR(IF(VLOOKUP(B20,敌人目录!$A$6:$AD$54,27,FALSE)="可回读","可回读","敌人参数错误"),"敌人不存在"))))))
A21: 15 | D21: =IF(OR(B21="",C21=""),"",ROUNDUP(C21*(1+(全局设置!$B$5-1)*全局设置!$B$6),0)) | E21: =IFERROR(VLOOKUP(B21,敌人目录!$A$6:$AD$54,13,FALSE),"") | F21: =IF(D21="","",D21*E21) | G21: =IF(F21="","",F21*全局设置!$B$7*全局设置!$D$14) | H21: =IF(G21="","",G21*全局设置!$B$5) | I21: =IF(AND(B21="",C21=""),"",IF(B21="","缺少敌人",IF(C21="","缺少数量",IF(OR(C21<1,C21>9999,C21<>INT(C21)),"数量无效",IF(COUNTIF($B$7:$B$24,B21)>1,"重复敌人",IFERROR(IF(VLOOKUP(B21,敌人目录!$A$6:$AD$54,27,FALSE)="可回读","可回读","敌人参数错误"),"敌人不存在"))))))
A22: 16 | D22: =IF(OR(B22="",C22=""),"",ROUNDUP(C22*(1+(全局设置!$B$5-1)*全局设置!$B$6),0)) | E22: =IFERROR(VLOOKUP(B22,敌人目录!$A$6:$AD$54,13,FALSE),"") | F22: =IF(D22="","",D22*E22) | G22: =IF(F22="","",F22*全局设置!$B$7*全局设置!$D$14) | H22: =IF(G22="","",G22*全局设置!$B$5) | I22: =IF(AND(B22="",C22=""),"",IF(B22="","缺少敌人",IF(C22="","缺少数量",IF(OR(C22<1,C22>9999,C22<>INT(C22)),"数量无效",IF(COUNTIF($B$7:$B$24,B22)>1,"重复敌人",IFERROR(IF(VLOOKUP(B22,敌人目录!$A$6:$AD$54,27,FALSE)="可回读","可回读","敌人参数错误"),"敌人不存在"))))))
A23: 17 | D23: =IF(OR(B23="",C23=""),"",ROUNDUP(C23*(1+(全局设置!$B$5-1)*全局设置!$B$6),0)) | E23: =IFERROR(VLOOKUP(B23,敌人目录!$A$6:$AD$54,13,FALSE),"") | F23: =IF(D23="","",D23*E23) | G23: =IF(F23="","",F23*全局设置!$B$7*全局设置!$D$14) | H23: =IF(G23="","",G23*全局设置!$B$5) | I23: =IF(AND(B23="",C23=""),"",IF(B23="","缺少敌人",IF(C23="","缺少数量",IF(OR(C23<1,C23>9999,C23<>INT(C23)),"数量无效",IF(COUNTIF($B$7:$B$24,B23)>1,"重复敌人",IFERROR(IF(VLOOKUP(B23,敌人目录!$A$6:$AD$54,27,FALSE)="可回读","可回读","敌人参数错误"),"敌人不存在"))))))
A24: 18 | D24: =IF(OR(B24="",C24=""),"",ROUNDUP(C24*(1+(全局设置!$B$5-1)*全局设置!$B$6),0)) | E24: =IFERROR(VLOOKUP(B24,敌人目录!$A$6:$AD$54,13,FALSE),"") | F24: =IF(D24="","",D24*E24) | G24: =IF(F24="","",F24*全局设置!$B$7*全局设置!$D$14) | H24: =IF(G24="","",G24*全局设置!$B$5) | I24: =IF(AND(B24="",C24=""),"",IF(B24="","缺少敌人",IF(C24="","缺少数量",IF(OR(C24<1,C24>9999,C24<>INT(C24)),"数量无效",IF(COUNTIF($B$7:$B$24,B24)>1,"重复敌人",IFERROR(IF(VLOOKUP(B24,敌人目录!$A$6:$AD$54,27,FALSE)="可回读","可回读","敌人参数错误"),"敌人不存在"))))))
A26: 基础总数 | B26: =SUM(C7:C24) -> 80 | C26: 实际总数 | D26: =SUM(D7:D24) -> 80 | E26: 最大息壤/玩家 | F26: =SUM(F7:F24) -> 96 | G26: 情景息壤/玩家 | H26: =SUM(G7:G24) -> 96
A27: 情景息壤/队伍 | B27: =SUM(H7:H24) -> 96 | C27: 情景收益 = 最大息壤 × 全局击杀率 × 第2日倍率；队伍值再乘模拟玩家数。 | D27: 情景收益 = 最大息壤 × 全局击杀率 × 第2日倍率；队伍值再乘模拟玩家数。 | E27: 情景收益 = 最大息壤 × 全局击杀率 × 第2日倍率；队伍值再乘模拟玩家数。 | F27: 情景收益 = 最大息壤 × 全局击杀率 × 第2日倍率；队伍值再乘模拟玩家数。 | G27: 情景收益 = 最大息壤 × 全局击杀率 × 第2日倍率；队伍值再乘模拟玩家数。 | H27: 情景收益 = 最大息壤 × 全局击杀率 × 第2日倍率；队伍值再乘模拟玩家数。 | I27: 情景收益 = 最大息壤 × 全局击杀率 × 第2日倍率；队伍值再乘模拟玩家数。
A31: 第 6 波｜第 2 日·2/4｜白昼｜当前正式配置 | B31: 第 6 波｜第 2 日·2/4｜白昼｜当前正式配置 | C31: 第 6 波｜第 2 日·2/4｜白昼｜当前正式配置 | D31: 第 6 波｜第 2 日·2/4｜白昼｜当前正式配置 | E31: 第 6 波｜第 2 日·2/4｜白昼｜当前正式配置 | F31: 第 6 波｜第 2 日·2/4｜白昼｜当前正式配置 | G31: 第 6 波｜第 2 日·2/4｜白昼｜当前正式配置 | H31: 第 6 波｜第 2 日·2/4｜白昼｜当前正式配置 | I31: 第 6 波｜第 2 日·2/4｜白昼｜当前正式配置
A32: 波次名称 | B32: 第6波 守护阵列 | C32: 第6波 守护阵列 | D32: 出生间隔(s) | E32: 0.4 | F32: 每Tick | G32: 1 | H32: 存活上限 | I32: 300
A33: 出生点 | B33: 点1·开启 | C33: 点2·开启 | D33: 点3·开启 | E33: 点4·开启 | F33: 点5·开启 | G33: 点6·开启 | H33: 波次校验 | I33: =IF(COUNTA(B36:B53)=0,"待设计",IF(COUNTIF(I36:I53,"可回读")=COUNTA(B36:B53),"可回读","需修正")) -> 可回读
A34: 仅编辑蓝色列。敌人数值、固定息壤与掉落统一在“敌人目录”维护；本页按实际数量逐项精确结算息壤。 | B34: 仅编辑蓝色列。敌人数值、固定息壤与掉落统一在“敌人目录”维护；本页按实际数量逐项精确结算息壤。 | C34: 仅编辑蓝色列。敌人数值、固定息壤与掉落统一在“敌人目录”维护；本页按实际数量逐项精确结算息壤。 | D34: 仅编辑蓝色列。敌人数值、固定息壤与掉落统一在“敌人目录”维护；本页按实际数量逐项精确结算息壤。 | E34: 仅编辑蓝色列。敌人数值、固定息壤与掉落统一在“敌人目录”维护；本页按实际数量逐项精确结算息壤。 | F34: 仅编辑蓝色列。敌人数值、固定息壤与掉落统一在“敌人目录”维护；本页按实际数量逐项精确结算息壤。 | G34: 仅编辑蓝色列。敌人数值、固定息壤与掉落统一在“敌人目录”维护；本页按实际数量逐项精确结算息壤。 | H34: 仅编辑蓝色列。敌人数值、固定息壤与掉落统一在“敌人目录”维护；本页按实际数量逐项精确结算息壤。 | I34: 仅编辑蓝色列。敌人数值、固定息壤与掉落统一在“敌人目录”维护；本页按实际数量逐项精确结算息壤。
A35: 槽位 | B35: 敌人（下拉选择） | C35: 基础数量 | D35: 实际数量 | E35: 息壤/击杀 | F35: 本项最大息壤/玩家 | G35: 本项情景息壤/玩家 | H35: 本项情景息壤/队伍 | I35: 校验
A36: 1 | B36: 普通原石虫 | C36: 28 | D36: =IF(OR(B36="",C36=""),"",ROUNDUP(C36*(1+(全局设置!$B$5-1)*全局设置!$B$6),0)) -> 28 | E36: =IFERROR(VLOOKUP(B36,敌人目录!$A$6:$AD$54,13,FALSE),"") -> 1 | F36: =IF(D36="","",D36*E36) -> 28 | G36: =IF(F36="","",F36*全局设置!$B$7*全局设置!$D$14) -> 28 | H36: =IF(G36="","",G36*全局设置!$B$5) -> 28 | I36: =IF(AND(B36="",C36=""),"",IF(B36="","缺少敌人",IF(C36="","缺少数量",IF(OR(C36<1,C36>9999,C36<>INT(C36)),"数量无效",IF(COUNTIF($B$36:$B$53,B36)>1,"重复敌人",IFERROR(IF(VLOOKUP(B36,敌人目录!$A$6:$AD$54,27,FALSE)="可回读","可回读","敌人参数错误"),"敌人不存在")))))) -> 可回读
A37: 2 | B37: 迅捷原石虫 | C37: 24 | D37: =IF(OR(B37="",C37=""),"",ROUNDUP(C37*(1+(全局设置!$B$5-1)*全局设置!$B$6),0)) -> 24 | E37: =IFERROR(VLOOKUP(B37,敌人目录!$A$6:$AD$54,13,FALSE),"") -> 1 | F37: =IF(D37="","",D37*E37) -> 24 | G37: =IF(F37="","",F37*全局设置!$B$7*全局设置!$D$14) -> 24 | H37: =IF(G37="","",G37*全局设置!$B$5) -> 24 | I37: =IF(AND(B37="",C37=""),"",IF(B37="","缺少敌人",IF(C37="","缺少数量",IF(OR(C37<1,C37>9999,C37<>INT(C37)),"数量无效",IF(COUNTIF($B$36:$B$53,B37)>1,"重复敌人",IFERROR(IF(VLOOKUP(B37,敌人目录!$A$6:$AD$54,27,FALSE)="可回读","可回读","敌人参数错误"),"敌人不存在")))))) -> 可回读
A38: 3 | B38: 硬壳原石虫 | C38: 12 | D38: =IF(OR(B38="",C38=""),"",ROUNDUP(C38*(1+(全局设置!$B$5-1)*全局设置!$B$6),0)) -> 12 | E38: =IFERROR(VLOOKUP(B38,敌人目录!$A$6:$AD$54,13,FALSE),"") -> 2 | F38: =IF(D38="","",D38*E38) -> 24 | G38: =IF(F38="","",F38*全局设置!$B$7*全局设置!$D$14) -> 24 | H38: =IF(G38="","",G38*全局设置!$B$5) -> 24 | I38: =IF(AND(B38="",C38=""),"",IF(B38="","缺少敌人",IF(C38="","缺少数量",IF(OR(C38<1,C38>9999,C38<>INT(C38)),"数量无效",IF(COUNTIF($B$36:$B$53,B38)>1,"重复敌人",IFERROR(IF(VLOOKUP(B38,敌人目录!$A$6:$AD$54,27,FALSE)="可回读","可回读","敌人参数错误"),"敌人不存在")))))) -> 可回读
A39: 4 | B39: 自爆原石虫 | C39: 12 | D39: =IF(OR(B39="",C39=""),"",ROUNDUP(C39*(1+(全局设置!$B$5-1)*全局设置!$B$6),0)) -> 12 | E39: =IFERROR(VLOOKUP(B39,敌人目录!$A$6:$AD$54,13,FALSE),"") -> 1 | F39: =IF(D39="","",D39*E39) -> 12 | G39: =IF(F39="","",F39*全局设置!$B$7*全局设置!$D$14) -> 12 | H39: =IF(G39="","",G39*全局设置!$B$5) -> 12 | I39: =IF(AND(B39="",C39=""),"",IF(B39="","缺少敌人",IF(C39="","缺少数量",IF(OR(C39<1,C39>9999,C39<>INT(C39)),"数量无效",IF(COUNTIF($B$36:$B$53,B39)>1,"重复敌人",IFERROR(IF(VLOOKUP(B39,敌人目录!$A$6:$AD$54,27,FALSE)="可回读","可回读","敌人参数错误"),"敌人不存在")))))) -> 可回读
A40: 5 | B40: 火焰弹原石虫 | C40: 12 | D40: =IF(OR(B40="",C40=""),"",ROUNDUP(C40*(1+(全局设置!$B$5-1)*全局设置!$B$6),0)) -> 12 | E40: =IFERROR(VLOOKUP(B40,敌人目录!$A$6:$AD$54,13,FALSE),"") -> 1 | F40: =IF(D40="","",D40*E40) -> 12 | G40: =IF(F40="","",F40*全局设置!$B$7*全局设置!$D$14) -> 12 | H40: =IF(G40="","",G40*全局设置!$B$5) -> 12 | I40: =IF(AND(B40="",C40=""),"",IF(B40="","缺少敌人",IF(C40="","缺少数量",IF(OR(C40<1,C40>9999,C40<>INT(C40)),"数量无效",IF(COUNTIF($B$36:$B$53,B40)>1,"重复敌人",IFERROR(IF(VLOOKUP(B40,敌人目录!$A$6:$AD$54,27,FALSE)="可回读","可回读","敌人参数错误"),"敌人不存在")))))) -> 可回读
A41: 6 | B41: 守护者原石虫 | C41: 8 | D41: =IF(OR(B41="",C41=""),"",ROUNDUP(C41*(1+(全局设置!$B$5-1)*全局设置!$B$6),0)) -> 8 | E41: =IFERROR(VLOOKUP(B41,敌人目录!$A$6:$AD$54,13,FALSE),"") -> 2 | F41: =IF(D41="","",D41*E41) -> 16 | G41: =IF(F41="","",F41*全局设置!$B$7*全局设置!$D$14) -> 16 | H41: =IF(G41="","",G41*全局设置!$B$5) -> 16 | I41: =IF(AND(B41="",C41=""),"",IF(B41="","缺少敌人",IF(C41="","缺少数量",IF(OR(C41<1,C41>9999,C41<>INT(C41)),"数量无效",IF(COUNTIF($B$36:$B$53,B41)>1,"重复敌人",IFERROR(IF(VLOOKUP(B41,敌人目录!$A$6:$AD$54,27,FALSE)="可回读","可回读","敌人参数错误"),"敌人不存在")))))) -> 可回读
A42: 7 | D42: =IF(OR(B42="",C42=""),"",ROUNDUP(C42*(1+(全局设置!$B$5-1)*全局设置!$B$6),0)) | E42: =IFERROR(VLOOKUP(B42,敌人目录!$A$6:$AD$54,13,FALSE),"") | F42: =IF(D42="","",D42*E42) | G42: =IF(F42="","",F42*全局设置!$B$7*全局设置!$D$14) | H42: =IF(G42="","",G42*全局设置!$B$5) | I42: =IF(AND(B42="",C42=""),"",IF(B42="","缺少敌人",IF(C42="","缺少数量",IF(OR(C42<1,C42>9999,C42<>INT(C42)),"数量无效",IF(COUNTIF($B$36:$B$53,B42)>1,"重复敌人",IFERROR(IF(VLOOKUP(B42,敌人目录!$A$6:$AD$54,27,FALSE)="可回读","可回读","敌人参数错误"),"敌人不存在"))))))
A43: 8 | D43: =IF(OR(B43="",C43=""),"",ROUNDUP(C43*(1+(全局设置!$B$5-1)*全局设置!$B$6),0)) | E43: =IFERROR(VLOOKUP(B43,敌人目录!$A$6:$AD$54,13,FALSE),"") | F43: =IF(D43="","",D43*E43) | G43: =IF(F43="","",F43*全局设置!$B$7*全局设置!$D$14) | H43: =IF(G43="","",G43*全局设置!$B$5) | I43: =IF(AND(B43="",C43=""),"",IF(B43="","缺少敌人",IF(C43="","缺少数量",IF(OR(C43<1,C43>9999,C43<>INT(C43)),"数量无效",IF(COUNTIF($B$36:$B$53,B43)>1,"重复敌人",IFERROR(IF(VLOOKUP(B43,敌人目录!$A$6:$AD$54,27,FALSE)="可回读","可回读","敌人参数错误"),"敌人不存在"))))))
A44: 9 | D44: =IF(OR(B44="",C44=""),"",ROUNDUP(C44*(1+(全局设置!$B$5-1)*全局设置!$B$6),0)) | E44: =IFERROR(VLOOKUP(B44,敌人目录!$A$6:$AD$54,13,FALSE),"") | F44: =IF(D44="","",D44*E44) | G44: =IF(F44="","",F44*全局设置!$B$7*全局设置!$D$14) | H44: =IF(G44="","",G44*全局设置!$B$5) | I44: =IF(AND(B44="",C44=""),"",IF(B44="","缺少敌人",IF(C44="","缺少数量",IF(OR(C44<1,C44>9999,C44<>INT(C44)),"数量无效",IF(COUNTIF($B$36:$B$53,B44)>1,"重复敌人",IFERROR(IF(VLOOKUP(B44,敌人目录!$A$6:$AD$54,27,FALSE)="可回读","可回读","敌人参数错误"),"敌人不存在"))))))
A45: 10 | D45: =IF(OR(B45="",C45=""),"",ROUNDUP(C45*(1+(全局设置!$B$5-1)*全局设置!$B$6),0)) | E45: =IFERROR(VLOOKUP(B45,敌人目录!$A$6:$AD$54,13,FALSE),"") | F45: =IF(D45="","",D45*E45) | G45: =IF(F45="","",F45*全局设置!$B$7*全局设置!$D$14) | H45: =IF(G45="","",G45*全局设置!$B$5) | I45: =IF(AND(B45="",C45=""),"",IF(B45="","缺少敌人",IF(C45="","缺少数量",IF(OR(C45<1,C45>9999,C45<>INT(C45)),"数量无效",IF(COUNTIF($B$36:$B$53,B45)>1,"重复敌人",IFERROR(IF(VLOOKUP(B45,敌人目录!$A$6:$AD$54,27,FALSE)="可回读","可回读","敌人参数错误"),"敌人不存在"))))))
...

Sheet 第3日
A2: 第 9 波｜第 3 日·1/4｜白昼｜当前正式配置 | B2: 第 9 波｜第 3 日·1/4｜白昼｜当前正式配置 | C2: 第 9 波｜第 3 日·1/4｜白昼｜当前正式配置 | D2: 第 9 波｜第 3 日·1/4｜白昼｜当前正式配置 | E2: 第 9 波｜第 3 日·1/4｜白昼｜当前正式配置 | F2: 第 9 波｜第 3 日·1/4｜白昼｜当前正式配置 | G2: 第 9 波｜第 3 日·1/4｜白昼｜当前正式配置 | H2: 第 9 波｜第 3 日·1/4｜白昼｜当前正式配置 | I2: 第 9 波｜第 3 日·1/4｜白昼｜当前正式配置
A3: 波次名称 | B3: 第9波 城镇前锋 | C3: 第9波 城镇前锋 | D3: 出生间隔(s) | E3: 0.28 | F3: 每Tick | G3: 1 | H3: 存活上限 | I3: 300
A4: 出生点 | B4: 点1·开启 | C4: 点2·开启 | D4: 点3·开启 | E4: 点4·开启 | F4: 点5·开启 | G4: 点6·开启 | H4: 波次校验 | I4: =IF(COUNTA(B7:B24)=0,"待设计",IF(COUNTIF(I7:I24,"可回读")=COUNTA(B7:B24),"可回读","需修正")) -> 可回读
A5: 仅编辑蓝色列。敌人数值、固定息壤与掉落统一在“敌人目录”维护；本页按实际数量逐项精确结算息壤。 | B5: 仅编辑蓝色列。敌人数值、固定息壤与掉落统一在“敌人目录”维护；本页按实际数量逐项精确结算息壤。 | C5: 仅编辑蓝色列。敌人数值、固定息壤与掉落统一在“敌人目录”维护；本页按实际数量逐项精确结算息壤。 | D5: 仅编辑蓝色列。敌人数值、固定息壤与掉落统一在“敌人目录”维护；本页按实际数量逐项精确结算息壤。 | E5: 仅编辑蓝色列。敌人数值、固定息壤与掉落统一在“敌人目录”维护；本页按实际数量逐项精确结算息壤。 | F5: 仅编辑蓝色列。敌人数值、固定息壤与掉落统一在“敌人目录”维护；本页按实际数量逐项精确结算息壤。 | G5: 仅编辑蓝色列。敌人数值、固定息壤与掉落统一在“敌人目录”维护；本页按实际数量逐项精确结算息壤。 | H5: 仅编辑蓝色列。敌人数值、固定息壤与掉落统一在“敌人目录”维护；本页按实际数量逐项精确结算息壤。 | I5: 仅编辑蓝色列。敌人数值、固定息壤与掉落统一在“敌人目录”维护；本页按实际数量逐项精确结算息壤。
A6: 槽位 | B6: 敌人（下拉选择） | C6: 基础数量 | D6: 实际数量 | E6: 息壤/击杀 | F6: 本项最大息壤/玩家 | G6: 本项情景息壤/玩家 | H6: 本项情景息壤/队伍 | I6: 校验
A7: 1 | B7: 普通原石虫 | C7: 26 | D7: =IF(OR(B7="",C7=""),"",ROUNDUP(C7*(1+(全局设置!$B$5-1)*全局设置!$B$6),0)) -> 26 | E7: =IFERROR(VLOOKUP(B7,敌人目录!$A$6:$AD$54,13,FALSE),"") -> 1 | F7: =IF(D7="","",D7*E7) -> 26 | G7: =IF(F7="","",F7*全局设置!$B$7*全局设置!$E$14) -> 26 | H7: =IF(G7="","",G7*全局设置!$B$5) -> 26 | I7: =IF(AND(B7="",C7=""),"",IF(B7="","缺少敌人",IF(C7="","缺少数量",IF(OR(C7<1,C7>9999,C7<>INT(C7)),"数量无效",IF(COUNTIF($B$7:$B$24,B7)>1,"重复敌人",IFERROR(IF(VLOOKUP(B7,敌人目录!$A$6:$AD$54,27,FALSE)="可回读","可回读","敌人参数错误"),"敌人不存在")))))) -> 可回读
A8: 2 | B8: 迅捷原石虫 | C8: 20 | D8: =IF(OR(B8="",C8=""),"",ROUNDUP(C8*(1+(全局设置!$B$5-1)*全局设置!$B$6),0)) -> 20 | E8: =IFERROR(VLOOKUP(B8,敌人目录!$A$6:$AD$54,13,FALSE),"") -> 1 | F8: =IF(D8="","",D8*E8) -> 20 | G8: =IF(F8="","",F8*全局设置!$B$7*全局设置!$E$14) -> 20 | H8: =IF(G8="","",G8*全局设置!$B$5) -> 20 | I8: =IF(AND(B8="",C8=""),"",IF(B8="","缺少敌人",IF(C8="","缺少数量",IF(OR(C8<1,C8>9999,C8<>INT(C8)),"数量无效",IF(COUNTIF($B$7:$B$24,B8)>1,"重复敌人",IFERROR(IF(VLOOKUP(B8,敌人目录!$A$6:$AD$54,27,FALSE)="可回读","可回读","敌人参数错误"),"敌人不存在")))))) -> 可回读
A9: 3 | B9: 硬壳原石虫 | C9: 20 | D9: =IF(OR(B9="",C9=""),"",ROUNDUP(C9*(1+(全局设置!$B$5-1)*全局设置!$B$6),0)) -> 20 | E9: =IFERROR(VLOOKUP(B9,敌人目录!$A$6:$AD$54,13,FALSE),"") -> 2 | F9: =IF(D9="","",D9*E9) -> 40 | G9: =IF(F9="","",F9*全局设置!$B$7*全局设置!$E$14) -> 40 | H9: =IF(G9="","",G9*全局设置!$B$5) -> 40 | I9: =IF(AND(B9="",C9=""),"",IF(B9="","缺少敌人",IF(C9="","缺少数量",IF(OR(C9<1,C9>9999,C9<>INT(C9)),"数量无效",IF(COUNTIF($B$7:$B$24,B9)>1,"重复敌人",IFERROR(IF(VLOOKUP(B9,敌人目录!$A$6:$AD$54,27,FALSE)="可回读","可回读","敌人参数错误"),"敌人不存在")))))) -> 可回读
A10: 4 | B10: 自爆原石虫 | C10: 16 | D10: =IF(OR(B10="",C10=""),"",ROUNDUP(C10*(1+(全局设置!$B$5-1)*全局设置!$B$6),0)) -> 16 | E10: =IFERROR(VLOOKUP(B10,敌人目录!$A$6:$AD$54,13,FALSE),"") -> 1 | F10: =IF(D10="","",D10*E10) -> 16 | G10: =IF(F10="","",F10*全局设置!$B$7*全局设置!$E$14) -> 16 | H10: =IF(G10="","",G10*全局设置!$B$5) -> 16 | I10: =IF(AND(B10="",C10=""),"",IF(B10="","缺少敌人",IF(C10="","缺少数量",IF(OR(C10<1,C10>9999,C10<>INT(C10)),"数量无效",IF(COUNTIF($B$7:$B$24,B10)>1,"重复敌人",IFERROR(IF(VLOOKUP(B10,敌人目录!$A$6:$AD$54,27,FALSE)="可回读","可回读","敌人参数错误"),"敌人不存在")))))) -> 可回读
A11: 5 | B11: 紫晶自爆原石虫 | C11: 12 | D11: =IF(OR(B11="",C11=""),"",ROUNDUP(C11*(1+(全局设置!$B$5-1)*全局设置!$B$6),0)) -> 12 | E11: =IFERROR(VLOOKUP(B11,敌人目录!$A$6:$AD$54,13,FALSE),"") -> 2 | F11: =IF(D11="","",D11*E11) -> 24 | G11: =IF(F11="","",F11*全局设置!$B$7*全局设置!$E$14) -> 24 | H11: =IF(G11="","",G11*全局设置!$B$5) -> 24 | I11: =IF(AND(B11="",C11=""),"",IF(B11="","缺少敌人",IF(C11="","缺少数量",IF(OR(C11<1,C11>9999,C11<>INT(C11)),"数量无效",IF(COUNTIF($B$7:$B$24,B11)>1,"重复敌人",IFERROR(IF(VLOOKUP(B11,敌人目录!$A$6:$AD$54,27,FALSE)="可回读","可回读","敌人参数错误"),"敌人不存在")))))) -> 可回读
A12: 6 | B12: 火焰弹原石虫 | C12: 20 | D12: =IF(OR(B12="",C12=""),"",ROUNDUP(C12*(1+(全局设置!$B$5-1)*全局设置!$B$6),0)) -> 20 | E12: =IFERROR(VLOOKUP(B12,敌人目录!$A$6:$AD$54,13,FALSE),"") -> 1 | F12: =IF(D12="","",D12*E12) -> 20 | G12: =IF(F12="","",F12*全局设置!$B$7*全局设置!$E$14) -> 20 | H12: =IF(G12="","",G12*全局设置!$B$5) -> 20 | I12: =IF(AND(B12="",C12=""),"",IF(B12="","缺少敌人",IF(C12="","缺少数量",IF(OR(C12<1,C12>9999,C12<>INT(C12)),"数量无效",IF(COUNTIF($B$7:$B$24,B12)>1,"重复敌人",IFERROR(IF(VLOOKUP(B12,敌人目录!$A$6:$AD$54,27,FALSE)="可回读","可回读","敌人参数错误"),"敌人不存在")))))) -> 可回读
A13: 7 | B13: 翠壳原石虫 | C13: 16 | D13: =IF(OR(B13="",C13=""),"",ROUNDUP(C13*(1+(全局设置!$B$5-1)*全局设置!$B$6),0)) -> 16 | E13: =IFERROR(VLOOKUP(B13,敌人目录!$A$6:$AD$54,13,FALSE),"") -> 2 | F13: =IF(D13="","",D13*E13) -> 32 | G13: =IF(F13="","",F13*全局设置!$B$7*全局设置!$E$14) -> 32 | H13: =IF(G13="","",G13*全局设置!$B$5) -> 32 | I13: =IF(AND(B13="",C13=""),"",IF(B13="","缺少敌人",IF(C13="","缺少数量",IF(OR(C13<1,C13>9999,C13<>INT(C13)),"数量无效",IF(COUNTIF($B$7:$B$24,B13)>1,"重复敌人",IFERROR(IF(VLOOKUP(B13,敌人目录!$A$6:$AD$54,27,FALSE)="可回读","可回读","敌人参数错误"),"敌人不存在")))))) -> 可回读
A14: 8 | B14: 守护者原石虫 | C14: 12 | D14: =IF(OR(B14="",C14=""),"",ROUNDUP(C14*(1+(全局设置!$B$5-1)*全局设置!$B$6),0)) -> 12 | E14: =IFERROR(VLOOKUP(B14,敌人目录!$A$6:$AD$54,13,FALSE),"") -> 2 | F14: =IF(D14="","",D14*E14) -> 24 | G14: =IF(F14="","",F14*全局设置!$B$7*全局设置!$E$14) -> 24 | H14: =IF(G14="","",G14*全局设置!$B$5) -> 24 | I14: =IF(AND(B14="",C14=""),"",IF(B14="","缺少敌人",IF(C14="","缺少数量",IF(OR(C14<1,C14>9999,C14<>INT(C14)),"数量无效",IF(COUNTIF($B$7:$B$24,B14)>1,"重复敌人",IFERROR(IF(VLOOKUP(B14,敌人目录!$A$6:$AD$54,27,FALSE)="可回读","可回读","敌人参数错误"),"敌人不存在")))))) -> 可回读
A15: 9 | B15: 骑士猫猫虫 | C15: 2 | D15: =IF(OR(B15="",C15=""),"",ROUNDUP(C15*(1+(全局设置!$B$5-1)*全局设置!$B$6),0)) -> 2 | E15: =IFERROR(VLOOKUP(B15,敌人目录!$A$6:$AD$54,13,FALSE),"") -> 4 | F15: =IF(D15="","",D15*E15) -> 8 | G15: =IF(F15="","",F15*全局设置!$B$7*全局设置!$E$14) -> 8 | H15: =IF(G15="","",G15*全局设置!$B$5) -> 8 | I15: =IF(AND(B15="",C15=""),"",IF(B15="","缺少敌人",IF(C15="","缺少数量",IF(OR(C15<1,C15>9999,C15<>INT(C15)),"数量无效",IF(COUNTIF($B$7:$B$24,B15)>1,"重复敌人",IFERROR(IF(VLOOKUP(B15,敌人目录!$A$6:$AD$54,27,FALSE)="可回读","可回读","敌人参数错误"),"敌人不存在")))))) -> 可回读
A16: 10 | D16: =IF(OR(B16="",C16=""),"",ROUNDUP(C16*(1+(全局设置!$B$5-1)*全局设置!$B$6),0)) | E16: =IFERROR(VLOOKUP(B16,敌人目录!$A$6:$AD$54,13,FALSE),"") | F16: =IF(D16="","",D16*E16) | G16: =IF(F16="","",F16*全局设置!$B$7*全局设置!$E$14) | H16: =IF(G16="","",G16*全局设置!$B$5) | I16: =IF(AND(B16="",C16=""),"",IF(B16="","缺少敌人",IF(C16="","缺少数量",IF(OR(C16<1,C16>9999,C16<>INT(C16)),"数量无效",IF(COUNTIF($B$7:$B$24,B16)>1,"重复敌人",IFERROR(IF(VLOOKUP(B16,敌人目录!$A$6:$AD$54,27,FALSE)="可回读","可回读","敌人参数错误"),"敌人不存在"))))))
A17: 11 | D17: =IF(OR(B17="",C17=""),"",ROUNDUP(C17*(1+(全局设置!$B$5-1)*全局设置!$B$6),0)) | E17: =IFERROR(VLOOKUP(B17,敌人目录!$A$6:$AD$54,13,FALSE),"") | F17: =IF(D17="","",D17*E17) | G17: =IF(F17="","",F17*全局设置!$B$7*全局设置!$E$14) | H17: =IF(G17="","",G17*全局设置!$B$5) | I17: =IF(AND(B17="",C17=""),"",IF(B17="","缺少敌人",IF(C17="","缺少数量",IF(OR(C17<1,C17>9999,C17<>INT(C17)),"数量无效",IF(COUNTIF($B$7:$B$24,B17)>1,"重复敌人",IFERROR(IF(VLOOKUP(B17,敌人目录!$A$6:$AD$54,27,FALSE)="可回读","可回读","敌人参数错误"),"敌人不存在"))))))
A18: 12 | D18: =IF(OR(B18="",C18=""),"",ROUNDUP(C18*(1+(全局设置!$B$5-1)*全局设置!$B$6),0)) | E18: =IFERROR(VLOOKUP(B18,敌人目录!$A$6:$AD$54,13,FALSE),"") | F18: =IF(D18="","",D18*E18) | G18: =IF(F18="","",F18*全局设置!$B$7*全局设置!$E$14) | H18: =IF(G18="","",G18*全局设置!$B$5) | I18: =IF(AND(B18="",C18=""),"",IF(B18="","缺少敌人",IF(C18="","缺少数量",IF(OR(C18<1,C18>9999,C18<>INT(C18)),"数量无效",IF(COUNTIF($B$7:$B$24,B18)>1,"重复敌人",IFERROR(IF(VLOOKUP(B18,敌人目录!$A$6:$AD$54,27,FALSE)="可回读","可回读","敌人参数错误"),"敌人不存在"))))))
A19: 13 | D19: =IF(OR(B19="",C19=""),"",ROUNDUP(C19*(1+(全局设置!$B$5-1)*全局设置!$B$6),0)) | E19: =IFERROR(VLOOKUP(B19,敌人目录!$A$6:$AD$54,13,FALSE),"") | F19: =IF(D19="","",D19*E19) | G19: =IF(F19="","",F19*全局设置!$B$7*全局设置!$E$14) | H19: =IF(G19="","",G19*全局设置!$B$5) | I19: =IF(AND(B19="",C19=""),"",IF(B19="","缺少敌人",IF(C19="","缺少数量",IF(OR(C19<1,C19>9999,C19<>INT(C19)),"数量无效",IF(COUNTIF($B$7:$B$24,B19)>1,"重复敌人",IFERROR(IF(VLOOKUP(B19,敌人目录!$A$6:$AD$54,27,FALSE)="可回读","可回读","敌人参数错误"),"敌人不存在"))))))
A20: 14 | D20: =IF(OR(B20="",C20=""),"",ROUNDUP(C20*(1+(全局设置!$B$5-1)*全局设置!$B$6),0)) | E20: =IFERROR(VLOOKUP(B20,敌人目录!$A$6:$AD$54,13,FALSE),"") | F20: =IF(D20="","",D20*E20) | G20: =IF(F20="","",F20*全局设置!$B$7*全局设置!$E$14) | H20: =IF(G20="","",G20*全局设置!$B$5) | I20: =IF(AND(B20="",C20=""),"",IF(B20="","缺少敌人",IF(C20="","缺少数量",IF(OR(C20<1,C20>9999,C20<>INT(C20)),"数量无效",IF(COUNTIF($B$7:$B$24,B20)>1,"重复敌人",IFERROR(IF(VLOOKUP(B20,敌人目录!$A$6:$AD$54,27,FALSE)="可回读","可回读","敌人参数错误"),"敌人不存在"))))))
A21: 15 | D21: =IF(OR(B21="",C21=""),"",ROUNDUP(C21*(1+(全局设置!$B$5-1)*全局设置!$B$6),0)) | E21: =IFERROR(VLOOKUP(B21,敌人目录!$A$6:$AD$54,13,FALSE),"") | F21: =IF(D21="","",D21*E21) | G21: =IF(F21="","",F21*全局设置!$B$7*全局设置!$E$14) | H21: =IF(G21="","",G21*全局设置!$B$5) | I21: =IF(AND(B21="",C21=""),"",IF(B21="","缺少敌人",IF(C21="","缺少数量",IF(OR(C21<1,C21>9999,C21<>INT(C21)),"数量无效",IF(COUNTIF($B$7:$B$24,B21)>1,"重复敌人",IFERROR(IF(VLOOKUP(B21,敌人目录!$A$6:$AD$54,27,FALSE)="可回读","可回读","敌人参数错误"),"敌人不存在"))))))
A22: 16 | D22: =IF(OR(B22="",C22=""),"",ROUNDUP(C22*(1+(全局设置!$B$5-1)*全局设置!$B$6),0)) | E22: =IFERROR(VLOOKUP(B22,敌人目录!$A$6:$AD$54,13,FALSE),"") | F22: =IF(D22="","",D22*E22) | G22: =IF(F22="","",F22*全局设置!$B$7*全局设置!$E$14) | H22: =IF(G22="","",G22*全局设置!$B$5) | I22: =IF(AND(B22="",C22=""),"",IF(B22="","缺少敌人",IF(C22="","缺少数量",IF(OR(C22<1,C22>9999,C22<>INT(C22)),"数量无效",IF(COUNTIF($B$7:$B$24,B22)>1,"重复敌人",IFERROR(IF(VLOOKUP(B22,敌人目录!$A$6:$AD$54,27,FALSE)="可回读","可回读","敌人参数错误"),"敌人不存在"))))))
A23: 17 | D23: =IF(OR(B23="",C23=""),"",ROUNDUP(C23*(1+(全局设置!$B$5-1)*全局设置!$B$6),0)) | E23: =IFERROR(VLOOKUP(B23,敌人目录!$A$6:$AD$54,13,FALSE),"") | F23: =IF(D23="","",D23*E23) | G23: =IF(F23="","",F23*全局设置!$B$7*全局设置!$E$14) | H23: =IF(G23="","",G23*全局设置!$B$5) | I23: =IF(AND(B23="",C23=""),"",IF(B23="","缺少敌人",IF(C23="","缺少数量",IF(OR(C23<1,C23>9999,C23<>INT(C23)),"数量无效",IF(COUNTIF($B$7:$B$24,B23)>1,"重复敌人",IFERROR(IF(VLOOKUP(B23,敌人目录!$A$6:$AD$54,27,FALSE)="可回读","可回读","敌人参数错误"),"敌人不存在"))))))
